Workbook

Sheet Mode d'emploi
B1: CorpusImmo · www.corpus.immo · Estimer, comparer, décider. Sur les ventes réelles.
B2: Mode d'emploi
B3: À quoi sert ce classeur, dans quel ordre le remplir, et comment lire ce qu'il répond.
B6: À QUOI SERT CE CLASSEUR
B7: Vous regardez un appartement ou une maison à rénover. Ce classeur répond à la question qui précède toute offre d'achat : combien vont coûter les travaux, en fourchette crédible, avant d'avoir un seul devis ?
B8: Il part de cinq données du bien (surface, niveaux, hauteur sous plafond, façades exposées, part rénovée), en déduit la géométrie, chiffre vingt-huit postes en quantité × prix unitaire, le prix étant pris dans une fourchette de marché selon un curseur, ajoute aléas et honoraires, calcule la TVA ligne à ligne à trois taux, et qualifie le chantier au regard de la règle de l'immeuble rendu neuf. Il rend trois budgets : bas de fourchette, retenu, haut de fourchette.
B9: Vous remplissez les cellules violettes de haut en bas ; à mesure que les devis arrivent, vous forcez les quantités et les prix, et la fourchette se referme. Deux mots reviennent partout : le gros œuvre, ce qui tient le bâtiment (fondations, murs porteurs, planchers porteurs, charpente), et le second œuvre, tout ce qui vient ensuite (cloisons, fenêtres, plomberie, électricité, chauffage, finitions).
B10: Vous êtes | C10: Ce que le classeur vous donne
B11: Marchand de biens | C11: Le budget travaux TTC en fourchette pour bâtir l'offre, et l'alerte sur la bascule de tout le chantier à 20 % de TVA (immeuble rendu neuf).
B12: Investisseur locatif | C12: Un ordre de grandeur au m² à comparer aux repères du marché, et la liste des postes à faire deviser.
B13: Maître d'œuvre, architecte | C13: Un cadrage par lot à confronter aux devis d'entreprises, avec le contrôle des parts par famille.
B14: Agent immobilier, chasseur | C14: Une réponse chiffrée en cinq minutes à « combien de travaux ? », avec ses hypothèses écrites.
B15: Banquier, courtier | C15: Un budget travaux justifié ligne à ligne, aléas et honoraires compris, pour le plan de financement.
B17: LE PRINCIPE, EN UNE LIGNE
B18: Quantité déduite du bien × prix pris dans la fourchette selon le curseur = lot ; lots + aléas + honoraires + TVA par ligne = budget TTC
B20: LES ONGLETS, DANS L'ORDRE OÙ ON LES REMPLIT
B21: Onglet | C21: Ce que vous y faites | D21: Ce que vous y lisez
B22: Mode d'emploi | C22: Rien à saisir. Vous lisez ce guide. | D22: La marche à suivre et l'exemple guidé.
B23: Chiffrage | C23: Vous décrivez le bien, réglez le curseur, les aléas et les honoraires, forcez des quantités et des prix dans le tableau, puis répondez aux douze questions du bloc TVA. | D23: Le tableau des lots, le récapitulatif en trois colonnes (bas, retenu, haut), les coûts au m², le niveau de rénovation, le contrôle par famille et sept contrôles vert / rouge.
B24: Référentiel | C24: Vous confrontez les fourchettes de prix, les taux de TVA et les ratios à vos chantiers, et les corrigez. Vous nommez les postes libres. | D24: Chaque valeur avec sa source datée : barèmes de TVA, seuils de l'immeuble neuf, coefficients de géométrie, bandes par famille, fourchettes 2026.
B25: Méthode | C25: Rien à saisir. | D25: Les conventions de calcul, la règle de TVA complète, ce que le modèle ne fait pas, les sources.
B27: LE CODE COULEUR, ET COMMENT DÉVERROUILLER UNE CELLULE
B28: Cellule | C28: Ce que c'est | D28: Ce que vous faites
B29: Fond violet clair | C29: Saisie utilisateur | D29: Vous la remplissez, ou vous l'effacez avec la touche Suppr, même feuille protégée. Jamais de formule dedans. Dans le tableau, une cellule violette vide laisse l'automatisme.
B30: Fond blanc | C30: Calcul | D30: Vous la lisez. Elle est verrouillée.
B31: Fond violet pâle, gras | C31: Résultat de bloc, chiffre clé | D31: Vous la lisez. C'est un chiffre à retenir.
B32: Bandeau violet | C32: Titre de section, en-tête de tableau | D32: Repère de navigation.
B33: Texte gris, à droite | C33: Commentaire d'aide, ordre de grandeur | D33: Une phrase par ligne pour savoir quoi saisir.
B34: Vert / rouge | C34: Contrôle de cohérence | D34: Rouge, la cellule affiche « À CORRIGER » : corrigez la saisie indiquée par le commentaire à droite. Le récapitulatif reste vide tant qu'un contrôle bloquant est rouge.
B35: Les onglets sont protégés sans mot de passe pour éviter d'écraser une formule par erreur. Pour modifier une cellule blanche : onglet Révision, puis « Ôter la protection de la feuille ». Aucun mot de passe n'est demandé. En pratique, tout ce qu'un professionnel doit régler est violet, dans le Chiffrage ou dans le Référentiel.
B37: LA MARCHE À SUIVRE, ÉTAPE PAR ÉTAPE
B38: Étape | C38: Où (onglet et plage) | D38: Ce que vous faites | E38: Pourquoi
B39: 0. L'exemple livré | C39: Chiffrage!D7:D16, F29:F59 et J29:J59, D62:D77 | D39: Le classeur est livré rempli d'un exemple (appartement de 90 m², détaillé plus bas). Gardez-le pour vous repérer, ou effacez toutes les cellules violettes du Chiffrage avant de saisir votre dossier : sélectionnez-les et appuyez sur Suppr, la protection de la feuille ne s'y oppose pas. Vérifiez surtout les saisies secondaires qui n'ont pas de raison d'être chez vous : les 8 quantités forcées de la colonne F (dont les 6 zéros qui désactivent couverture, charpente, combles, chaudière, ravalement et VRD, la voirie et les réseaux du terrain), les douze réponses du bloc TVA, le taux forcé D77 (à laisser vide) et le curseur D14. | E39: Une saisie résiduelle de l'exemple est l'erreur la plus probable d'un premier usage : sur une maison, les trois zéros hérités de l'appartement (couverture, charpente, combles) font disparaître 15 030 € de travaux sans un mot.
B40: 1. Vos prix | C40: Référentiel!E70:G100, puis C109 | D40: Premier chiffrage, sans chantier derrière vous : ne touchez à rien, les fourchettes livrées sont sourcées ligne à ligne et datées 2026, elles suffisent à cadrer. Ensuite, à chaque devis reçu, corrigez la ligne concernée, ainsi que son taux de TVA si le devis en applique un autre, et mettez la date de vérification à jour. Nommez les postes libres (lignes 98 à 100) si votre chantier a du désamiantage, du plomb ou un ascenseur. | E40: Ce sont vos prix et vos ratios qui comptent dès que vous en avez. Tout le classeur pointe ici : rien n'est écrit en dur ailleurs.
B41: 2. Le bien | C41: Chiffrage!D7:D11 | D41: Surface habitable (à défaut, la surface Carrez de l'annonce en est très proche pour un appartement), nombre de niveaux, hauteur sous plafond mesurée sur place, façades exposées (4 pour une maison, 2 pour un appartement traversant, 1 sinon), part du logement rénovée. | E41: La surface pilote presque toutes les quantités ; les façades distinguent une maison d'un appartement ; la part rénovée réduit dépose, réseaux, sols et peinture.
B42: 3. Le chiffrage | C42: Chiffrage!D14:D16 | D42: Curseur de fourchette (repères du Référentiel : province 40 % à 60 %, Île-de-France 60 % à 80 %), provision pour aléas (10 % à 15 % dans l'ancien), honoraires de maîtrise d'œuvre (8 % à 12 % en exécution). | E42: Le curseur représente la tension du marché et le type d'entreprise. Les aléas et les honoraires s'ajoutent aux lots avant TVA.
B43: 4. Le tableau des lots | C43: Chiffrage!F29:F59 et J29:J59 | D43: Deux colonnes violettes seulement, F (quantité forcée) et J (prix forcé) : les autres sont calculées. Quantité forcée : 0 pour désactiver un poste (couverture, charpente, combles, chaudière, ravalement et VRD sont livrés à 0 pour un appartement), une valeur comptée sur plan sinon, vide pour l'automatisme. Prix forcés à mesure que les devis arrivent, en priorité sur pompe à chaleur, cuisine, salle de bains, ventilation. | E43: Une valeur forcée l'emporte toujours sur le calcul sans le détruire. Un prix forcé vaut dans les trois colonnes du récapitulatif : c'est un devis.
B44: 5. La TVA du chantier | C44: Chiffrage!D62:D73 et D77 | D44: Douze réponses dans des listes déroulantes : nature du local, ancienneté, extension, trois critères de gros œuvre, six éléments de second œuvre. Lisez D76 : vert « Taux par ligne », ou rouge « TOUT À 20 % ». Laissez D77 vide sauf pour imposer un taux unique. | E44: C'est la règle de l'immeuble rendu neuf (CGI art. 257) : dès qu'un critère est rempli, l'opération entière perd les taux réduits. Le classeur l'applique et l'affiche.
B45: 6. Les sept contrôles | C45: Chiffrage!D24:D25, D80:D83, H110 ; Référentiel!C7 | D45: Vérifiez que tout est vert. Un rouge désigne la saisie à corriger dans son commentaire. Les contrôles rejouent aussi les bornes des listes et des validations : une valeur collée ou héritée de l'exemple n'y échappe pas. | E45: Tant qu'un contrôle bloquant est rouge, le récapitulatif ou la TVA restent vides : le classeur préfère ne rien afficher plutôt qu'un chiffre faux.
B46: 7. Les résultats | C46: Chiffrage!D87:F99 et E100 | D46: Rien à saisir. Lisez les trois colonnes : bas de fourchette, retenu, haut de fourchette. Puis le contrôle par famille en dessous. | E46: Le sous-total des lots se compare à un devis d'entreprise générale ; le TTC est le budget à financer ; les parts par famille disent si un lot manque.
...

Sheet Chiffrage
B1: CorpusImmo · www.corpus.immo · Estimer, comparer, décider. Sur les ventes réelles.
B2: Chiffrage de travaux par lot
B3: Cinq entrées, vingt-huit postes chiffrés en fourchette, chaque quantité et chaque prix restent forçables, et la TVA du chantier est qualifiée.
B5: Cellules violettes : à remplir. Cellules blanches : calculées automatiquement.
B6: LE BIEN
B7: Surface habitable | D7: 90 | E7: Le pivot : elle pilote la plupart des quantités. Bornes de saisie : 9 à 5 000 m².
B8: Nombre de niveaux | D8: 1 | E8: Sert à déduire l'emprise au sol : toiture, combles, charpente. Entier de 1 à 6.
B9: Hauteur sous plafond | D9: 2.5 | E9: Sert aux murs et aux cloisons. Mesurez-la sur place. Bornes de saisie : 2 à 5 m.
B10: Façades exposées | D10: 2 | E10: 4 pour une maison, 2 pour un appartement traversant, 1 sinon (mitoyen ou en cœur d'îlot).
B11: Part du logement rénovée | D11: 1 | E11: 100 % = rénovation complète. Pilote dépose, électricité, plomberie, sols, peinture, cloisons.
B13: LE CHIFFRAGE
B14: Positionnement dans la fourchette | D14: 0.5 | E14: ="0 % = bas de fourchette, 100 % = haut. Repères (Référentiel) : province "&ROUND(Référentiel!$C$27*100,1)&" %"&" à "&ROUND(Référentiel!$D$27*100,1)&" %"&", Île-de-France "&ROUND(Référentiel!$C$28*100,1)&" %"&" à "&ROUND(Référentiel!$D$28*100,1)&" %"&", Paris "&ROUND(Référentiel!$C$29*100,1)&" %"&" à "&ROUND(Référentiel!$D$29*100,1)&" %"&"." -> 0 % = bas de fourchette, 100 % = haut. Repères (Référentiel) : province 40 % à 60 %, Île-de-France 60 % à 80 %, Paris 70 % à 100 %.
B15: Provision pour aléas | D15: 0.12 | E15: ="Rénovation dans l'ancien : "&ROUND(Référentiel!$C$30*100,1)&" %"&" à "&ROUND(Référentiel!$D$30*100,1)&" %"&" (Référentiel). En dessous, vous pariez." -> Rénovation dans l'ancien : 10 % à 15 % (Référentiel). En dessous, vous pariez.
B16: Honoraires de maîtrise d'œuvre | D16: 0.1 | E16: ="Maîtrise d'œuvre d'exécution "&ROUND(Référentiel!$C$31*100,1)&" %"&" à "&ROUND(Référentiel!$D$31*100,1)&" %"&", architecte en mission complète "&ROUND(Référentiel!$C$32*100,1)&" %"&" à "&ROUND(Référentiel!$D$32*100,1)&" %"&" (Référentiel). TVA à "&ROUND(Référentiel!$C$10*100,1)&" %"&"." -> Maîtrise d'œuvre d'exécution 8 % à 12 %, architecte en mission complète 12 % à 18 % (Référentiel). TVA à 20 %.
B18: CE QUE LA GÉOMÉTRIE EN DÉDUIT
B19: Emprise au sol | D19: =IF(AND(ISNUMBER($D$7),$D$7>0,ISNUMBER($D$8),$D$8>0),$D$7/$D$8,"") -> 90 | E19: Surface habitable / nombre de niveaux.
B20: Périmètre estimé | D20: =IF($D$19="","",Référentiel!$C$19*SQRT($D$19)) -> 39.844699 | E20: Coefficient du Référentiel × racine de l'emprise. Le périmètre n'est pas proportionnel à la surface.
B21: Murs de façade | D21: =IF($D$20="","",$D$20*$D$9*$D$8*$D$10/Référentiel!$C$20) -> 49.805873 | E21: Périmètre × HSP × niveaux × façades exposées / nombre de façades (Référentiel). Pilote isolation, doublage, ravalement.
B22: Surface traitée | D22: =IF($D$19="","",$D$7*$D$11) -> 90 | E22: Surface habitable × part rénovée.
B23: Surface de toit | D23: =IF($D$19="","",$D$19*Référentiel!$C$21) -> 108 | E23: Emprise × coefficient de pente (Référentiel).
B24: Saisies du bien et du chiffrage complètes et dans leurs bornes | D24: =IF(AND(ISNUMBER($D$7),$D$7>=9,$D$7<=5000,ISNUMBER($D$8),$D$8>=1,$D$8<=6,$D$8=INT($D$8),ISNUMBER($D$9),$D$9>=2,$D$9<=5,ISNUMBER($D$10),$D$10>=0,$D$10<=4,$D$10=INT($D$10),ISNUMBER($D$11),$D$11>=0,$D$11<=1,ISNUMBER($D$14),$D$14>=0,$D$14<=1,ISNUMBER($D$15),$D$15>=0,$D$15<=0.5,ISNUMBER($D$16),$D$16>=0,$D$16<=0.5,COUNTIF($F$29:$F$59,"<0")=0,SUMPRODUCT(--ISTEXT($F$29:$F$59))=0,COUNTIF($J$29:$J$59,"<0")=0,SUMPRODUCT(--ISTEXT($J$29:$J$59))=0),"OK","À CORRIGER") -> OK | E24: À CORRIGER : une saisie manque, sort de ses bornes, ou un forçage du tableau est négatif ou en texte. Le récapitulatif reste vide tant que c'est rouge.
B25: Référentiel cohérent | D25: =IF(Référentiel!$C$7="OK","OK","À CORRIGER") -> OK | E25: À CORRIGER : une valeur du Référentiel manque ou sort de ses bornes (prix, ratio, taux hors liste, bas supérieur au haut). Le récapitulatif reste vide.
B27: LES LOTS : QUANTITÉ × PRIX UNITAIRE, PRIX PRIS DANS LA FOURCHETTE SELON LE CURSEUR
B28: Lot | C28: Prestation | D28: Unité | E28: Qté auto | F28: Qté forcée | G28: Qté retenue | H28: PU bas | I28: PU haut | J28: PU forcé | K28: PU retenu | L28: Total HT | M28: TVA | N28: Total TTC
B29: =Référentiel!$C$70 -> Dépose et démolition | C29: =Référentiel!$B$70 -> Dépose de cloisons, sols et sanitaires | D29: =Référentiel!$D$70 -> m² au sol | E29: =IF($D$19="","",ROUND($D$22*Référentiel!$I$70,0)) -> 90 | G29: =IF(F29="",E29,F29) -> 90 | H29: =Référentiel!$E$70 -> 25 | I29: =Référentiel!$F$70 -> 60 | K29: =IF(J29="",H29+(I29-H29)*$D$14,J29) -> 42.5 | L29: =IF(OR(G29="",NOT(ISNUMBER(G29)),NOT(ISNUMBER(K29))),"",G29*K29) -> 3825 | M29: =IF($D$78="",Référentiel!$G$70,$D$78) -> 0.1 | N29: =IF(OR(L29="",NOT(ISNUMBER(M29))),"",L29*(1+M29)) -> 4207.5
B30: =Référentiel!$C$71 -> Dépose et démolition | C30: =Référentiel!$B$71 -> Évacuation en benne | D30: =Référentiel!$D$71 -> forfait | E30: =IF($D$19="","",ROUNDUP($D$7*Référentiel!$I$71,0)) -> 1 | G30: =IF(F30="",E30,F30) -> 1 | H30: =Référentiel!$E$71 -> 400 | I30: =Référentiel!$F$71 -> 1200 | K30: =IF(J30="",H30+(I30-H30)*$D$14,J30) -> 800 | L30: =IF(OR(G30="",NOT(ISNUMBER(G30)),NOT(ISNUMBER(K30))),"",G30*K30) -> 800 | M30: =IF($D$78="",Référentiel!$G$71,$D$78) -> 0.1 | N30: =IF(OR(L30="",NOT(ISNUMBER(M30))),"",L30*(1+M30)) -> 880
B31: =Référentiel!$C$72 -> Gros œuvre | C31: =Référentiel!$B$72 -> Ouverture dans un mur porteur avec IPN | D31: =Référentiel!$D$72 -> unité | E31: =IF($D$19="","",ROUND($D$7*Référentiel!$I$72,0)) -> 0 | F31: 1 | G31: =IF(F31="",E31,F31) -> 1 | H31: =Référentiel!$E$72 -> 1800 | I31: =Référentiel!$F$72 -> 4500 | K31: =IF(J31="",H31+(I31-H31)*$D$14,J31) -> 3150 | L31: =IF(OR(G31="",NOT(ISNUMBER(G31)),NOT(ISNUMBER(K31))),"",G31*K31) -> 3150 | M31: =IF($D$78="",Référentiel!$G$72,$D$78) -> 0.1 | N31: =IF(OR(L31="",NOT(ISNUMBER(M31))),"",L31*(1+M31)) -> 3465
B32: =Référentiel!$C$73 -> Gros œuvre | C32: =Référentiel!$B$73 -> Reprise de maçonnerie et rebouchage | D32: =Référentiel!$D$73 -> m² | E32: =IF($D$19="","",ROUND($D$7*Référentiel!$I$73,0)) -> 0 | F32: 20 | G32: =IF(F32="",E32,F32) -> 20 | H32: =Référentiel!$E$73 -> 45 | I32: =Référentiel!$F$73 -> 110 | K32: =IF(J32="",H32+(I32-H32)*$D$14,J32) -> 77.5 | L32: =IF(OR(G32="",NOT(ISNUMBER(G32)),NOT(ISNUMBER(K32))),"",G32*K32) -> 1550 | M32: =IF($D$78="",Référentiel!$G$73,$D$78) -> 0.1 | N32: =IF(OR(L32="",NOT(ISNUMBER(M32))),"",L32*(1+M32)) -> 1705
B33: =Référentiel!$C$74 -> Charpente et toiture | C33: =Référentiel!$B$74 -> Réfection de couverture en tuiles | D33: =Référentiel!$D$74 -> m² de toit | E33: =IF($D$19="","",ROUND($D$23*Référentiel!$I$74,0)) -> 108 | F33: 0 | G33: =IF(F33="",E33,F33) -> 0 | H33: =Référentiel!$E$74 -> 90 | I33: =Référentiel!$F$74 -> 190 | K33: =IF(J33="",H33+(I33-H33)*$D$14,J33) -> 140 | L33: =IF(OR(G33="",NOT(ISNUMBER(G33)),NOT(ISNUMBER(K33))),"",G33*K33) -> 0 | M33: =IF($D$78="",Référentiel!$G$74,$D$78) -> 0.1 | N33: =IF(OR(L33="",NOT(ISNUMBER(M33))),"",L33*(1+M33)) -> 0
B34: =Référentiel!$C$75 -> Charpente et toiture | C34: =Référentiel!$B$75 -> Traitement de charpente | D34: =Référentiel!$D$75 -> m² au sol | E34: =IF($D$19="","",ROUND($D$19*Référentiel!$I$75,0)) -> 90 | F34: 0 | G34: =IF(F34="",E34,F34) -> 0 | H34: =Référentiel!$E$75 -> 25 | I34: =Référentiel!$F$75 -> 55 | K34: =IF(J34="",H34+(I34-H34)*$D$14,J34) -> 40 | L34: =IF(OR(G34="",NOT(ISNUMBER(G34)),NOT(ISNUMBER(K34))),"",G34*K34) -> 0 | M34: =IF($D$78="",Référentiel!$G$75,$D$78) -> 0.1 | N34: =IF(OR(L34="",NOT(ISNUMBER(M34))),"",L34*(1+M34)) -> 0
B35: =Référentiel!$C$76 -> Menuiseries extérieures | C35: =Référentiel!$B$76 -> Fenêtre PVC double vitrage posée | D35: =Référentiel!$D$76 -> unité | E35: =IF($D$19="","",ROUND($D$7*Référentiel!$I$76,0)) -> 7 | G35: =IF(F35="",E35,F35) -> 7 | H35: =Référentiel!$E$76 -> 550 | I35: =Référentiel!$F$76 -> 1400 | K35: =IF(J35="",H35+(I35-H35)*$D$14,J35) -> 975 | L35: =IF(OR(G35="",NOT(ISNUMBER(G35)),NOT(ISNUMBER(K35))),"",G35*K35) -> 6825 | M35: =IF($D$78="",Référentiel!$G$76,$D$78) -> 0.055 | N35: =IF(OR(L35="",NOT(ISNUMBER(M35))),"",L35*(1+M35)) -> 7200.375
B36: =Référentiel!$C$77 -> Menuiseries extérieures | C36: =Référentiel!$B$77 -> Porte d'entrée | D36: =Référentiel!$D$77 -> unité | E36: =ROUND(Référentiel!$I$77,0) -> 1 | G36: =IF(F36="",E36,F36) -> 1 | H36: =Référentiel!$E$77 -> 900 | I36: =Référentiel!$F$77 -> 2600 | K36: =IF(J36="",H36+(I36-H36)*$D$14,J36) -> 1750 | L36: =IF(OR(G36="",NOT(ISNUMBER(G36)),NOT(ISNUMBER(K36))),"",G36*K36) -> 1750 | M36: =IF($D$78="",Référentiel!$G$77,$D$78) -> 0.055 | N36: =IF(OR(L36="",NOT(ISNUMBER(M36))),"",L36*(1+M36)) -> 1846.25
B37: =Référentiel!$C$78 -> Isolation | C37: =Référentiel!$B$78 -> Isolation des murs par l'intérieur | D37: =Référentiel!$D$78 -> m² de mur | E37: =IF($D$19="","",ROUND($D$21*Référentiel!$I$78,0)) -> 50 | G37: =IF(F37="",E37,F37) -> 50 | H37: =Référentiel!$E$78 -> 45 | I37: =Référentiel!$F$78 -> 95 | K37: =IF(J37="",H37+(I37-H37)*$D$14,J37) -> 70 | L37: =IF(OR(G37="",NOT(ISNUMBER(G37)),NOT(ISNUMBER(K37))),"",G37*K37) -> 3500 | M37: =IF($D$78="",Référentiel!$G$78,$D$78) -> 0.055 | N37: =IF(OR(L37="",NOT(ISNUMBER(M37))),"",L37*(1+M37)) -> 3692.5
B38: =Référentiel!$C$79 -> Isolation | C38: =Référentiel!$B$79 -> Isolation des combles perdus | D38: =Référentiel!$D$79 -> m² au sol | E38: =IF($D$19="","",ROUND($D$19*Référentiel!$I$79,0)) -> 90 | F38: 0 | G38: =IF(F38="",E38,F38) -> 0 | H38: =Référentiel!$E$79 -> 25 | I38: =Référentiel!$F$79 -> 60 | K38: =IF(J38="",H38+(I38-H38)*$D$14,J38) -> 42.5 | L38: =IF(OR(G38="",NOT(ISNUMBER(G38)),NOT(ISNUMBER(K38))),"",G38*K38) -> 0 | M38: =IF($D$78="",Référentiel!$G$79,$D$78) -> 0.055 | N38: =IF(OR(L38="",NOT(ISNUMBER(M38))),"",L38*(1+M38)) -> 0
B39: =Référentiel!$C$80 -> Cloisons et plâtrerie | C39: =Référentiel!$B$80 -> Cloison placo sur ossature | D39: =Référentiel!$D$80 -> m² | E39: =IF($D$19="","",ROUND($D$22*$D$9*Référentiel!$I$80,0)) -> 45 | G39: =IF(F39="",E39,F39) -> 45 | H39: =Référentiel!$E$80 -> 45 | I39: =Référentiel!$F$80 -> 95 | K39: =IF(J39="",H39+(I39-H39)*$D$14,J39) -> 70 | L39: =IF(OR(G39="",NOT(ISNUMBER(G39)),NOT(ISNUMBER(K39))),"",G39*K39) -> 3150 | M39: =IF($D$78="",Référentiel!$G$80,$D$78) -> 0.1 | N39: =IF(OR(L39="",NOT(ISNUMBER(M39))),"",L39*(1+M39)) -> 3465
B40: =Référentiel!$C$81 -> Cloisons et plâtrerie | C40: =Référentiel!$B$81 -> Doublage et enduit de finition | D40: =Référentiel!$D$81 -> m² | E40: =IF($D$19="","",ROUND($D$21*Référentiel!$I$81,0)) -> 50 | G40: =IF(F40="",E40,F40) -> 50 | H40: =Référentiel!$E$81 -> 30 | I40: =Référentiel!$F$81 -> 65 | K40: =IF(J40="",H40+(I40-H40)*$D$14,J40) -> 47.5 | L40: =IF(OR(G40="",NOT(ISNUMBER(G40)),NOT(ISNUMBER(K40))),"",G40*K40) -> 2375 | M40: =IF($D$78="",Référentiel!$G$81,$D$78) -> 0.1 | N40: =IF(OR(L40="",NOT(ISNUMBER(M40))),"",L40*(1+M40)) -> 2612.5
B41: =Référentiel!$C$82 -> Électricité | C41: =Référentiel!$B$82 -> Électricité complète, NF C 15-100 | D41: =Référentiel!$D$82 -> m² au sol | E41: =IF($D$19="","",ROUND($D$22*Référentiel!$I$82,0)) -> 90 | G41: =IF(F41="",E41,F41) -> 90 | H41: =Référentiel!$E$82 -> 90 | I41: =Référentiel!$F$82 -> 165 | K41: =IF(J41="",H41+(I41-H41)*$D$14,J41) -> 127.5 | L41: =IF(OR(G41="",NOT(ISNUMBER(G41)),NOT(ISNUMBER(K41))),"",G41*K41) -> 11475 | M41: =IF($D$78="",Référentiel!$G$82,$D$78) -> 0.1 | N41: =IF(OR(L41="",NOT(ISNUMBER(M41))),"",L41*(1+M41)) -> 12622.5
B42: =Référentiel!$C$83 -> Électricité | C42: =Référentiel!$B$83 -> Tableau électrique neuf | D42: =Référentiel!$D$83 -> unité | E42: =ROUND(Référentiel!$I$83,0) -> 1 | G42: =IF(F42="",E42,F42) -> 1 | H42: =Référentiel!$E$83 -> 900 | I42: =Référentiel!$F$83 -> 2200 | K42: =IF(J42="",H42+(I42-H42)*$D$14,J42) -> 1550 | L42: =IF(OR(G42="",NOT(ISNUMBER(G42)),NOT(ISNUMBER(K42))),"",G42*K42) -> 1550 | M42: =IF($D$78="",Référentiel!$G$83,$D$78) -> 0.1 | N42: =IF(OR(L42="",NOT(ISNUMBER(M42))),"",L42*(1+M42)) -> 1705
B43: =Référentiel!$C$84 -> Plomberie et chauffage | C43: =Référentiel!$B$84 -> Réseau plomberie complet | D43: =Référentiel!$D$84 -> m² au sol | E43: =IF($D$19="","",ROUND($D$22*Référentiel!$I$84,0)) -> 90 | G43: =IF(F43="",E43,F43) -> 90 | H43: =Référentiel!$E$84 -> 55 | I43: =Référentiel!$F$84 -> 120 | K43: =IF(J43="",H43+(I43-H43)*$D$14,J43) -> 87.5 | L43: =IF(OR(G43="",NOT(ISNUMBER(G43)),NOT(ISNUMBER(K43))),"",G43*K43) -> 7875 | M43: =IF($D$78="",Référentiel!$G$84,$D$78) -> 0.1 | N43: =IF(OR(L43="",NOT(ISNUMBER(M43))),"",L43*(1+M43)) -> 8662.5
B44: =Référentiel!$C$85 -> Plomberie et chauffage | C44: =Référentiel!$B$85 -> Pompe à chaleur air/eau ou air/air | D44: =Référentiel!$D$85 -> unité | E44: =ROUND(Référentiel!$I$85,0) -> 1 | G44: =IF(F44="",E44,F44) -> 1 | H44: =Référentiel!$E$85 -> 3500 | I44: =Référentiel!$F$85 -> 14000 | K44: =IF(J44="",H44+(I44-H44)*$D$14,J44) -> 8750 | L44: =IF(OR(G44="",NOT(ISNUMBER(G44)),NOT(ISNUMBER(K44))),"",G44*K44) -> 8750 | M44: =IF($D$78="",Référentiel!$G$85,$D$78) -> 0.055 | N44: =IF(OR(L44="",NOT(ISNUMBER(M44))),"",L44*(1+M44)) -> 9231.25
...

Sheet Référentiel
B1: CorpusImmo · www.corpus.immo · Estimer, comparer, décider. Sur les ventes réelles.
B2: Référentiel
B3: Un prix, un taux de TVA et un ratio par prestation ; les barèmes et les conventions du classeur. Rien n'est écrit en dur ailleurs.
B5: Cellules violettes : à remplir. Cellules blanches : calculées automatiquement.
B6: Fourchettes indicatives 2026, France hors Paris intra-muros. Fournitures et pose, hors taxes. Les cellules violettes sont vos prix : confrontez-les à vos trois derniers chantiers.
B7: Référentiel cohérent (bornes des barèmes, des prix, des ratios et des taux) | C7: =IF(AND(COUNT(C10:C15)=ROWS(C10:C15),COUNTIF(C10:C14,"<0")=0,COUNTIF(C10:C14,">1")=0,C15>=0,C15<=50,C15=INT(C15),COUNT(C19:C23)=ROWS(C19:C23),C19>=3.5,C19<=8,C20>=1,C20<=8,C20=INT(C20),C21>=1,C21<=2,C22>=0,C23>=C22,COUNT(C27:D32)=ROWS(C27:D32)*COLUMNS(C27:D32),COUNTIF(C27:D32,"<0")=0,COUNTIF(C27:D32,">1")=0,SUMPRODUCT(--(C27:C32>D27:D32))=0,COUNT(C36:D41)=ROWS(C36:D41)*COLUMNS(C36:D41),COUNTIF(C36:D41,"<0")=0,COUNTIF(C36:D41,">1")=0,SUMPRODUCT(--(C36:C41>D36:D41))=0,COUNT(E70:F100)=ROWS(E70:F100)*COLUMNS(E70:F100),COUNTIF(E70:F100,"<0")=0,SUMPRODUCT(--(E70:E100>F70:F100))=0,COUNT(I70:I100)=ROWS(I70:I100),COUNTIF(I70:I100,"<0")=0,COUNTIF(G70:G100,C10)+COUNTIF(G70:G100,C11)+COUNTIF(G70:G100,C12)=ROWS(G70:G100)),"OK","À CORRIGER") -> OK | D7: Rouge : une cellule violette de cet onglet manque ou sort de ses bornes. Le Chiffrage le reprend et suspend son récapitulatif.
B8: BARÈMES RÉGLEMENTAIRES : TVA DES TRAVAUX ET IMMEUBLE RENDU NEUF (DROIT 2026)
B9: Paramètre | C9: Valeur | D9: Mise à jour | J9: Source (organisme, texte, date) | K9: Commentaire
B10: TVA, taux normal | C10: 0.2 | D10: Chaque loi de finances | J10: ="CGI art. 278 ; Service-public Entreprendre F23568, mis à jour le 21/02/2026. "&"Vérifié le "&TEXT(DAY(Référentiel!$C$109),"00")&"/"&TEXT(MONTH(Référentiel!$C$109),"00")&"/"&YEAR(Référentiel!$C$109) -> CGI art. 278 ; Service-public Entreprendre F23568, mis à jour le 21/02/2026. Vérifié le 05/09/2026 | K10: Local de moins de 2 ans, local non affecté à l'habitation, immeuble rendu neuf, extension de plus de 10 %, honoraires (prestation intellectuelle), chaudière fossile.
B11: TVA, taux intermédiaire (amélioration d'un logement de plus de 2 ans) | C11: 0.1 | D11: Chaque loi de finances | J11: ="CGI art. 279-0 bis ; BOI-TVA-LIQ-30-20-90-10 du 22/10/2025. "&"Vérifié le "&TEXT(DAY(Référentiel!$C$109),"00")&"/"&TEXT(MONTH(Référentiel!$C$109),"00")&"/"&YEAR(Référentiel!$C$109) -> CGI art. 279-0 bis ; BOI-TVA-LIQ-30-20-90-10 du 22/10/2025. Vérifié le 05/09/2026 | K11: Travaux d'amélioration, de transformation, d'aménagement et d'entretien. Taux par défaut du Référentiel.
B12: TVA, taux réduit (rénovation énergétique éligible) | C12: 0.055 | D12: Loi de finances et arrêtés | J12: ="CGI art. 278-0 bis A ; arrêté du 24/12/2024 (liste des équipements) ; BOFiP ACTU-2025-00165 du 22/10/2025 ; FFB, liste du 25/08/2026. "&"Vérifié le "&TEXT(DAY(Référentiel!$C$109),"00")&"/"&TEXT(MONTH(Référentiel!$C$109),"00")&"/"&YEAR(Référentiel!$C$109) -> CGI art. 278-0 bis A ; arrêté du 24/12/2024 (liste des équipements) ; BOFiP ACTU-2025-00165 du 22/10/2025 ; FFB, liste du 25/08/2026. Vérifié le 05/09/2026 | K12: Isolation, fenêtres et portes extérieures, pompes à chaleur (air/air depuis le 18/07/2026), VMC double flux ou hygroréglable. Chaudières fossiles exclues depuis le 01/03/2025.
B13: Immeuble rendu neuf : proportion de chaque élément de second œuvre | C13: 0.66666667 | D13: Stable | J13: ="CGI art. 257, I-2-2° ; CGI annexe II art. 245 A ; BOI-TVA-IMM-10-10-10-20 § 140 et suivants. "&"Vérifié le "&TEXT(DAY(Référentiel!$C$109),"00")&"/"&TEXT(MONTH(Référentiel!$C$109),"00")&"/"&YEAR(Référentiel!$C$109) -> CGI art. 257, I-2-2° ; CGI annexe II art. 245 A ; BOI-TVA-IMM-10-10-10-20 § 140 et suivants. Vérifié le 05/09/2026 | K13: Les six éléments (planchers non porteurs, huisseries extérieures, cloisons, plomberie et sanitaires, électricité, chauffage) refaits chacun à au moins cette proportion rendent l'immeuble neuf : 20 % sur tout.
B14: Extension de surface de plancher qui exclut les taux réduits | C14: 0.1 | D14: Stable | J14: ="CGI art. 279-0 bis, 2 bis ; BOI-TVA-LIQ-30-20-90-10 du 22/10/2025. "&"Vérifié le "&TEXT(DAY(Référentiel!$C$109),"00")&"/"&TEXT(MONTH(Référentiel!$C$109),"00")&"/"&YEAR(Référentiel!$C$109) -> CGI art. 279-0 bis, 2 bis ; BOI-TVA-LIQ-30-20-90-10 du 22/10/2025. Vérifié le 05/09/2026 | K14: Au-delà de cette augmentation de surface, l'ensemble des travaux est au taux normal.
B15: Ancienneté minimale du logement pour les taux réduits | C15: 2 | D15: Stable | J15: ="CGI art. 279-0 bis, 1 ; BOI-TVA-LIQ-30-20-90-10 § 10 : appréciée au début des travaux. "&"Vérifié le "&TEXT(DAY(Référentiel!$C$109),"00")&"/"&TEXT(MONTH(Référentiel!$C$109),"00")&"/"&YEAR(Référentiel!$C$109) -> CGI art. 279-0 bis, 1 ; BOI-TVA-LIQ-30-20-90-10 § 10 : appréciée au début des travaux. Vérifié le 05/09/2026 | K15: Achevé depuis plus de deux ans au début des travaux. Sinon 20 % sur tout le chantier.
B17: REPÈRES DE MARCHÉ ET CONVENTIONS DE CHIFFRAGE
B18: Paramètre | C18: Valeur | D18: Mise à jour | J18: Source (organisme, texte, date) | K18: Commentaire
B19: Coefficient de périmètre (périmètre = coefficient × racine de l'emprise) | C19: 4.2 | D19: Par dossier | J19: ="Géométrie : 4,0 pour un carré, 4,08 pour un rectangle 1,5:1, 4,24 pour un rectangle 2:1. "&"Vérifié le "&TEXT(DAY(Référentiel!$C$109),"00")&"/"&TEXT(MONTH(Référentiel!$C$109),"00")&"/"&YEAR(Référentiel!$C$109) -> Géométrie : 4,0 pour un carré, 4,08 pour un rectangle 1,5:1, 4,24 pour un rectangle 2:1. Vérifié le 05/09/2026 | K19: Convention CorpusImmo pour un plan allongé. Plan en L ou très étroit : montez à 4,5 ou forcez les murs.
B20: Nombre de façades d'un bâtiment (diviseur des façades exposées) | C20: 4 | D20: Jamais | J20: ="Géométrie. "&"Vérifié le "&TEXT(DAY(Référentiel!$C$109),"00")&"/"&TEXT(MONTH(Référentiel!$C$109),"00")&"/"&YEAR(Référentiel!$C$109) -> Géométrie. Vérifié le 05/09/2026 | K20: Murs de façade = périmètre × hauteur × niveaux × façades exposées / ce nombre.
B21: Coefficient de toiture (surface de toit = emprise × coefficient) | C21: 1.2 | D21: Par dossier | J21: ="Trigonométrie : 1/cos 30° = 1,155 ; 1/cos 35° = 1,221 ; 1,41 à 45°. "&"Vérifié le "&TEXT(DAY(Référentiel!$C$109),"00")&"/"&TEXT(MONTH(Référentiel!$C$109),"00")&"/"&YEAR(Référentiel!$C$109) -> Trigonométrie : 1/cos 30° = 1,155 ; 1/cos 35° = 1,221 ; 1,41 à 45°. Vérifié le 05/09/2026 | K21: 1,20 pour une pente de 30 à 35°. Toit plat : 1,00.
B22: Coût TTC au m² : au-dessus, on ne rafraîchit plus, on rénove | C22: 750 | D22: Annuelle | J22: ="Hellowatt 2026 : léger 250 à 750, moyen 750 à 1 500, lourd 2 000 à 4 000 €/m² TTC ; Illico Travaux 2026 : complet 1 000 à 1 800, lourd 1 500 et plus. "&"Vérifié le "&TEXT(DAY(Référentiel!$C$109),"00")&"/"&TEXT(MONTH(Référentiel!$C$109),"00")&"/"&YEAR(Référentiel!$C$109) -> Hellowatt 2026 : léger 250 à 750, moyen 750 à 1 500, lourd 2 000 à 4 000 €/m² TTC ; Illico Travaux 2026 : complet 1 000 à 1 800, lourd 1 500 et plus. Vérifié le 05/09/2026 | K22: Aléas et honoraires compris, comme le chiffrage.
B23: Coût TTC au m² : au-dessus, rénovation lourde ou restructuration | C23: 1500 | D23: Annuelle | J23: ="Mêmes sources. Le 1 500 €/m² est un plancher de rénovation lourde, pas un centre. "&"Vérifié le "&TEXT(DAY(Référentiel!$C$109),"00")&"/"&TEXT(MONTH(Référentiel!$C$109),"00")&"/"&YEAR(Référentiel!$C$109) -> Mêmes sources. Le 1 500 €/m² est un plancher de rénovation lourde, pas un centre. Vérifié le 05/09/2026 | K23: Au-delà, un maître d'œuvre s'impose.
B25: REPÈRES DE SAISIE DU CHIFFRAGE (BAS / HAUT) : CURSEUR PAR ZONE, ALÉAS, HONORAIRES
B26: Repère | C26: Bas | D26: Haut | J26: Source (organisme, texte, date) | K26: Commentaire
B27: Curseur de fourchette usuel, province | C27: 0.4 | D27: 0.6 | J27: ="Observatoire ARTEP (monimmeuble.com), Erema Bat 2026, AZ Bâtiments 2026 : Île-de-France + 15 à 30 % sur la province, Paris intra-muros + 20 à 35 %, soit un curseur plus haut, pas une autre grille. "&"Vérifié le "&TEXT(DAY(Référentiel!$C$109),"00")&"/"&TEXT(MONTH(Référentiel!$C$109),"00")&"/"&YEAR(Référentiel!$C$109) -> Observatoire ARTEP (monimmeuble.com), Erema Bat 2026, AZ Bâtiments 2026 : Île-de-France + 15 à 30 % sur la province, Paris intra-muros + 20 à 35 %, soit un curseur plus haut, pas une autre grille. Vérifié le 05/09/2026 | K27: Tension du marché et type d'entreprise : artisans en direct en bas, entreprise générale en haut.
B28: Curseur de fourchette usuel, Île-de-France | C28: 0.6 | D28: 0.8 | J28: ="Observatoire ARTEP (monimmeuble.com), Erema Bat 2026, AZ Bâtiments 2026 : Île-de-France + 15 à 30 % sur la province, Paris intra-muros + 20 à 35 %, soit un curseur plus haut, pas une autre grille. "&"Vérifié le "&TEXT(DAY(Référentiel!$C$109),"00")&"/"&TEXT(MONTH(Référentiel!$C$109),"00")&"/"&YEAR(Référentiel!$C$109) -> Observatoire ARTEP (monimmeuble.com), Erema Bat 2026, AZ Bâtiments 2026 : Île-de-France + 15 à 30 % sur la province, Paris intra-muros + 20 à 35 %, soit un curseur plus haut, pas une autre grille. Vérifié le 05/09/2026
B29: Curseur de fourchette usuel, Paris intra-muros | C29: 0.7 | D29: 1 | J29: ="Observatoire ARTEP (monimmeuble.com), Erema Bat 2026, AZ Bâtiments 2026 : Île-de-France + 15 à 30 % sur la province, Paris intra-muros + 20 à 35 %, soit un curseur plus haut, pas une autre grille. "&"Vérifié le "&TEXT(DAY(Référentiel!$C$109),"00")&"/"&TEXT(MONTH(Référentiel!$C$109),"00")&"/"&YEAR(Référentiel!$C$109) -> Observatoire ARTEP (monimmeuble.com), Erema Bat 2026, AZ Bâtiments 2026 : Île-de-France + 15 à 30 % sur la province, Paris intra-muros + 20 à 35 %, soit un curseur plus haut, pas une autre grille. Vérifié le 05/09/2026 | K29: Les fourchettes du Référentiel sont hors Paris intra-muros : c'est le curseur qui absorbe le surcoût.
B30: Provision pour aléas, rénovation dans l'ancien | C30: 0.1 | D30: 0.15 | J30: ="maitre-doeuvre.fr, architecte-batiments.fr, 2026 : 5 à 10 % en rénovation standard, 10 à 15 % dans l'ancien, 15 à 20 % avec inconnues structurelles. "&"Vérifié le "&TEXT(DAY(Référentiel!$C$109),"00")&"/"&TEXT(MONTH(Référentiel!$C$109),"00")&"/"&YEAR(Référentiel!$C$109) -> maitre-doeuvre.fr, architecte-batiments.fr, 2026 : 5 à 10 % en rénovation standard, 10 à 15 % dans l'ancien, 15 à 20 % avec inconnues structurelles. Vérifié le 05/09/2026 | K30: En dessous, vous pariez. Jusqu'à 20 % avec inconnues structurelles.
B31: Honoraires de maîtrise d'œuvre d'exécution | C31: 0.08 | D31: 0.12 | J31: ="Ootravaux, tarifs architecte 2026 ; Meta Architecte, barème 2026 : maîtrise d'œuvre 6 à 12 %, architecte 8 à 15 %, mission complète en rénovation 12 à 18 %. "&"Vérifié le "&TEXT(DAY(Référentiel!$C$109),"00")&"/"&TEXT(MONTH(Référentiel!$C$109),"00")&"/"&YEAR(Référentiel!$C$109) -> Ootravaux, tarifs architecte 2026 ; Meta Architecte, barème 2026 : maîtrise d'œuvre 6 à 12 %, architecte 8 à 15 %, mission complète en rénovation 12 à 18 %. Vérifié le 05/09/2026 | K31: Pourcentage des travaux HT, TVA 20 %.
B32: Honoraires d'architecte en mission complète, rénovation | C32: 0.12 | D32: 0.18 | J32: ="Ootravaux, tarifs architecte 2026 ; Meta Architecte, barème 2026 : maîtrise d'œuvre 6 à 12 %, architecte 8 à 15 %, mission complète en rénovation 12 à 18 %. "&"Vérifié le "&TEXT(DAY(Référentiel!$C$109),"00")&"/"&TEXT(MONTH(Référentiel!$C$109),"00")&"/"&YEAR(Référentiel!$C$109) -> Ootravaux, tarifs architecte 2026 ; Meta Architecte, barème 2026 : maîtrise d'œuvre 6 à 12 %, architecte 8 à 15 %, mission complète en rénovation 12 à 18 %. Vérifié le 05/09/2026
B34: FAMILLES DE LOTS ET BANDES USUELLES (PART DU SOUS-TOTAL HT)
B35: Famille | C35: Part basse | D35: Part haute | J35: Source | K35: Ce qu'elle regroupe
B36: Dépose et gros œuvre | C36: 0.05 | D36: 0.12 | J36: ="Convention CorpusImmo, non sourcée : à caler sur vos propres chantiers. Elle décrit une rénovation lourde de logement ancien. "&"Vérifié le "&TEXT(DAY(Référentiel!$C$109),"00")&"/"&TEXT(MONTH(Référentiel!$C$109),"00")&"/"&YEAR(Référentiel!$C$109) -> Convention CorpusImmo, non sourcée : à caler sur vos propres chantiers. Elle décrit une rénovation lourde de logement ancien. Vérifié le 05/09/2026 | K36: Dépose et démolition, gros œuvre
B37: Enveloppe | C37: 0.1 | D37: 0.3 | J37: Idem. | K37: Toiture, menuiseries extérieures, isolation, extérieurs
B38: Technique | C38: 0.25 | D38: 0.35 | J38: Idem. | K38: Électricité, plomberie, chauffage, ventilation
B39: Cloisons et finitions | C39: 0.15 | D39: 0.28 | J39: Idem. | K39: Plâtrerie, sols, peinture, menuiseries intérieures
B40: Cuisine et salle de bains | C40: 0.12 | D40: 0.25 | J40: Idem. | K40: Cuisine équipée, salle de bains, WC
B41: Postes libres | C41: 0 | D41: 0.15 | J41: Idem. | K41: Lignes ajoutées : désamiantage, plomb, ascenseur, escalier, diagnostics
B43: LOTS ET FAMILLES : LIBELLÉS FIXES, TESTÉS PAR LES FORMULES DU CHIFFRAGE
B44: Lot | C44: Famille | K44: Commentaire
B45: Dépose et démolition | C45: Dépose et gros œuvre | K45: Renommer un lot ici sans le renommer dans le tableau des fourchettes fait sortir ses lignes du contrôle par famille (le Chiffrage le signale).
...

Sheet Méthode
B1: CorpusImmo · www.corpus.immo · Estimer, comparer, décider. Sur les ventes réelles.
B2: Méthode et limites
B3: Comment lire ce chiffrage, ce qu'il ne dit pas, et sur quelles sources reposent ses chiffres.
B5: CONVENTIONS RETENUES, ET CE QU'ELLES COÛTENT
B6: Les cinq entrées | C6: Surface habitable, nombre de niveaux, hauteur sous plafond, façades exposées, part rénovée. Elles suffisent à remplir les vingt-huit postes. Tout le reste est déduit ou forçable. Un bloc de douze réponses oui / non qualifie ensuite la TVA du chantier.
B7: Quantité auto | C7: Base × ratio, arrondie à l'unité pour que le chiffre affiché soit exactement celui qui est multiplié. La base et le ratio sont lisibles ligne à ligne dans le Référentiel.
B8: Quantité et prix forcés | C8: Une valeur saisie dans une colonne violette l'emporte toujours sur le calcul, sans le détruire : effacez-la et l'automatisme revient. C'est la colonne à remplir à mesure que les devis arrivent. Saisir 0 en quantité forcée désactive le poste.
B9: Géométrie | C9: Emprise = surface / niveaux. Périmètre = coefficient × racine de l'emprise (4,2 dans le Référentiel : 4,0 pour un carré, 4,24 pour un rectangle 2:1) : il n'est pas proportionnel à la surface, un coefficient linéaire se trompe de 30 % dès 160 m². Murs de façade = périmètre × hauteur × niveaux × façades exposées / 4 : c'est le paramètre façades qui distingue un appartement d'une maison. Toit = emprise × coefficient de pente (1,20 pour 30 à 35°). Les trois coefficients (périmètre, nombre de façades, pente) sont des cellules du Référentiel : ce ne sont plus des constantes écrites dans les formules, vous pouvez les changer.
B10: Prix retenu | C10: Prix bas + (prix haut − prix bas) × curseur. Le curseur unique représente la tension du marché et le type d'entreprise : 0 à 30 % artisans en direct en zone détendue, 40 à 60 % cas courant, 70 à 100 % entreprise générale, zone tendue, délais courts ou copropriété contraignante. Le curseur est borné de 0 à 100 % par validation. Il absorbe aussi la zone : Île-de-France + 15 à 30 % sur la province, Paris intra-muros + 20 à 35 % (Observatoire ARTEP, Erema Bat 2026), soit un curseur de 60 à 80 %, pas une autre grille.
B11: Fourchette basse et haute | C11: Le récapitulatif affiche trois colonnes : le bas de fourchette (tous les prix au curseur 0 %), le chiffrage retenu (curseur saisi) et le haut (curseur 100 %), avec les mêmes quantités et les mêmes forçages. Un prix forcé vaut dans les trois colonnes : c'est un devis, il n'a plus de fourchette. La fourchette est donc celle des postes encore non devisés.
B12: Quand forcer un prix | C12: Quatre postes ont une fourchette de 1 à 4 parce qu'ils recouvrent un choix d'équipement et non une tension de marché : pompe à chaleur ou chaudière, cuisine, salle de bains, VMC. Ils pèsent environ un tiers du budget. Le curseur ne sait pas arbitrer à votre place : forcez leur prix.
B13: Provision pour aléas | C13: Appliquée aux lots, avant honoraires et avant TVA. Ce n'est pas une marge de confort : en rénovation ancienne, la découverte à l'ouverture des murs est la première cause de dérapage. En dessous de 10 %, vous pariez.
B14: Honoraires | C14: Pourcentage des travaux hors taxes. Les fourchettes usuelles sont dans le Référentiel, bloc Repères de saisie : maîtrise d'œuvre d'exécution, et architecte en mission complète. Le commentaire de la cellule des honoraires les affiche. Ils restent à 20 % de TVA : une prestation intellectuelle ne bénéficie pas du taux réduit, même quand les travaux qu'elle pilote en bénéficient.
B15: TVA par ligne | C15: Chaque prestation porte son taux dans le Référentiel, choisi dans une liste de trois : 5,5 % sur la rénovation énergétique éligible selon l'arrêté du 24 décembre 2024 (isolation, fenêtres et portes extérieures, pompes à chaleur, y compris air/air depuis le 18 juillet 2026, VMC double flux ou hygroréglable), 10 % sur l'amélioration d'un logement achevé depuis plus de deux ans, 20 % sinon. Une chaudière gaz ou fioul est à 20 % depuis le 1er mars 2025, même à très haute performance. Une VMC simple flux autoréglable est à 10 %. Les travaux induits par une opération énergétique peuvent suivre son taux (le doublage et la peinture qui suivent une isolation) : le classeur ne l'applique pas seul, changez le taux de la ligne dans le Référentiel après vérification. Le taux forcé du Chiffrage, choisi dans la même liste, remplace tous les taux de ligne.
B16: Immeuble rendu à l'état neuf | C16: Le bloc de qualification du Chiffrage applique la règle de bascule au taux normal : local autre que d'habitation, logement de moins de deux ans au début des travaux, augmentation de la surface de plancher de plus de 10 %, ou immeuble rendu neuf. Un immeuble est rendu neuf (CGI art. 257, I-2-2° et annexe II art. 245 A) quand les travaux refont la majorité des fondations, ou la majorité des éléments hors fondations qui déterminent la résistance et la rigidité de l'ouvrage, ou la majorité de la consistance des façades hors ravalement, ou les six éléments de second œuvre chacun à au moins deux tiers : planchers non porteurs, huisseries extérieures, cloisons intérieures, installations sanitaires et plomberie, installations électriques, chauffage. Dès qu'un critère est rempli, la cellule « Taux réduits admis » passe au rouge, le taux appliqué à toutes les lignes devient 20 % et le récapitulatif suit. Le classeur compte aussi, à titre indicatif, les éléments de second œuvre que le chiffrage lui-même refait (part rénovée d'au moins deux tiers, lignes actives) et signale « À VÉRIFIER » si vous en déclarez moins. C'est le premier risque fiscal d'une rénovation lourde de marchand de biens : il touche aussi le régime de TVA de la revente, que ce classeur ne traite pas.
B17: Mention sur le devis | C17: L'attestation écrite du client pour les taux réduits est supprimée depuis février 2025 (LF 2025, art. 41). Le client certifie directement sur le devis ou la facture que les conditions sont remplies (nature du local, ancienneté, travaux n'aboutissant pas à un immeuble neuf), et conserve le document jusqu'au 31 décembre de la cinquième année. Le prestataire est déchargé si la mention est inexacte du fait du client.
... B21: Taux et formats | C21: Tous les taux sont des fractions affichées en pourcentage : tapez 12 dans la cellule des aléas, elle affiche 12,0 % et contient 0,12. Aucune formule ne divise par 100. Les quantités sont arrondies à l'unité, les montants sont en euros hors taxes puis toutes taxes comprises, la date de vérification du Référentiel est une vraie date.
B23: CE QUE CE MODÈLE NE FAIT PAS
B24: • Il ne remplace pas un devis. Il sert à décider s'il vaut la peine d'en demander trois.
B25: • Les ratios de comptage cadrent, ils ne comptent pas : au-delà de l'avant-projet, relevez sur plan.
B26: • Il suppose un logement de forme compacte. Sur un plan très développé ou très étroit, forcez les surfaces de murs.
B27: • Il ignore les contraintes de site : étage sans ascenseur, accès difficile, copropriété, ABF.
B28: • Il ne chiffre ni le désamiantage, ni le plomb, ni les fondations, ni les diagnostics et études (amiante, plomb, structure, DPE projeté), ni l'assurance dommages-ouvrage, obligatoire dès qu'il y a gros œuvre. Trois lignes libres sont prévues pour eux, à renseigner dans le Référentiel.
B29: • Il n'intègre aucune aide (MaPrimeRénov', CEE, éco-PTZ) : leurs barèmes changent trop vite pour être figés ici.
B30: • Il ne gère ni le phasage, ni les délais, ni le coût de portage.
B31: • Il n'applique pas de lui-même le taux des travaux induits (doublage, peinture après isolation) : c'est à vous de changer le taux de la ligne.
B32: • Il ne pré-positionne pas le curseur selon la zone (province, métropole, Île-de-France, Paris) : le commentaire du curseur donne les repères.
B33: • L'éligibilité au taux réduit relève de la mention certifiée par le client sur le devis ou la facture (attestation supprimée depuis février 2025), pas de ce tableau : le bloc TVA aide à qualifier, il ne certifie rien.
B34: • Il ne traite pas la TVA de la revente (TVA sur marge, régime du marchand de biens, immeuble neuf à la revente) ni les droits d'enregistrement.
B36: SOURCES
B37: TVA, taux normal | C37: ="CGI art. 278 ; Service-public Entreprendre F23568, mis à jour le 21/02/2026. "&"Vérifié le "&TEXT(DAY(Référentiel!$C$109),"00")&"/"&TEXT(MONTH(Référentiel!$C$109),"00")&"/"&YEAR(Référentiel!$C$109) -> CGI art. 278 ; Service-public Entreprendre F23568, mis à jour le 21/02/2026. Vérifié le 05/09/2026
B38: TVA, taux intermédiaire (amélioration d'un logement de plus de 2 ans) | C38: ="CGI art. 279-0 bis ; BOI-TVA-LIQ-30-20-90-10 du 22/10/2025. "&"Vérifié le "&TEXT(DAY(Référentiel!$C$109),"00")&"/"&TEXT(MONTH(Référentiel!$C$109),"00")&"/"&YEAR(Référentiel!$C$109) -> CGI art. 279-0 bis ; BOI-TVA-LIQ-30-20-90-10 du 22/10/2025. Vérifié le 05/09/2026
B39: TVA, taux réduit (rénovation énergétique éligible) | C39: ="CGI art. 278-0 bis A ; arrêté du 24/12/2024 (liste des équipements) ; BOFiP ACTU-2025-00165 du 22/10/2025 ; FFB, liste du 25/08/2026. "&"Vérifié le "&TEXT(DAY(Référentiel!$C$109),"00")&"/"&TEXT(MONTH(Référentiel!$C$109),"00")&"/"&YEAR(Référentiel!$C$109) -> CGI art. 278-0 bis A ; arrêté du 24/12/2024 (liste des équipements) ; BOFiP ACTU-2025-00165 du 22/10/2025 ; FFB, liste du 25/08/2026. Vérifié le 05/09/2026
B40: Immeuble rendu neuf : proportion de chaque élément de second œuvre | C40: ="CGI art. 257, I-2-2° ; CGI annexe II art. 245 A ; BOI-TVA-IMM-10-10-10-20 § 140 et suivants. "&"Vérifié le "&TEXT(DAY(Référentiel!$C$109),"00")&"/"&TEXT(MONTH(Référentiel!$C$109),"00")&"/"&YEAR(Référentiel!$C$109) -> CGI art. 257, I-2-2° ; CGI annexe II art. 245 A ; BOI-TVA-IMM-10-10-10-20 § 140 et suivants. Vérifié le 05/09/2026
B41: Extension de surface de plancher qui exclut les taux réduits | C41: ="CGI art. 279-0 bis, 2 bis ; BOI-TVA-LIQ-30-20-90-10 du 22/10/2025. "&"Vérifié le "&TEXT(DAY(Référentiel!$C$109),"00")&"/"&TEXT(MONTH(Référentiel!$C$109),"00")&"/"&YEAR(Référentiel!$C$109) -> CGI art. 279-0 bis, 2 bis ; BOI-TVA-LIQ-30-20-90-10 du 22/10/2025. Vérifié le 05/09/2026
B42: Ancienneté minimale du logement pour les taux réduits | C42: ="CGI art. 279-0 bis, 1 ; BOI-TVA-LIQ-30-20-90-10 § 10 : appréciée au début des travaux. "&"Vérifié le "&TEXT(DAY(Référentiel!$C$109),"00")&"/"&TEXT(MONTH(Référentiel!$C$109),"00")&"/"&YEAR(Référentiel!$C$109) -> CGI art. 279-0 bis, 1 ; BOI-TVA-LIQ-30-20-90-10 § 10 : appréciée au début des travaux. Vérifié le 05/09/2026
B43: Coefficient de périmètre (périmètre = coefficient × racine de l'emprise) | C43: ="Géométrie : 4,0 pour un carré, 4,08 pour un rectangle 1,5:1, 4,24 pour un rectangle 2:1. "&"Vérifié le "&TEXT(DAY(Référentiel!$C$109),"00")&"/"&TEXT(MONTH(Référentiel!$C$109),"00")&"/"&YEAR(Référentiel!$C$109) -> Géométrie : 4,0 pour un carré, 4,08 pour un rectangle 1,5:1, 4,24 pour un rectangle 2:1. Vérifié le 05/09/2026
B44: Nombre de façades d'un bâtiment (diviseur des façades exposées) | C44: ="Géométrie. "&"Vérifié le "&TEXT(DAY(Référentiel!$C$109),"00")&"/"&TEXT(MONTH(Référentiel!$C$109),"00")&"/"&YEAR(Référentiel!$C$109) -> Géométrie. Vérifié le 05/09/2026
B45: Coefficient de toiture (surface de toit = emprise × coefficient) | C45: ="Trigonométrie : 1/cos 30° = 1,155 ; 1/cos 35° = 1,221 ; 1,41 à 45°. "&"Vérifié le "&TEXT(DAY(Référentiel!$C$109),"00")&"/"&TEXT(MONTH(Référentiel!$C$109),"00")&"/"&YEAR(Référentiel!$C$109) -> Trigonométrie : 1/cos 30° = 1,155 ; 1/cos 35° = 1,221 ; 1,41 à 45°. Vérifié le 05/09/2026
B46: Coût TTC au m² : au-dessus, on ne rafraîchit plus, on rénove | C46: ="Hellowatt 2026 : léger 250 à 750, moyen 750 à 1 500, lourd 2 000 à 4 000 €/m² TTC ; Illico Travaux 2026 : complet 1 000 à 1 800, lourd 1 500 et plus. "&"Vérifié le "&TEXT(DAY(Référentiel!$C$109),"00")&"/"&TEXT(MONTH(Référentiel!$C$109),"00")&"/"&YEAR(Référentiel!$C$109) -> Hellowatt 2026 : léger 250 à 750, moyen 750 à 1 500, lourd 2 000 à 4 000 €/m² TTC ; Illico Travaux 2026 : complet 1 000 à 1 800, lourd 1 500 et plus. Vérifié le 05/09/2026
...
