Workbook

Sheet Mode d'emploi
B1: CorpusImmo · corpus.immo · Estimer, comparer, décider. Sur les ventes réelles.
B2: Mode d'emploi
B3: À quoi sert ce classeur, dans quel ordre le remplir, et comment lire ce qu'il répond.
B6: À QUOI SERT CE CLASSEUR
B7: Vous allez louer un appartement ou une maison, et vous hésitez : location nue au micro-foncier ou au réel, meublé au micro-BIC ou au LMNP réel (loueur en meublé non professionnel) avec amortissement, ou société civile à l'impôt sur les sociétés ? Ce classeur prend le même bien, le même loyer et le même prêt, et calcule pour chacun des cinq régimes l'impôt de chaque année, ce qui vous reste en poche après crédit et impôt, ce que vous laissez en réserve (déficits, amortissements différés), puis l'impôt et le net de la revente à la fin de la durée de détention.
B8: Il répond sur toute la durée de détention, revente comprise, et non sur la seule première année. Amortir, c'est déduire chaque année une part du prix du bâti, des travaux et du mobilier, sans rien décaisser : cela efface l'impôt pendant la détention, mais la revente en reprend une partie. Au LMNP réel, les amortissements déduits sont réintégrés dans la plus-value depuis 2025, c'est-à-dire retirés du prix d'achat que l'on retranche du prix de vente. À la SCI à l'impôt sur les sociétés, la plus-value se calcule sur la valeur nette comptable, le prix diminué de tous les amortissements déjà déduits, et sortir l'argent de la société coûte encore le prélèvement forfaitaire unique (PFU, ou flat tax). C'est là que ces deux régimes montrent leur vrai coût.
B9: Tout se saisit dans un seul onglet, Hypothèses. Le Comparateur donne la synthèse en un écran ; le Pluriannuel montre le détail année par année.
B10: Vous êtes | C10: Ce que le classeur vous donne
B11: Investisseur particulier | C11: Le régime qui laisse le plus d'argent en poche sur votre horizon, l'écart avec le suivant, et le taux de rendement interne (TRI) après impôt de chacun.
B12: Conseiller en gestion de patrimoine | C12: Une comparaison à cinq colonnes, année 1 et cumul, avec la revente, pour arbitrer nu, meublé et société devant le client.
B13: Notaire | C13: Le net de revente de chaque régime, avec la plus-value des particuliers (amortissements réintégrés en LMNP) et la plus-value professionnelle à l'IS.
B14: Expert-comptable, fiscaliste | C14: Le détail des reports d'une année sur l'autre (déficit foncier hors intérêts, amortissements différés au titre de l'article 39 C, déficit BIC, déficit IS), la distribution des dividendes et le compte courant d'associé de la SCI, la base réintégrée. Ligne par ligne dans le Pluriannuel : reports fonciers lignes 38 à 40, amortissements différés 54 à 56, déficit BIC 57 à 60, réintégration ligne 64, déficit IS 70 à 72, compte courant et dividendes 81 à 89.
B15: Agent immobilier, chasseur | C15: Un argument chiffré pour un acquéreur investisseur : ce que le bien rapporte après impôt selon la façon de le louer.
B17: LE PRINCIPE, EN UNE LIGNE
B18: Loyers − charges − mensualités du prêt − impôt de chaque année + net de revente = ce que le régime vous laisse, sur toute la durée
B20: LES ONGLETS, DANS L'ORDRE OÙ ON LES REMPLIT
B21: Onglet | C21: Ce que vous y faites | D21: Ce que vous y lisez
B22: Mode d'emploi | C22: Rien à saisir. Vous lisez ce guide. | D22: La marche à suivre et l'exemple guidé.
B23: Hypothèses | C23: Vous remplissez les six blocs de saisie, de haut en bas : le bien, l'exploitation, le financement, le foyer, la détention, les options. | D23: Huit contrôles OK / KO (C13, C23, C33, C38, C46, C58, C61, puis le contrôle général C62) et, tout en bas, le régime le plus favorable (Hypothèses!C63) avec l'écart (Hypothèses!C64).
B24: Comparateur | C24: Rien à saisir. | D24: Cinq colonnes, une par régime, et une colonne Lecture à droite qui explique chaque ligne en français. De haut en bas : éligibilité et année 1 (lignes 8 à 11), cumul sur la détention (14 à 17), revente (20 à 31), bilan, TRI et rang (34 à 38), verdict (41 à 43).
B25: Pluriannuel | C25: Rien à saisir. | D25: Trente années en colonnes (D à AG) : loyer, prêt, amortissements, puis pour chaque régime le résultat, l'impôt, les reports et le flux en poche. La colonne C donne le cumul sur la durée de détention, ou le stock en fin de détention pour les reports : c'est elle que lit le Comparateur. Les années au-delà de la détention sont grisées.
B26: Paramètres | C26: Rien, sauf à la mise à jour annuelle des barèmes et des repères. | D26: Chaque valeur avec sa source datée et sa fréquence de mise à jour, la table des abattements de durée, les listes.
B27: Méthode | C27: Rien à saisir. | D27: Les conventions, ce que le modèle ne fait pas, les points de droit signalés, les sources.
B29: LE CODE COULEUR, ET COMMENT DÉVERROUILLER UNE CELLULE
B30: Cellule | C30: Ce que c'est | D30: Ce que vous faites
B31: Fond bleu ciel, texte bleu nuit | C31: Saisie utilisateur | D31: Vous la remplissez. Jamais de formule dedans.
B32: Fond blanc | C32: Calcul | D32: Vous la lisez. Elle est verrouillée.
B33: Fond presque blanc, texte bleu nuit en gras | C33: Résultat de bloc, chiffre clé | D33: Vous la lisez. C'est un chiffre à retenir.
B34: Bandeau bleu nuit | C34: Titre de section, en-tête de tableau | D34: Repère de navigation.
B35: Texte gris, à droite | C35: Commentaire d'aide, ordre de grandeur | D35: Une phrase par ligne pour savoir quoi saisir. Les ordres de grandeur viennent de Paramètres.
B36: Vert OK / rouge À CORRIGER | C36: Contrôle de cohérence | D36: Rouge : corrigez la saisie indiquée dans le commentaire. Tant qu'un contrôle est rouge, le Comparateur reste entièrement vide, éligibilité et revente comprises : le classeur préfère ne rien afficher plutôt qu'un chiffre faux. Le Pluriannuel, lui, continue d'afficher le détail des années.
B37: Les onglets sont protégés sans mot de passe pour éviter d'écraser une formule par erreur. Les cellules bleues restent modifiables et effaçables sans rien déverrouiller. Pour modifier une cellule blanche : onglet Révision, puis « Ôter la protection de la feuille ». Aucun mot de passe n'est demandé.
B39: LA MARCHE À SUIVRE, ÉTAPE PAR ÉTAPE
B40: Étape | C40: Où (onglet et plage) | D40: Ce que vous faites | E40: Pourquoi
B41: 0. L'exemple livré | C41: Hypothèses!C7, Hypothèses!C9:C11, Hypothèses!C16:C21, Hypothèses!C26:C29, Hypothèses!C36:C37, Hypothèses!C41:C43 (vos données) ; Hypothèses!C8, Hypothèses!C49:C57 (les listes et les options, à ajuster, jamais à effacer) | D41: Le classeur arrive rempli d'un exemple. Gardez-le pour vous repérer, ou effacez vos données de projet avant de saisir votre dossier : les cinq premières plages ci-contre. Vérifiez surtout les saisies secondaires qui n'ont pas de raison d'être chez vous : travaux (Hypothèses!C10), mobilier (Hypothèses!C11), CFE (Hypothèses!C18), honoraires comptables (Hypothèses!C19 et Hypothèses!C20), autres revenus fonciers (Hypothèses!C37), prix de revente forcé (Hypothèses!C43). N'effacez jamais le mode d'acquisition (C8) ni les options C49:C57 : ce sont des listes, elles n'ont pas de valeur vide, et le classeur cesse de calculer dès qu'il en manque une. Ajustez-les une par une, ou gardez les valeurs livrées : achat à titre onéreux, meublé classique, distribution Non, frais immobilisés, rénovation énergétique Non, CSG déductible Non, terrain 15 %, bâti 30 ans, travaux 15 ans, mobilier 7 ans. | E41: Une valeur résiduelle de l'exemple est l'erreur la plus probable d'un premier usage : 8 000 € de mobilier oubliés changent l'amortissement, la CFE et les cinq TRI. Pendant que vous effacez, les contrôles passent au rouge et le Comparateur se vide : c'est normal, tout revient dès que la saisie est complète. Les cellules bleues s'effacent avec la touche Suppr, sans rien déverrouiller.
B42: 1. Le bien | C42: Hypothèses!C7, Hypothèses!C9:C11, plus le mode d'acquisition en Hypothèses!C8 | D42: Prix net vendeur, mode d'acquisition (achat à titre onéreux, succession ou donation), frais d'acquisition (notaire et agence), travaux à l'acquisition, mobilier. Vérifiez que le contrôle du bloc affiche OK. | E42: Le coût total est ce que vous financez ; frais, travaux et mobilier n'ont pas le même sort fiscal selon le régime. Le mode d'acquisition, lui, ne joue qu'à la revente : le forfait de frais de 7,5 % du prix n'est ouvert qu'aux biens achetés à titre onéreux. Sur un bien reçu par succession ou par donation, seuls vos frais réels justifiés entrent dans le prix d'acquisition, et la plus-value imposable est plus élevée.
B43: 2. L'exploitation | C43: Hypothèses!C16:C21 | D43: Loyer annuel encaissé, charges déductibles hors intérêts, cotisation foncière des entreprises (CFE, due par les régimes meublés et par la SCI), honoraires comptables du LMNP réel et de la SCI, indexation annuelle. | E43: Les charges décaissées et les honoraires pèsent différemment : déduits au réel, pas au micro ; la CFE n'existe qu'en meublé. Remettez-la à 0 si vous ne comparez que des locations nues.
B44: 3. Le financement | C44: Hypothèses!C26:C29 | D44: Montant emprunté, taux nominal, durée en années entières, taux d'assurance sur capital initial. L'apport se calcule. Les cellules de taux sont déjà au format pourcentage : tapez 3,25 pour 3,25 %, ne convertissez pas vous-même en fraction. | E44: Les intérêts décroissants alimentent chaque année la base au réel ; l'annuité complète entre dans le flux en poche. Un taux positif inférieur au plancher de plausibilité de Paramètres passe le contrôle « Taux saisis en pourcentage » (Hypothèses!C61) au rouge.
B45: 4. Le foyer | C45: Hypothèses!C36:C37 | D45: Tranche marginale d'imposition (TMI) : le taux auquel un euro de revenu supplémentaire est imposé chez vous. À choisir dans la liste. Autres revenus fonciers nets du foyer (0 sinon). | E45: La TMI fait varier l'impôt de zéro à plusieurs milliers d'euros ; les autres revenus fonciers absorbent d'abord un déficit.
B46: 5. La détention et la revente | C46: Hypothèses!C41:C43 | D46: Durée de détention (1 à 30 ans), revalorisation annuelle du bien, et au besoin un prix de revente forcé. | E46: La revente décide souvent du classement : au LMNP réel les amortissements déjà déduits sont réintégrés dans la plus-value, à la SCI la plus-value se calcule sur la valeur nette comptable (le prix diminué des amortissements), et en direct les abattements pour durée de détention effacent progressivement la plus-value.
...

Sheet Hypothèses
B1: CorpusImmo · corpus.immo · Estimer, comparer, décider. Sur les ventes réelles.
B2: Arbitrage fiscal : nu, LMNP ou SCI à l'IS
B3: Le même bien sous cinq régimes, sur toute la durée de détention, revente comprise. Saisissez ici, lisez le Comparateur.
B5: Cellules bleues : à remplir. Cellules blanches : calculées automatiquement.
B6: LE BIEN
B7: Prix net vendeur | C7: 200000 | D7: Hors frais de notaire et hors honoraires d'agence. Bien reçu : la valeur retenue pour les droits de mutation à titre gratuit.
B8: Comment le bien a été acquis | C8: Achat (à titre onéreux) | D8: Achat : le forfait de frais de 7,5 % du prix est possible à la revente, et le classeur retient le plus élevé du forfait et de vos frais réels. Succession ou donation : le forfait est fermé, seuls les frais réels ci-dessous comptent.
B9: Frais d'acquisition (notaire et agence) | C9: 16000 | D9: ="Notaire dans l'ancien : "&ROUND(Paramètres!$C$91*100,1)&" %"&" à "&ROUND(Paramètres!$C$92*100,1)&" %"&" du prix (Paramètres, repères), plus l'agence si elle est à votre charge." -> Notaire dans l'ancien : 7,5 % à 8,5 % du prix (Paramètres, repères), plus l'agence si elle est à votre charge.
B10: Travaux à l'acquisition | C10: 5000 | D10: Déduits l'année 1 au réel foncier (déficit foncier), amortis au LMNP réel et à l'IS. 0 si aucun.
B11: Mobilier et équipements | C11: 8000 | D11: Justifié par factures. Amorti au LMNP réel et à l'IS. 0 si vous ne comparez que des locations nues.
B12: Coût total de l'opération | C12: =Hypothèses!$C$7+Hypothèses!$C$9+Hypothèses!$C$10+Hypothèses!$C$11 -> 229000 | D12: Ce que vous devez financer : prix, frais, travaux, mobilier.
B13: Le bien : saisies cohérentes | C13: =IF(AND(AND(ISNUMBER(Hypothèses!$C$7),Hypothèses!$C$7>=0),Hypothèses!$C$7>0,OR(Hypothèses!$C$9="",AND(ISNUMBER(Hypothèses!$C$9),Hypothèses!$C$9>=0)),OR(Hypothèses!$C$10="",AND(ISNUMBER(Hypothèses!$C$10),Hypothèses!$C$10>=0)),OR(Hypothèses!$C$11="",AND(ISNUMBER(Hypothèses!$C$11),Hypothèses!$C$11>=0)),NOT(ISNA(MATCH(Hypothèses!$C$8,Paramètres!$E$33:$E$35,0)))),"OK","À CORRIGER") -> OK | D13: KO si le prix manque, si une saisie est négative ou n'est pas un nombre, ou si le mode d'acquisition n'est pas une valeur de sa liste.
B15: L'EXPLOITATION
B16: Loyer annuel encaissé, année 1 | C16: 13200 | D16: Hors charges récupérables, net de vacance. Le même loyer sert aux cinq régimes (voir Méthode).
B17: Charges annuelles déductibles hors intérêts, année 1 | C17: 3100 | D17: Taxe foncière hors TEOM, PNO, copropriété non récupérable, gestion, entretien courant.
B18: CFE annuelle (régimes meublés) | C18: 400 | D18: ="Base minimum 2026 : "&IF(Paramètres!$C$97>=1000,INT(Paramètres!$C$97/1000)&" "&TEXT(MOD(Paramètres!$C$97,1000),"000"),TEXT(Paramètres!$C$97,"0"))&" €"&" à "&IF(Paramètres!$C$98>=1000,INT(Paramètres!$C$98/1000)&" "&TEXT(MOD(Paramètres!$C$98,1000),"000"),TEXT(Paramètres!$C$98,"0"))&" €"&" selon la commune (Paramètres, repères). Exonérée l'année de création." -> Base minimum 2026 : 247 € à 1 179 € selon la commune (Paramètres, repères). Exonérée l'année de création.
B19: Honoraires comptables annuels, LMNP réel | C19: 500 | D19: ="Ordre de grandeur : "&IF(Paramètres!$C$93>=1000,INT(Paramètres!$C$93/1000)&" "&TEXT(MOD(Paramètres!$C$93,1000),"000"),TEXT(Paramètres!$C$93,"0"))&" €"&" à "&IF(Paramètres!$C$94>=1000,INT(Paramètres!$C$94/1000)&" "&TEXT(MOD(Paramètres!$C$94,1000),"000"),TEXT(Paramètres!$C$94,"0"))&" €"&" TTC par an (Paramètres, repères). Déduits au LMNP réel seulement." -> Ordre de grandeur : 300 € à 900 € TTC par an (Paramètres, repères). Déduits au LMNP réel seulement.
B20: Honoraires comptables annuels, SCI à l'IS | C20: 1200 | D20: ="Ordre de grandeur : "&IF(Paramètres!$C$95>=1000,INT(Paramètres!$C$95/1000)&" "&TEXT(MOD(Paramètres!$C$95,1000),"000"),TEXT(Paramètres!$C$95,"0"))&" €"&" à "&IF(Paramètres!$C$96>=1000,INT(Paramètres!$C$96/1000)&" "&TEXT(MOD(Paramètres!$C$96,1000),"000"),TEXT(Paramètres!$C$96,"0"))&" €"&" HT par an (Paramètres, repères). Déduits à l'IS seulement." -> Ordre de grandeur : 1 200 € à 2 500 € HT par an (Paramètres, repères). Déduits à l'IS seulement.
B21: Indexation annuelle des loyers et des charges | C21: 0.01 | D21: Appliquée à partir de l'année 2 au loyer, aux charges, à la CFE et aux honoraires. 0 pour raisonner en euros constants.
B22: Loyer moins charges, année 1 (avant intérêts et impôt) | C22: =Hypothèses!$C$16-Hypothèses!$C$17 -> 10100 | D22: Le résultat d'exploitation avant financement, commun aux cinq régimes.
B23: L'exploitation : saisies cohérentes | C23: =IF(AND(AND(ISNUMBER(Hypothèses!$C$16),Hypothèses!$C$16>=0),Hypothèses!$C$16>0,OR(Hypothèses!$C$17="",AND(ISNUMBER(Hypothèses!$C$17),Hypothèses!$C$17>=0)),OR(Hypothèses!$C$18="",AND(ISNUMBER(Hypothèses!$C$18),Hypothèses!$C$18>=0)),OR(Hypothèses!$C$19="",AND(ISNUMBER(Hypothèses!$C$19),Hypothèses!$C$19>=0)),OR(Hypothèses!$C$20="",AND(ISNUMBER(Hypothèses!$C$20),Hypothèses!$C$20>=0)),OR(Hypothèses!$C$21="",AND(ISNUMBER(Hypothèses!$C$21),Hypothèses!$C$21>=-0.05,Hypothèses!$C$21<=0.1))),"OK","À CORRIGER") -> OK | D23: KO si le loyer manque, si une charge est négative ou si l'indexation sort de la plage admise (de moins 5 % à 10 %).
B25: LE FINANCEMENT
B26: Montant emprunté | C26: 200000 | D26: 0 pour un achat comptant. Au plus le coût total. L'apport est la différence.
B27: Taux du prêt (hors assurance) | C27: 0.0325 | D27: ="Taux nominal annuel. Repère : "&ROUND(Paramètres!$C$87*100,2)&" %"&" à "&ROUND(Paramètres!$C$88*100,2)&" %"&" de 20 à 25 ans (Paramètres, repères). Tapez 3,25 pour 3,25 % : la cellule est déjà au format pourcentage, ne convertissez pas en fraction." -> Taux nominal annuel. Repère : 3,27 % à 3,35 % de 20 à 25 ans (Paramètres, repères). Tapez 3,25 pour 3,25 % : la cellule est déjà au format pourcentage, ne convertissez pas en fraction.
B28: Durée du prêt | C28: 20 | D28: Années entières, de 1 à 30. Vide si aucun emprunt.
B29: Taux d'assurance emprunteur (sur capital initial) | C29: 0.0034 | D29: ="Repère : "&ROUND(Paramètres!$C$90*100,2)&" %"&" à "&ROUND(Paramètres!$C$89*100,2)&" %"&" par an (Paramètres, repères). Déductible comme les intérêts." -> Repère : 0,17 % à 0,36 % par an (Paramètres, repères). Déductible comme les intérêts.
B30: Apport personnel | C30: =Hypothèses!$C$12-Hypothèses!$C$26 -> 29000 | D30: Coût total moins emprunt. À l'IS, il est placé en compte courant d'associé, remboursable sans impôt.
B31: Mensualité du prêt (capital et intérêts) | C31: =IF(AND(Hypothèses!$C$33="OK",Hypothèses!$C$26>0),IF(Hypothèses!$C$27=0,Hypothèses!$C$26/(Hypothèses!$C$28*12),-PMT(Hypothèses!$C$27/12,Hypothèses!$C$28*12,Hypothèses!$C$26)),0) -> 1134.3915 | D31: Annuité constante, taux nominal divisé par 12. Assurance en plus.
B32: Intérêts de la première année | C32: =Pluriannuel!$D$14 -> 6393.0881 | D32: Somme des douze premières échéances. Ils baissent ensuite chaque année (onglet Pluriannuel).
B33: Le financement : saisies cohérentes | C33: =IF(AND(OR(Hypothèses!$C$26="",AND(ISNUMBER(Hypothèses!$C$26),Hypothèses!$C$26>=0,Hypothèses!$C$26<=Hypothèses!$C$12)),OR(Hypothèses!$C$27="",AND(ISNUMBER(Hypothèses!$C$27),Hypothèses!$C$27>=0,Hypothèses!$C$27<=0.2)),OR(Hypothèses!$C$29="",AND(ISNUMBER(Hypothèses!$C$29),Hypothèses!$C$29>=0,Hypothèses!$C$29<=0.05)),OR(Hypothèses!$C$28="",AND(ISNUMBER(Hypothèses!$C$28),Hypothèses!$C$28>=1,Hypothèses!$C$28<=30,Hypothèses!$C$28=INT(Hypothèses!$C$28))),OR(Hypothèses!$C$26=0,ISNUMBER(Hypothèses!$C$28))),"OK","À CORRIGER") -> OK | D33: KO si l'emprunt dépasse le coût total, si la durée manque ou n'est pas entière, ou si un taux sort de la plage admise.
B35: LE FOYER FISCAL
B36: Tranche marginale d'imposition (TMI) | C36: 0.3 | D36: Taux de la tranche la plus haute de votre foyer, après les revenus de ce bien : 0, 11, 30, 41 ou 45 %.
B37: Autres revenus fonciers nets annuels du foyer | C37: 0 | D37: Revenus nets des autres biens loués nus. Ils absorbent d'abord un déficit foncier et les reports. 0 sinon.
B38: Le foyer : saisies cohérentes | C38: =IF(AND(ISNUMBER(Hypothèses!$C$36),NOT(ISNA(MATCH(Hypothèses!$C$36,Paramètres!$B$33:$B$37,0))),OR(Hypothèses!$C$37="",AND(ISNUMBER(Hypothèses!$C$37),Hypothèses!$C$37>=0))),"OK","À CORRIGER") -> OK | D38: KO si la TMI n'est pas une valeur de la liste ou si les autres revenus fonciers sont négatifs.
B40: LA DÉTENTION ET LA REVENTE
B41: Durée de détention | C41: 10 | D41: Années entières, de 1 à 30. La revente a lieu à la fin de cette année. 10 ans par défaut.
B42: Revalorisation annuelle du bien | C42: 0.015 | D42: Hausse de prix annuelle jusqu'à la revente. 0 pour une revente au prix d'achat. De moins 10 % à 20 %.
B43: Prix de revente forcé (facultatif) | D43: Vide : le prix de cession vient de la revalorisation. Un montant saisi la remplace.
B44: Durée retenue pour les calculs | C44: =IF(AND(ISNUMBER(Hypothèses!$C$41),Hypothèses!$C$41>=1,Hypothèses!$C$41<=30,Hypothèses!$C$41=INT(Hypothèses!$C$41)),Hypothèses!$C$41,1) -> 10 | D44: La durée saisie si elle est valide, sinon 1 an et le contrôle passe au rouge.
B45: Prix de cession retenu | C45: =IF(AND(ISNUMBER(Hypothèses!$C$43),Hypothèses!$C$43>0),Hypothèses!$C$43,Hypothèses!$C$7*(1+Hypothèses!$C$42)^Hypothèses!$C$44) -> 232108.17 | D45: Prix net vendeur revalorisé sur la durée, ou prix forcé.
...

Sheet Comparateur
B1: CorpusImmo · corpus.immo · Estimer, comparer, décider. Sur les ventes réelles.
B2: Comparateur
B3: Année 1, cumul sur la durée de détention, revente, TRI : le même bien sous cinq régimes, et le plus favorable. Se remplit depuis Hypothèses.
B6: Indicateur | C6: Location nue, micro-foncier | D6: Location nue, réel foncier | E6: Meublé, LMNP micro-BIC | F6: Meublé, LMNP réel | G6: SCI à l'IS | H6: Lecture
B7: ÉLIGIBILITÉ ET PREMIÈRE ANNÉE
B8: Éligibilité au régime | C8: =IF(Hypothèses!$C$62<>"OK","",IF(MAX(Pluriannuel!$D$9,INDEX(Pluriannuel!$D$9:$AG$9,Hypothèses!$C$44))<=Paramètres!$C$12,"Éligible","Non éligible")) -> Éligible | D8: =IF(Hypothèses!$C$62<>"OK","","Éligible") -> Éligible | E8: =IF(Hypothèses!$C$62<>"OK","",IF(MAX(Pluriannuel!$D$9,INDEX(Pluriannuel!$D$9:$AG$9,Hypothèses!$C$44))<=IF(ISNUMBER(MATCH(Hypothèses!$C$49,Paramètres!$B$27:$B$29,0)),INDEX(Paramètres!$D$27:$D$29,MATCH(Hypothèses!$C$49,Paramètres!$B$27:$B$29,0)),0),"Éligible","Non éligible")) -> Éligible | F8: =IF(Hypothèses!$C$62<>"OK","","Éligible") -> Éligible | G8: =IF(Hypothèses!$C$62<>"OK","","Éligible") -> Éligible | H8: Les régimes micro sont fermés au-dessus de leur plafond de recettes (testé en année 1 et en dernière année).
B9: Base imposable, année 1 | C9: =IF(Hypothèses!$C$62<>"OK","",Pluriannuel!$D$25) -> 9240 | D9: =IF(Hypothèses!$C$62<>"OK","",Pluriannuel!$D$41) -> 0 | E9: =IF(Hypothèses!$C$62<>"OK","",Pluriannuel!$D$47) -> 6600 | F9: =IF(Hypothèses!$C$62<>"OK","",Pluriannuel!$D$61) -> 0 | G9: =IF(Hypothèses!$C$62<>"OK","",Pluriannuel!$D$73) -> 0 | H9: IR : base soumise à la TMI et aux prélèvements sociaux. IS : bénéfice imposable de la société.
B10: Impôt, année 1 | C10: =IF(Hypothèses!$C$62<>"OK","",Pluriannuel!$D$26) -> 4361.28 | D10: =IF(Hypothèses!$C$62<>"OK","",Pluriannuel!$D$42) -> -591.92643 | E10: =IF(Hypothèses!$C$62<>"OK","",Pluriannuel!$D$48) -> 3207.6 | F10: =IF(Hypothèses!$C$62<>"OK","",Pluriannuel!$D$62) -> 0 | G10: =IF(Hypothèses!$C$62<>"OK","",Pluriannuel!$D$74) -> 0 | H10: IR plus prélèvements sociaux (négatif : économie d'impôt du déficit foncier). SCI : IS de la société.
B11: Flux net en poche, année 1 | C11: =IF(Hypothèses!$C$62<>"OK","",Pluriannuel!$D$28) -> -8553.9783 | D11: =IF(Hypothèses!$C$62<>"OK","",Pluriannuel!$D$44) -> -3600.7718 | E11: =IF(Hypothèses!$C$62<>"OK","",Pluriannuel!$D$50) -> -7800.2983 | F11: =IF(Hypothèses!$C$62<>"OK","",Pluriannuel!$D$66) -> -5092.6983 | G11: =IF(Hypothèses!$C$62<>"OK","",Pluriannuel!$D$86) -> -5792.6983 | H11: Loyer moins charges, annuité (capital compris) et impôt. SCI : ce que l'associé reçoit ou apporte.
B13: CUMUL SUR LA DURÉE DE DÉTENTION
B14: Impôts cumulés sur la détention | C14: =IF(Hypothèses!$C$62<>"OK","",Pluriannuel!$C$26-Pluriannuel!$C$27) -> 45628.638 | D14: =IF(Hypothèses!$C$62<>"OK","",Pluriannuel!$C$42-Pluriannuel!$C$43) -> 20000.2 | E14: =IF(Hypothèses!$C$62<>"OK","",Pluriannuel!$C$48-Pluriannuel!$C$49) -> 33558.593 | F14: =IF(Hypothèses!$C$62<>"OK","",Pluriannuel!$C$62-Pluriannuel!$C$65) -> 0 | G14: =IF(Hypothèses!$C$62<>"OK","",Pluriannuel!$C$74+Pluriannuel!$C$84) -> 0 | H14: IR et prélèvements sociaux nets de la CSG déductible ; SCI : IS plus PFU sur les dividendes. Hors revente.
B15: Flux nets cumulés sur la détention | C15: =IF(Hypothèses!$C$62<>"OK","",Pluriannuel!$C$28) -> -82887.274 | D15: =IF(Hypothèses!$C$62<>"OK","",Pluriannuel!$C$44) -> -57258.837 | E15: =IF(Hypothèses!$C$62<>"OK","",Pluriannuel!$C$50) -> -75002.114 | F15: =IF(Hypothèses!$C$62<>"OK","",Pluriannuel!$C$66) -> -46674.627 | G15: =IF(Hypothèses!$C$62<>"OK","",Pluriannuel!$C$86) -> -53998.176 | H15: Somme des flux annuels en poche, avant revente. Négatif : effort d'épargne cumulé.
B16: Reports non consommés en fin de détention | C16: =IF(Hypothèses!$C$62<>"OK","",0) -> 0 | D16: =IF(Hypothèses!$C$62<>"OK","",Pluriannuel!$C$40) -> 0 | E16: =IF(Hypothèses!$C$62<>"OK","",0) -> 0 | F16: =IF(Hypothèses!$C$62<>"OK","",Pluriannuel!$C$56+Pluriannuel!$C$60) -> 35295.025 | G16: =IF(Hypothèses!$C$62<>"OK","",Pluriannuel!$C$72) -> 42618.574 | H16: Déficits fonciers, amortissements différés et déficits BIC, déficit IS : ce que le régime laisse en réserve.
B17: Trésorerie restant en société | C17: ="" | D17: ="" | E17: ="" | F17: ="" | G17: =IF(Hypothèses!$C$62<>"OK","",Pluriannuel!$C$87) -> 0 | H17: SCI seulement : l'argent qui n'est pas un revenu tant qu'il n'est pas distribué.
B19: REVENTE À LA FIN DE LA DÉTENTION
B20: Prix de cession | C20: =IF(Hypothèses!$C$62<>"OK","",Hypothèses!$C$45) -> 232108.17 | D20: =IF(Hypothèses!$C$62<>"OK","",Hypothèses!$C$45) -> 232108.17 | E20: =IF(Hypothèses!$C$62<>"OK","",Hypothèses!$C$45) -> 232108.17 | F20: =IF(Hypothèses!$C$62<>"OK","",Hypothèses!$C$45) -> 232108.17 | G20: =IF(Hypothèses!$C$62<>"OK","",Hypothèses!$C$45) -> 232108.17 | H20: Prix revalorisé ou prix forcé (Hypothèses).
B21: Prix d'acquisition retenu ou valeur nette comptable | C21: =IF(Hypothèses!$C$62<>"OK","",Hypothèses!$C$7+IF(Hypothèses!$C$8=Paramètres!$E$33,MAX(Hypothèses!$C$9,Hypothèses!$C$7*Paramètres!$C$21),Hypothèses!$C$9)+IF(Hypothèses!$C$44>Paramètres!$C$23,Hypothèses!$C$7*Paramètres!$C$22,0)) -> 246000 | D21: =IF(Hypothèses!$C$62<>"OK","",Hypothèses!$C$7+IF(Hypothèses!$C$8=Paramètres!$E$33,MAX(Hypothèses!$C$9,Hypothèses!$C$7*Paramètres!$C$21),Hypothèses!$C$9)+IF(Hypothèses!$C$44>Paramètres!$C$23,Hypothèses!$C$7*Paramètres!$C$22,0)) -> 246000 | E21: =IF(Hypothèses!$C$62<>"OK","",Hypothèses!$C$7+IF(Hypothèses!$C$8=Paramètres!$E$33,MAX(Hypothèses!$C$9,Hypothèses!$C$7*Paramètres!$C$21),Hypothèses!$C$9)+IF(Hypothèses!$C$44>Paramètres!$C$23,Hypothèses!$C$7*Paramètres!$C$22,0)) -> 246000 | F21: =IF(Hypothèses!$C$62<>"OK","",Hypothèses!$C$7+IF(Hypothèses!$C$8=Paramètres!$E$33,MAX(Hypothèses!$C$9,Hypothèses!$C$7*Paramètres!$C$21),Hypothèses!$C$9)+IF(Hypothèses!$C$44>Paramètres!$C$23,Hypothèses!$C$7*Paramètres!$C$22,0)-Pluriannuel!$C$64) -> 212092.47 | G21: =IF(Hypothèses!$C$62<>"OK","",Hypothèses!$C$7+IF(Hypothèses!$C$51=Paramètres!$D$33,Hypothèses!$C$9,0)+Hypothèses!$C$10+Hypothèses!$C$11-Pluriannuel!$C$22) -> 156466.67 | H21: Particuliers : prix, frais (réels, ou forfait de 7,5 % si le bien a été acheté à titre onéreux), forfait travaux après cinq ans, moins les amortissements déduits en LMNP réel. SCI : VNC.
B22: dont amortissements réintégrés dans la plus-value | C22: ="" | D22: ="" | E22: ="" | F22: =IF(Hypothèses!$C$62<>"OK","",Pluriannuel!$C$64) -> 33907.527 | G22: ="" | H22: LMNP réel seulement : les amortissements déduits sur l'immeuble (bâti, frais immobilisés, travaux) viennent en moins du prix d'acquisition depuis 2025. Détail année par année dans le Pluriannuel.
B23: Plus-value imposable | C23: =IF(Hypothèses!$C$62<>"OK","",MAX(0,$C$20-$C$21)) -> 0 | D23: =IF(Hypothèses!$C$62<>"OK","",MAX(0,$D$20-$D$21)) -> 0 | E23: =IF(Hypothèses!$C$62<>"OK","",MAX(0,$E$20-$E$21)) -> 0 | F23: =IF(Hypothèses!$C$62<>"OK","",MAX(0,$F$20-$F$21)) -> 20015.692 | G23: =IF(Hypothèses!$C$62<>"OK","",$G$20-$G$21) -> 75641.498 | H23: Particuliers : avant abattements pour durée (une moins-value vaut 0). SCI : plus-value professionnelle sur VNC.
B24: dont plus-value imposable à l'impôt sur le revenu | C24: =IF(Hypothèses!$C$62<>"OK","",$C$23*(1-INDEX(Paramètres!$C$41:$C$70,Hypothèses!$C$44))) -> 0 | D24: =IF(Hypothèses!$C$62<>"OK","",$D$23*(1-INDEX(Paramètres!$C$41:$C$70,Hypothèses!$C$44))) -> 0 | E24: =IF(Hypothèses!$C$62<>"OK","",$E$23*(1-INDEX(Paramètres!$C$41:$C$70,Hypothèses!$C$44))) -> 0 | F24: =IF(Hypothèses!$C$62<>"OK","",$F$23*(1-INDEX(Paramètres!$C$41:$C$70,Hypothèses!$C$44))) -> 14010.984 | G24: ="" | H24: Particuliers : la plus-value après l'abattement pour durée de détention applicable à l'impôt sur le revenu. C'est l'assiette de la surtaxe ci-dessous, et non celle des prélèvements sociaux, qui est plus élevée. Vide à l'IS.
B25: Surtaxe sur les plus-values élevées | C25: =IF(Hypothèses!$C$62<>"OK","",IF($C$24<=INDEX(Paramètres!$B$74:$B$83,1),0,MAX(0,INDEX(Paramètres!$C$74:$C$83,MATCH($C$24,Paramètres!$B$74:$B$83,1))*$C$24-INDEX(Paramètres!$D$74:$D$83,MATCH($C$24,Paramètres!$B$74:$B$83,1))*MAX(0,INDEX(Paramètres!$E$74:$E$83,MATCH($C$24,Paramètres!$B$74:$B$83,1))-$C$24)))) -> 0 | D25: =IF(Hypothèses!$C$62<>"OK","",IF($D$24<=INDEX(Paramètres!$B$74:$B$83,1),0,MAX(0,INDEX(Paramètres!$C$74:$C$83,MATCH($D$24,Paramètres!$B$74:$B$83,1))*$D$24-INDEX(Paramètres!$D$74:$D$83,MATCH($D$24,Paramètres!$B$74:$B$83,1))*MAX(0,INDEX(Paramètres!$E$74:$E$83,MATCH($D$24,Paramètres!$B$74:$B$83,1))-$D$24)))) -> 0 | E25: =IF(Hypothèses!$C$62<>"OK","",IF($E$24<=INDEX(Paramètres!$B$74:$B$83,1),0,MAX(0,INDEX(Paramètres!$C$74:$C$83,MATCH($E$24,Paramètres!$B$74:$B$83,1))*$E$24-INDEX(Paramètres!$D$74:$D$83,MATCH($E$24,Paramètres!$B$74:$B$83,1))*MAX(0,INDEX(Paramètres!$E$74:$E$83,MATCH($E$24,Paramètres!$B$74:$B$83,1))-$E$24)))) -> 0 | F25: =IF(Hypothèses!$C$62<>"OK","",IF($F$24<=INDEX(Paramètres!$B$74:$B$83,1),0,MAX(0,INDEX(Paramètres!$C$74:$C$83,MATCH($F$24,Paramètres!$B$74:$B$83,1))*$F$24-INDEX(Paramètres!$D$74:$D$83,MATCH($F$24,Paramètres!$B$74:$B$83,1))*MAX(0,INDEX(Paramètres!$E$74:$E$83,MATCH($F$24,Paramètres!$B$74:$B$83,1))-$F$24)))) -> 0 | G25: ="" | H25: Taxe par tranches de 2 à 6 % au-delà de 50 000 € de plus-value imposable à l'impôt sur le revenu (CGI art. 1609 nonies G), barème et lissage dans Paramètres. Elle ne vise que les plus-values des particuliers : la SCI à l'IS en est hors du champ, la cellule reste vide.
B26: IS sur la plus-value de cession | C26: ="" | D26: ="" | E26: ="" | F26: ="" | G26: =IF(Hypothèses!$C$62<>"OK","",(MIN(MAX(0,INDEX(Pluriannuel!$D$73:$AG$73,Hypothèses!$C$44)+$G$23-Pluriannuel!$C$72),Paramètres!$C$16)*Paramètres!$C$15+MAX(0,MAX(0,INDEX(Pluriannuel!$D$73:$AG$73,Hypothèses!$C$44)+$G$23-Pluriannuel!$C$72)-Paramètres!$C$16)*Paramètres!$C$17)-(MIN(INDEX(Pluriannuel!$D$73:$AG$73,Hypothèses!$C$44),Paramètres!$C$16)*Paramètres!$C$15+MAX(0,INDEX(Pluriannuel!$D$73:$AG$73,Hypothèses!$C$44)-Paramètres!$C$16)*Paramètres!$C$17)) -> 4953.4386 | H26: SCI : après imputation du déficit reportable, au barème 15 % / 25 % de l'exercice.
B27: Trésorerie de liquidation | C27: ="" | D27: ="" | E27: ="" | F27: ="" | G27: =IF(Hypothèses!$C$62<>"OK","",Pluriannuel!$C$87+$G$20-Pluriannuel!$C$18-$G$26) -> 111067.66 | H27: SCI : trésorerie, plus prix de cession, moins capital restant dû, moins IS.
B28: Remboursement du compte courant d'associé | C28: ="" | D28: ="" | E28: ="" | F28: ="" | G28: =IF(Hypothèses!$C$62<>"OK","",MIN($G$27,Pluriannuel!$C$88)) -> 82998.176 | H28: SCI : restitué sans impôt (négatif : l'associé comble le passif).
B29: Boni de liquidation | C29: ="" | D29: ="" | E29: ="" | F29: ="" | G29: =IF(Hypothèses!$C$62<>"OK","",MAX(0,$G$27-Pluriannuel!$C$88)) -> 28069.486 | H29: SCI : le surplus, imposé au PFU comme un dividende.
B30: Impôt total à la revente | C30: =IF(Hypothèses!$C$62<>"OK","",$C$24*Paramètres!$C$19+$C$23*(1-INDEX(Paramètres!$D$41:$D$70,Hypothèses!$C$44))*Paramètres!$C$20+$C$25) -> 0 | D30: =IF(Hypothèses!$C$62<>"OK","",$D$24*Paramètres!$C$19+$D$23*(1-INDEX(Paramètres!$D$41:$D$70,Hypothèses!$C$44))*Paramètres!$C$20+$D$25) -> 0 | E30: =IF(Hypothèses!$C$62<>"OK","",$E$24*Paramètres!$C$19+$E$23*(1-INDEX(Paramètres!$D$41:$D$70,Hypothèses!$C$44))*Paramètres!$C$20+$E$25) -> 0 | F30: =IF(Hypothèses!$C$62<>"OK","",$F$24*Paramètres!$C$19+$F$23*(1-INDEX(Paramètres!$D$41:$D$70,Hypothèses!$C$44))*Paramètres!$C$20+$F$25) -> 5820.7633 | G30: =IF(Hypothèses!$C$62<>"OK","",$G$26+$G$29*Paramètres!$C$18) -> 13767.257 | H30: Particuliers : 19 % d'IR et 17,2 % de prélèvements sociaux après abattements pour durée, plus la surtaxe ci-dessus. SCI : IS sur la plus-value plus PFU sur le boni.
B31: Net de revente en poche | C31: =IF(Hypothèses!$C$62<>"OK","",$C$20-Pluriannuel!$C$18-$C$30) -> 116021.1 | D31: =IF(Hypothèses!$C$62<>"OK","",$D$20-Pluriannuel!$C$18-$D$30) -> 116021.1 | E31: =IF(Hypothèses!$C$62<>"OK","",$E$20-Pluriannuel!$C$18-$E$30) -> 116021.1 | F31: =IF(Hypothèses!$C$62<>"OK","",$F$20-Pluriannuel!$C$18-$F$30) -> 110200.34 | G31: =IF(Hypothèses!$C$62<>"OK","",$G$28+$G$29*(1-Paramètres!$C$18)) -> 102253.84 | H31: Prix de cession moins capital restant dû moins impôt. SCI : compte courant remboursé plus boni net.
B33: BILAN SUR LA DURÉE DE DÉTENTION
B34: Total net en poche après impôt et après revente | C34: =IF(Hypothèses!$C$62<>"OK","",IF($C$8="Éligible",$C$15+$C$31,"Non éligible")) -> 33133.826 | D34: =IF(Hypothèses!$C$62<>"OK","",IF($D$8="Éligible",$D$15+$D$31,"Non éligible")) -> 58762.264 | E34: =IF(Hypothèses!$C$62<>"OK","",IF($E$8="Éligible",$E$15+$E$31,"Non éligible")) -> 41018.986 | F34: =IF(Hypothèses!$C$62<>"OK","",IF($F$8="Éligible",$F$15+$F$31,"Non éligible")) -> 63525.71 | G34: =IF(Hypothèses!$C$62<>"OK","",IF($G$8="Éligible",$G$15+$G$31,"Non éligible")) -> 48255.667 | H34: Flux nets cumulés plus net de revente. C'est le chiffre qui classe les régimes.
B35: Gain net après remboursement de l'apport | C35: =IF(ISNUMBER($C$34),$C$34-Hypothèses!$C$30,"") -> 4133.826 | D35: =IF(ISNUMBER($D$34),$D$34-Hypothèses!$C$30,"") -> 29762.264 | E35: =IF(ISNUMBER($E$34),$E$34-Hypothèses!$C$30,"") -> 12018.986 | F35: =IF(ISNUMBER($F$34),$F$34-Hypothèses!$C$30,"") -> 34525.71 | G35: =IF(ISNUMBER($G$34),$G$34-Hypothèses!$C$30,"") -> 19255.667 | H35: Total net moins l'apport initial. Négatif : l'opération détruit de la valeur.
B36: TRI après impôt | C36: =IF(ISNUMBER($C$34),IF(AND(MIN(Pluriannuel!$C$92:$AG$92)<0,MAX(Pluriannuel!$C$92:$AG$92)>0),IRR(Pluriannuel!$C$92:$AG$92,IF($C$35<0,-0.2,0.05)),"n.d."),"") -> 0.0060598173 | D36: =IF(ISNUMBER($D$34),IF(AND(MIN(Pluriannuel!$C$93:$AG$93)<0,MAX(Pluriannuel!$C$93:$AG$93)>0),IRR(Pluriannuel!$C$93:$AG$93,IF($D$35<0,-0.2,0.05)),"n.d."),"") -> 0.046979946 | E36: =IF(ISNUMBER($E$34),IF(AND(MIN(Pluriannuel!$C$94:$AG$94)<0,MAX(Pluriannuel!$C$94:$AG$94)>0),IRR(Pluriannuel!$C$94:$AG$94,IF($E$35<0,-0.2,0.05)),"n.d."),"") -> 0.01782064 | F36: =IF(ISNUMBER($F$34),IF(AND(MIN(Pluriannuel!$C$95:$AG$95)<0,MAX(Pluriannuel!$C$95:$AG$95)>0),IRR(Pluriannuel!$C$95:$AG$95,IF($F$35<0,-0.2,0.05)),"n.d."),"") -> 0.055035895 | G36: =IF(ISNUMBER($G$34),IF(AND(MIN(Pluriannuel!$C$96:$AG$96)<0,MAX(Pluriannuel!$C$96:$AG$96)>0),IRR(Pluriannuel!$C$96:$AG$96,IF($G$35<0,-0.2,0.05)),"n.d."),"") -> 0.031670479 | H36: Taux de rendement interne des flux de l'investisseur, apport en année 0, revente en fin de détention.
B37: Écart avec le meilleur régime | C37: =IF(ISNUMBER($C$34),MAX($C$34:$G$34)-$C$34,"") -> 30391.884 | D37: =IF(ISNUMBER($D$34),MAX($C$34:$G$34)-$D$34,"") -> 4763.4458 | E37: =IF(ISNUMBER($E$34),MAX($C$34:$G$34)-$E$34,"") -> 22506.723 | F37: =IF(ISNUMBER($F$34),MAX($C$34:$G$34)-$F$34,"") -> 0 | G37: =IF(ISNUMBER($G$34),MAX($C$34:$G$34)-$G$34,"") -> 15270.043 | H37: En euros sur toute la durée. 0 sur le régime le plus favorable.
B38: Rang | C38: =IF(ISNUMBER($C$34),COUNTIF($C$34:$G$34,">"&$C$34)+1,"") -> 5 | D38: =IF(ISNUMBER($D$34),COUNTIF($C$34:$G$34,">"&$D$34)+1,"") -> 2 | E38: =IF(ISNUMBER($E$34),COUNTIF($C$34:$G$34,">"&$E$34)+1,"") -> 4 | F38: =IF(ISNUMBER($F$34),COUNTIF($C$34:$G$34,">"&$F$34)+1,"") -> 1 | G38: =IF(ISNUMBER($G$34),COUNTIF($C$34:$G$34,">"&$G$34)+1,"") -> 3 | H38: 1 : le plus favorable.
B40: VERDICT
B41: Régime le plus favorable sur la durée | C41: =IF(Hypothèses!$C$62<>"OK","",INDEX($C$6:$G$6,MATCH(MAX($C$34:$G$34),$C$34:$G$34,0))) -> Meublé, LMNP réel | H41: Total net le plus élevé parmi les régimes éligibles.
B42: Écart avec le régime suivant | C42: =IF(Hypothèses!$C$62<>"OK","",IF(COUNT($C$34:$G$34)>=2,MAX($C$34:$G$34)-LARGE($C$34:$G$34,2),0)) -> 4763.4458 | H42: Un écart inférieur au coût d'une comptabilité ou d'une structure ne tranche rien.
B43: Classement sans ex aequo | C43: =IF(AND(Hypothèses!$C$62="OK",COUNTIF($C$34:$G$34,MAX($C$34:$G$34))=1),"OK","À CORRIGER") -> OK | H43: KO si deux régimes arrivent à égalité parfaite : le premier nommé l'emporte par ordre de colonne.
B45: CorpusImmo, millésime 2026. Modèle d'aide à la décision : ne constitue ni un conseil en investissement, ni un conseil fiscal, ni une expertise au sens de la charte de l'expertise en évaluation immobilière. Vérifiez les paramètres avant tout engagement.

Sheet Pluriannuel
B1: CorpusImmo · corpus.immo · Estimer, comparer, décider. Sur les ventes réelles.
B2: Pluriannuel
B3: Année par année, pour chaque régime : résultat fiscal, impôt, reports, flux net en poche. Colonne C : cumul (ou valeur en fin de détention pour les stocks). Les années au-delà de la détention sont grisées.
B6: Année | C6: Cumul sur la détention, ou fin de détention | D6: 1 | E6: 2 | F6: 3 | G6: 4 | H6: 5 | I6: 6 | J6: 7 | K6: 8 | L6: 9 | M6: 10 | N6: 11 | O6: 12 | P6: 13 | Q6: 14 | R6: 15 | S6: 16 | T6: 17 | U6: 18 | V6: 19 | W6: 20 | X6: 21 | Y6: 22 | Z6: 23 | AA6: 24 | AB6: 25 | AC6: 26 | AD6: 27 | AE6: 28 | AF6: 29 | AG6: 30
B8: LE BIEN, LE LOYER ET LE PRÊT
B9: Loyer encaissé | C9: =SUMPRODUCT((D$6:AG$6<=Hypothèses!$C$44)*(D9:AG9)) -> 138101.21 | D9: =Hypothèses!$C$16*(1+Hypothèses!$C$21)^(D$6-1) -> 13200 | E9: =Hypothèses!$C$16*(1+Hypothèses!$C$21)^(E$6-1) -> 13332 | F9: =Hypothèses!$C$16*(1+Hypothèses!$C$21)^(F$6-1) -> 13465.32 | G9: =Hypothèses!$C$16*(1+Hypothèses!$C$21)^(G$6-1) -> 13599.973 | H9: =Hypothèses!$C$16*(1+Hypothèses!$C$21)^(H$6-1) -> 13735.973 | I9: =Hypothèses!$C$16*(1+Hypothèses!$C$21)^(I$6-1) -> 13873.333 | J9: =Hypothèses!$C$16*(1+Hypothèses!$C$21)^(J$6-1) -> 14012.066 | K9: =Hypothèses!$C$16*(1+Hypothèses!$C$21)^(K$6-1) -> 14152.187 | ... AG9: =Hypothèses!$C$16*(1+Hypothèses!$C$21)^(AG$6-1) -> 17615.451
B10: Charges déductibles hors intérêts | C10: =SUMPRODUCT((D$6:AG$6<=Hypothèses!$C$44)*(D10:AG10)) -> 32432.859 | D10: =Hypothèses!$C$17*(1+Hypothèses!$C$21)^(D$6-1) -> 3100 | E10: =Hypothèses!$C$17*(1+Hypothèses!$C$21)^(E$6-1) -> 3131 | F10: =Hypothèses!$C$17*(1+Hypothèses!$C$21)^(F$6-1) -> 3162.31 | G10: =Hypothèses!$C$17*(1+Hypothèses!$C$21)^(G$6-1) -> 3193.9331 | H10: =Hypothèses!$C$17*(1+Hypothèses!$C$21)^(H$6-1) -> 3225.8724 | I10: =Hypothèses!$C$17*(1+Hypothèses!$C$21)^(I$6-1) -> 3258.1312 | J10: =Hypothèses!$C$17*(1+Hypothèses!$C$21)^(J$6-1) -> 3290.7125 | K10: =Hypothèses!$C$17*(1+Hypothèses!$C$21)^(K$6-1) -> 3323.6196 | ... AG10: =Hypothèses!$C$17*(1+Hypothèses!$C$21)^(AG$6-1) -> 4136.962
B11: CFE (régimes meublés) | C11: =SUMPRODUCT((D$6:AG$6<=Hypothèses!$C$44)*(D11:AG11)) -> 4184.885 | D11: =Hypothèses!$C$18*(1+Hypothèses!$C$21)^(D$6-1) -> 400 | E11: =Hypothèses!$C$18*(1+Hypothèses!$C$21)^(E$6-1) -> 404 | F11: =Hypothèses!$C$18*(1+Hypothèses!$C$21)^(F$6-1) -> 408.04 | G11: =Hypothèses!$C$18*(1+Hypothèses!$C$21)^(G$6-1) -> 412.1204 | H11: =Hypothèses!$C$18*(1+Hypothèses!$C$21)^(H$6-1) -> 416.2416 | I11: =Hypothèses!$C$18*(1+Hypothèses!$C$21)^(I$6-1) -> 420.40402 | J11: =Hypothèses!$C$18*(1+Hypothèses!$C$21)^(J$6-1) -> 424.60806 | K11: =Hypothèses!$C$18*(1+Hypothèses!$C$21)^(K$6-1) -> 428.85414 | ... AG11: =Hypothèses!$C$18*(1+Hypothèses!$C$21)^(AG$6-1) -> 533.80155
B12: Honoraires comptables LMNP réel | C12: =SUMPRODUCT((D$6:AG$6<=Hypothèses!$C$44)*(D12:AG12)) -> 5231.1063 | D12: =Hypothèses!$C$19*(1+Hypothèses!$C$21)^(D$6-1) -> 500 | E12: =Hypothèses!$C$19*(1+Hypothèses!$C$21)^(E$6-1) -> 505 | F12: =Hypothèses!$C$19*(1+Hypothèses!$C$21)^(F$6-1) -> 510.05 | G12: =Hypothèses!$C$19*(1+Hypothèses!$C$21)^(G$6-1) -> 515.1505 | H12: =Hypothèses!$C$19*(1+Hypothèses!$C$21)^(H$6-1) -> 520.30201 | I12: =Hypothèses!$C$19*(1+Hypothèses!$C$21)^(I$6-1) -> 525.50503 | J12: =Hypothèses!$C$19*(1+Hypothèses!$C$21)^(J$6-1) -> 530.76008 | K12: =Hypothèses!$C$19*(1+Hypothèses!$C$21)^(K$6-1) -> 536.06768 | ... AG12: =Hypothèses!$C$19*(1+Hypothèses!$C$21)^(AG$6-1) -> 667.25194
B13: Honoraires comptables SCI IS | C13: =SUMPRODUCT((D$6:AG$6<=Hypothèses!$C$44)*(D13:AG13)) -> 12554.655 | D13: =Hypothèses!$C$20*(1+Hypothèses!$C$21)^(D$6-1) -> 1200 | E13: =Hypothèses!$C$20*(1+Hypothèses!$C$21)^(E$6-1) -> 1212 | F13: =Hypothèses!$C$20*(1+Hypothèses!$C$21)^(F$6-1) -> 1224.12 | G13: =Hypothèses!$C$20*(1+Hypothèses!$C$21)^(G$6-1) -> 1236.3612 | H13: =Hypothèses!$C$20*(1+Hypothèses!$C$21)^(H$6-1) -> 1248.7248 | I13: =Hypothèses!$C$20*(1+Hypothèses!$C$21)^(I$6-1) -> 1261.2121 | J13: =Hypothèses!$C$20*(1+Hypothèses!$C$21)^(J$6-1) -> 1273.8242 | K13: =Hypothèses!$C$20*(1+Hypothèses!$C$21)^(K$6-1) -> 1286.5624 | ... AG13: =Hypothèses!$C$20*(1+Hypothèses!$C$21)^(AG$6-1) -> 1601.4047
B14: Intérêts d'emprunt | C14: =SUMPRODUCT((D$6:AG$6<=Hypothèses!$C$44)*(D14:AG14)) -> 52214.047 | D14: =IF(OR(NOT(AND(Hypothèses!$C$26>0,Hypothèses!$C$33="OK",D$6<=Hypothèses!$C$28)),Hypothèses!$C$27=0),0,-CUMIPMT(Hypothèses!$C$27/12,Hypothèses!$C$28*12,Hypothèses!$C$26,12*(D$6-1)+1,12*D$6,0)) -> 6393.0881 | E14: =IF(OR(NOT(AND(Hypothèses!$C$26>0,Hypothèses!$C$33="OK",E$6<=Hypothèses!$C$28)),Hypothèses!$C$27=0),0,-CUMIPMT(Hypothèses!$C$27/12,Hypothèses!$C$28*12,Hypothèses!$C$26,12*(E$6-1)+1,12*E$6,0)) -> 6154.9239 | F14: =IF(OR(NOT(AND(Hypothèses!$C$26>0,Hypothèses!$C$33="OK",F$6<=Hypothèses!$C$28)),Hypothèses!$C$27=0),0,-CUMIPMT(Hypothèses!$C$27/12,Hypothèses!$C$28*12,Hypothèses!$C$26,12*(F$6-1)+1,12*F$6,0)) -> 5908.903 | G14: =IF(OR(NOT(AND(Hypothèses!$C$26>0,Hypothèses!$C$33="OK",G$6<=Hypothèses!$C$28)),Hypothèses!$C$27=0),0,-CUMIPMT(Hypothèses!$C$27/12,Hypothèses!$C$28*12,Hypothèses!$C$26,12*(G$6-1)+1,12*G$6,0)) -> 5654.7663 | H14: =IF(OR(NOT(AND(Hypothèses!$C$26>0,Hypothèses!$C$33="OK",H$6<=Hypothèses!$C$28)),Hypothèses!$C$27=0),0,-CUMIPMT(Hypothèses!$C$27/12,Hypothèses!$C$28*12,Hypothèses!$C$26,12*(H$6-1)+1,12*H$6,0)) -> 5392.2459 | I14: =IF(OR(NOT(AND(Hypothèses!$C$26>0,Hypothèses!$C$33="OK",I$6<=Hypothèses!$C$28)),Hypothèses!$C$27=0),0,-CUMIPMT(Hypothèses!$C$27/12,Hypothèses!$C$28*12,Hypothèses!$C$26,12*(I$6-1)+1,12*I$6,0)) -> 5121.0655 | J14: =IF(OR(NOT(AND(Hypothèses!$C$26>0,Hypothèses!$C$33="OK",J$6<=Hypothèses!$C$28)),Hypothèses!$C$27=0),0,-CUMIPMT(Hypothèses!$C$27/12,Hypothèses!$C$28*12,Hypothèses!$C$26,12*(J$6-1)+1,12*J$6,0)) -> 4840.9391 | K14: =IF(OR(NOT(AND(Hypothèses!$C$26>0,Hypothèses!$C$33="OK",K$6<=Hypothèses!$C$28)),Hypothèses!$C$27=0),0,-CUMIPMT(Hypothèses!$C$27/12,Hypothèses!$C$28*12,Hypothèses!$C$26,12*(K$6-1)+1,12*K$6,0)) -> 4551.5718 | ... AG14: =IF(OR(NOT(AND(Hypothèses!$C$26>0,Hypothèses!$C$33="OK",AG$6<=Hypothèses!$C$28)),Hypothèses!$C$27=0),0,-CUMIPMT(Hypothèses!$C$27/12,Hypothèses!$C$28*12,Hypothèses!$C$26,12*(AG$6-1)+1,12*AG$6,0)) -> 0
B15: Capital remboursé | C15: =SUMPRODUCT((D$6:AG$6<=Hypothèses!$C$44)*(D15:AG15)) -> 83912.935 | D15: =IF(NOT(AND(Hypothèses!$C$26>0,Hypothèses!$C$33="OK",D$6<=Hypothèses!$C$28)),0,IF(Hypothèses!$C$27=0,Hypothèses!$C$26/Hypothèses!$C$28,-CUMPRINC(Hypothèses!$C$27/12,Hypothèses!$C$28*12,Hypothèses!$C$26,12*(D$6-1)+1,12*D$6,0))) -> 7219.6102 | E15: =IF(NOT(AND(Hypothèses!$C$26>0,Hypothèses!$C$33="OK",E$6<=Hypothèses!$C$28)),0,IF(Hypothèses!$C$27=0,Hypothèses!$C$26/Hypothèses!$C$28,-CUMPRINC(Hypothèses!$C$27/12,Hypothèses!$C$28*12,Hypothèses!$C$26,12*(E$6-1)+1,12*E$6,0))) -> 7457.7744 | F15: =IF(NOT(AND(Hypothèses!$C$26>0,Hypothèses!$C$33="OK",F$6<=Hypothèses!$C$28)),0,IF(Hypothèses!$C$27=0,Hypothèses!$C$26/Hypothèses!$C$28,-CUMPRINC(Hypothèses!$C$27/12,Hypothèses!$C$28*12,Hypothèses!$C$26,12*(F$6-1)+1,12*F$6,0))) -> 7703.7953 | G15: =IF(NOT(AND(Hypothèses!$C$26>0,Hypothèses!$C$33="OK",G$6<=Hypothèses!$C$28)),0,IF(Hypothèses!$C$27=0,Hypothèses!$C$26/Hypothèses!$C$28,-CUMPRINC(Hypothèses!$C$27/12,Hypothèses!$C$28*12,Hypothèses!$C$26,12*(G$6-1)+1,12*G$6,0))) -> 7957.932 | H15: =IF(NOT(AND(Hypothèses!$C$26>0,Hypothèses!$C$33="OK",H$6<=Hypothèses!$C$28)),0,IF(Hypothèses!$C$27=0,Hypothèses!$C$26/Hypothèses!$C$28,-CUMPRINC(Hypothèses!$C$27/12,Hypothèses!$C$28*12,Hypothèses!$C$26,12*(H$6-1)+1,12*H$6,0))) -> 8220.4523 | I15: =IF(NOT(AND(Hypothèses!$C$26>0,Hypothèses!$C$33="OK",I$6<=Hypothèses!$C$28)),0,IF(Hypothèses!$C$27=0,Hypothèses!$C$26/Hypothèses!$C$28,-CUMPRINC(Hypothèses!$C$27/12,Hypothèses!$C$28*12,Hypothèses!$C$26,12*(I$6-1)+1,12*I$6,0))) -> 8491.6328 | J15: =IF(NOT(AND(Hypothèses!$C$26>0,Hypothèses!$C$33="OK",J$6<=Hypothèses!$C$28)),0,IF(Hypothèses!$C$27=0,Hypothèses!$C$26/Hypothèses!$C$28,-CUMPRINC(Hypothèses!$C$27/12,Hypothèses!$C$28*12,Hypothèses!$C$26,12*(J$6-1)+1,12*J$6,0))) -> 8771.7592 | K15: =IF(NOT(AND(Hypothèses!$C$26>0,Hypothèses!$C$33="OK",K$6<=Hypothèses!$C$28)),0,IF(Hypothèses!$C$27=0,Hypothèses!$C$26/Hypothèses!$C$28,-CUMPRINC(Hypothèses!$C$27/12,Hypothèses!$C$28*12,Hypothèses!$C$26,12*(K$6-1)+1,12*K$6,0))) -> 9061.1264 | ... AG15: =IF(NOT(AND(Hypothèses!$C$26>0,Hypothèses!$C$33="OK",AG$6<=Hypothèses!$C$28)),0,IF(Hypothèses!$C$27=0,Hypothèses!$C$26/Hypothèses!$C$28,-CUMPRINC(Hypothèses!$C$27/12,Hypothèses!$C$28*12,Hypothèses!$C$26,12*(AG$6-1)+1,12*AG$6,0))) -> 0
B16: Assurance emprunteur | C16: =SUMPRODUCT((D$6:AG$6<=Hypothèses!$C$44)*(D16:AG16)) -> 6800 | D16: =IF(AND(Hypothèses!$C$26>0,Hypothèses!$C$33="OK",D$6<=Hypothèses!$C$28),Hypothèses!$C$26*Hypothèses!$C$29,0) -> 680 | E16: =IF(AND(Hypothèses!$C$26>0,Hypothèses!$C$33="OK",E$6<=Hypothèses!$C$28),Hypothèses!$C$26*Hypothèses!$C$29,0) -> 680 | F16: =IF(AND(Hypothèses!$C$26>0,Hypothèses!$C$33="OK",F$6<=Hypothèses!$C$28),Hypothèses!$C$26*Hypothèses!$C$29,0) -> 680 | G16: =IF(AND(Hypothèses!$C$26>0,Hypothèses!$C$33="OK",G$6<=Hypothèses!$C$28),Hypothèses!$C$26*Hypothèses!$C$29,0) -> 680 | H16: =IF(AND(Hypothèses!$C$26>0,Hypothèses!$C$33="OK",H$6<=Hypothèses!$C$28),Hypothèses!$C$26*Hypothèses!$C$29,0) -> 680 | I16: =IF(AND(Hypothèses!$C$26>0,Hypothèses!$C$33="OK",I$6<=Hypothèses!$C$28),Hypothèses!$C$26*Hypothèses!$C$29,0) -> 680 | J16: =IF(AND(Hypothèses!$C$26>0,Hypothèses!$C$33="OK",J$6<=Hypothèses!$C$28),Hypothèses!$C$26*Hypothèses!$C$29,0) -> 680 | K16: =IF(AND(Hypothèses!$C$26>0,Hypothèses!$C$33="OK",K$6<=Hypothèses!$C$28),Hypothèses!$C$26*Hypothèses!$C$29,0) -> 680 | ... AG16: =IF(AND(Hypothèses!$C$26>0,Hypothèses!$C$33="OK",AG$6<=Hypothèses!$C$28),Hypothèses!$C$26*Hypothèses!$C$29,0) -> 0
B17: Annuité totale (intérêts, capital, assurance) | C17: =SUMPRODUCT((D$6:AG$6<=Hypothèses!$C$44)*(D17:AG17)) -> 142926.98 | D17: =D14+D15+D16 -> 14292.698 | E17: =E14+E15+E16 -> 14292.698 | F17: =F14+F15+F16 -> 14292.698 | G17: =G14+G15+G16 -> 14292.698 | H17: =H14+H15+H16 -> 14292.698 | I17: =I14+I15+I16 -> 14292.698 | J17: =J14+J15+J16 -> 14292.698 | K17: =K14+K15+K16 -> 14292.698 | ... AG17: =AG14+AG15+AG16 -> 0
B18: Capital restant dû en fin d'année | C18: =INDEX(D18:AG18,Hypothèses!$C$44) -> 116087.06 | D18: =IF(AND(Hypothèses!$C$26>0,Hypothèses!$C$33="OK",D$6<=Hypothèses!$C$28),Hypothèses!$C$26-D15,0) -> 192780.39 | E18: =IF(AND(Hypothèses!$C$26>0,Hypothèses!$C$33="OK",E$6<=Hypothèses!$C$28),D18-E15,0) -> 185322.62 | F18: =IF(AND(Hypothèses!$C$26>0,Hypothèses!$C$33="OK",F$6<=Hypothèses!$C$28),E18-F15,0) -> 177618.82 | G18: =IF(AND(Hypothèses!$C$26>0,Hypothèses!$C$33="OK",G$6<=Hypothèses!$C$28),F18-G15,0) -> 169660.89 | H18: =IF(AND(Hypothèses!$C$26>0,Hypothèses!$C$33="OK",H$6<=Hypothèses!$C$28),G18-H15,0) -> 161440.44 | I18: =IF(AND(Hypothèses!$C$26>0,Hypothèses!$C$33="OK",I$6<=Hypothèses!$C$28),H18-I15,0) -> 152948.8 | J18: =IF(AND(Hypothèses!$C$26>0,Hypothèses!$C$33="OK",J$6<=Hypothèses!$C$28),I18-J15,0) -> 144177.04 | K18: =IF(AND(Hypothèses!$C$26>0,Hypothèses!$C$33="OK",K$6<=Hypothèses!$C$28),J18-K15,0) -> 135115.92 | L18: =IF(AND(Hypothèses!$C$26>0,Hypothèses!$C$33="OK",L$6<=Hypothèses!$C$28),K18-L15,0) -> 125755.88 | ... AG18: =IF(AND(Hypothèses!$C$26>0,Hypothèses!$C$33="OK",AG$6<=Hypothèses!$C$28),AF18-AG15,0) -> 0
B19: Amortissement du bâti (hors terrain) | C19: =SUMPRODUCT((D$6:AG$6<=Hypothèses!$C$44)*(D19:AG19)) -> 61200 | D19: =IF(AND(Hypothèses!$C$55>0,D$6<=Hypothèses!$C$55),((Hypothèses!$C$7+IF(Hypothèses!$C$51=Paramètres!$D$33,Hypothèses!$C$9,0))*(1-Hypothèses!$C$54))/Hypothèses!$C$55,0) -> 6120 | E19: =IF(AND(Hypothèses!$C$55>0,E$6<=Hypothèses!$C$55),((Hypothèses!$C$7+IF(Hypothèses!$C$51=Paramètres!$D$33,Hypothèses!$C$9,0))*(1-Hypothèses!$C$54))/Hypothèses!$C$55,0) -> 6120 | F19: =IF(AND(Hypothèses!$C$55>0,F$6<=Hypothèses!$C$55),((Hypothèses!$C$7+IF(Hypothèses!$C$51=Paramètres!$D$33,Hypothèses!$C$9,0))*(1-Hypothèses!$C$54))/Hypothèses!$C$55,0) -> 6120 | G19: =IF(AND(Hypothèses!$C$55>0,G$6<=Hypothèses!$C$55),((Hypothèses!$C$7+IF(Hypothèses!$C$51=Paramètres!$D$33,Hypothèses!$C$9,0))*(1-Hypothèses!$C$54))/Hypothèses!$C$55,0) -> 6120 | H19: =IF(AND(Hypothèses!$C$55>0,H$6<=Hypothèses!$C$55),((Hypothèses!$C$7+IF(Hypothèses!$C$51=Paramètres!$D$33,Hypothèses!$C$9,0))*(1-Hypothèses!$C$54))/Hypothèses!$C$55,0) -> 6120 | I19: =IF(AND(Hypothèses!$C$55>0,I$6<=Hypothèses!$C$55),((Hypothèses!$C$7+IF(Hypothèses!$C$51=Paramètres!$D$33,Hypothèses!$C$9,0))*(1-Hypothèses!$C$54))/Hypothèses!$C$55,0) -> 6120 | J19: =IF(AND(Hypothèses!$C$55>0,J$6<=Hypothèses!$C$55),((Hypothèses!$C$7+IF(Hypothèses!$C$51=Paramètres!$D$33,Hypothèses!$C$9,0))*(1-Hypothèses!$C$54))/Hypothèses!$C$55,0) -> 6120 | K19: =IF(AND(Hypothèses!$C$55>0,K$6<=Hypothèses!$C$55),((Hypothèses!$C$7+IF(Hypothèses!$C$51=Paramètres!$D$33,Hypothèses!$C$9,0))*(1-Hypothèses!$C$54))/Hypothèses!$C$55,0) -> 6120 | ... AG19: =IF(AND(Hypothèses!$C$55>0,AG$6<=Hypothèses!$C$55),((Hypothèses!$C$7+IF(Hypothèses!$C$51=Paramètres!$D$33,Hypothèses!$C$9,0))*(1-Hypothèses!$C$54))/Hypothèses!$C$55,0) -> 6120
B20: Amortissement des travaux | C20: =SUMPRODUCT((D$6:AG$6<=Hypothèses!$C$44)*(D20:AG20)) -> 3333.3333 | D20: =IF(AND(Hypothèses!$C$56>0,D$6<=Hypothèses!$C$56),Hypothèses!$C$10/Hypothèses!$C$56,0) -> 333.33333 | E20: =IF(AND(Hypothèses!$C$56>0,E$6<=Hypothèses!$C$56),Hypothèses!$C$10/Hypothèses!$C$56,0) -> 333.33333 | F20: =IF(AND(Hypothèses!$C$56>0,F$6<=Hypothèses!$C$56),Hypothèses!$C$10/Hypothèses!$C$56,0) -> 333.33333 | G20: =IF(AND(Hypothèses!$C$56>0,G$6<=Hypothèses!$C$56),Hypothèses!$C$10/Hypothèses!$C$56,0) -> 333.33333 | H20: =IF(AND(Hypothèses!$C$56>0,H$6<=Hypothèses!$C$56),Hypothèses!$C$10/Hypothèses!$C$56,0) -> 333.33333 | I20: =IF(AND(Hypothèses!$C$56>0,I$6<=Hypothèses!$C$56),Hypothèses!$C$10/Hypothèses!$C$56,0) -> 333.33333 | J20: =IF(AND(Hypothèses!$C$56>0,J$6<=Hypothèses!$C$56),Hypothèses!$C$10/Hypothèses!$C$56,0) -> 333.33333 | K20: =IF(AND(Hypothèses!$C$56>0,K$6<=Hypothèses!$C$56),Hypothèses!$C$10/Hypothèses!$C$56,0) -> 333.33333 | ... AG20: =IF(AND(Hypothèses!$C$56>0,AG$6<=Hypothèses!$C$56),Hypothèses!$C$10/Hypothèses!$C$56,0) -> 0
B21: Amortissement du mobilier | C21: =SUMPRODUCT((D$6:AG$6<=Hypothèses!$C$44)*(D21:AG21)) -> 8000 | D21: =IF(AND(Hypothèses!$C$57>0,D$6<=Hypothèses!$C$57),Hypothèses!$C$11/Hypothèses!$C$57,0) -> 1142.8571 | E21: =IF(AND(Hypothèses!$C$57>0,E$6<=Hypothèses!$C$57),Hypothèses!$C$11/Hypothèses!$C$57,0) -> 1142.8571 | F21: =IF(AND(Hypothèses!$C$57>0,F$6<=Hypothèses!$C$57),Hypothèses!$C$11/Hypothèses!$C$57,0) -> 1142.8571 | G21: =IF(AND(Hypothèses!$C$57>0,G$6<=Hypothèses!$C$57),Hypothèses!$C$11/Hypothèses!$C$57,0) -> 1142.8571 | H21: =IF(AND(Hypothèses!$C$57>0,H$6<=Hypothèses!$C$57),Hypothèses!$C$11/Hypothèses!$C$57,0) -> 1142.8571 | I21: =IF(AND(Hypothèses!$C$57>0,I$6<=Hypothèses!$C$57),Hypothèses!$C$11/Hypothèses!$C$57,0) -> 1142.8571 | J21: =IF(AND(Hypothèses!$C$57>0,J$6<=Hypothèses!$C$57),Hypothèses!$C$11/Hypothèses!$C$57,0) -> 1142.8571 | K21: =IF(AND(Hypothèses!$C$57>0,K$6<=Hypothèses!$C$57),Hypothèses!$C$11/Hypothèses!$C$57,0) -> 0 | ... AG21: =IF(AND(Hypothèses!$C$57>0,AG$6<=Hypothèses!$C$57),Hypothèses!$C$11/Hypothèses!$C$57,0) -> 0
B22: Amortissement total de l'année | C22: =SUMPRODUCT((D$6:AG$6<=Hypothèses!$C$44)*(D22:AG22)) -> 72533.333 | D22: =D19+D20+D21 -> 7596.1905 | E22: =E19+E20+E21 -> 7596.1905 | F22: =F19+F20+F21 -> 7596.1905 | G22: =G19+G20+G21 -> 7596.1905 | H22: =H19+H20+H21 -> 7596.1905 | I22: =I19+I20+I21 -> 7596.1905 | J22: =J19+J20+J21 -> 7596.1905 | K22: =K19+K20+K21 -> 6453.3333 | ... AG22: =AG19+AG20+AG21 -> 6120
B24: LOCATION NUE, MICRO-FONCIER
B25: Base imposable (loyer moins abattement) | C25: =SUMPRODUCT((D$6:AG$6<=Hypothèses!$C$44)*(D25:AG25)) -> 96670.844 | D25: =D9*(1-Paramètres!$C$11) -> 9240 | E25: =E9*(1-Paramètres!$C$11) -> 9332.4 | F25: =F9*(1-Paramètres!$C$11) -> 9425.724 | G25: =G9*(1-Paramètres!$C$11) -> 9519.9812 | H25: =H9*(1-Paramètres!$C$11) -> 9615.1811 | I25: =I9*(1-Paramètres!$C$11) -> 9711.3329 | J25: =J9*(1-Paramètres!$C$11) -> 9808.4462 | K25: =K9*(1-Paramètres!$C$11) -> 9906.5307 | ... AG25: =AG9*(1-Paramètres!$C$11) -> 12330.816
B26: Impôt sur le revenu et prélèvements sociaux | C26: =SUMPRODUCT((D$6:AG$6<=Hypothèses!$C$44)*(D26:AG26)) -> 45628.638 | D26: =D25*(Hypothèses!$C$36+Paramètres!$C$8) -> 4361.28 | E26: =E25*(Hypothèses!$C$36+Paramètres!$C$8) -> 4404.8928 | F26: =F25*(Hypothèses!$C$36+Paramètres!$C$8) -> 4448.9417 | G26: =G25*(Hypothèses!$C$36+Paramètres!$C$8) -> 4493.4311 | H26: =H25*(Hypothèses!$C$36+Paramètres!$C$8) -> 4538.3655 | I26: =I25*(Hypothèses!$C$36+Paramètres!$C$8) -> 4583.7491 | J26: =J25*(Hypothèses!$C$36+Paramètres!$C$8) -> 4629.5866 | K26: =K25*(Hypothèses!$C$36+Paramètres!$C$8) -> 4675.8825 | ... AG26: =AG25*(Hypothèses!$C$36+Paramètres!$C$8) -> 5820.1451
B27: Économie d'IR sur la CSG déductible (option) | C27: =SUMPRODUCT((D$6:AG$6<=Hypothèses!$C$44)*(D27:AG27)) -> 0 | D27: =0 -> 0 | E27: =IF(Hypothèses!$C$53=Paramètres!$C$33,MAX(0,D25)*Paramètres!$C$10*Hypothèses!$C$36,0) -> 0 | F27: =IF(Hypothèses!$C$53=Paramètres!$C$33,MAX(0,E25)*Paramètres!$C$10*Hypothèses!$C$36,0) -> 0 | G27: =IF(Hypothèses!$C$53=Paramètres!$C$33,MAX(0,F25)*Paramètres!$C$10*Hypothèses!$C$36,0) -> 0 | H27: =IF(Hypothèses!$C$53=Paramètres!$C$33,MAX(0,G25)*Paramètres!$C$10*Hypothèses!$C$36,0) -> 0 | I27: =IF(Hypothèses!$C$53=Paramètres!$C$33,MAX(0,H25)*Paramètres!$C$10*Hypothèses!$C$36,0) -> 0 | J27: =IF(Hypothèses!$C$53=Paramètres!$C$33,MAX(0,I25)*Paramètres!$C$10*Hypothèses!$C$36,0) -> 0 | K27: =IF(Hypothèses!$C$53=Paramètres!$C$33,MAX(0,J25)*Paramètres!$C$10*Hypothèses!$C$36,0) -> 0 | L27: =IF(Hypothèses!$C$53=Paramètres!$C$33,MAX(0,K25)*Paramètres!$C$10*Hypothèses!$C$36,0) -> 0 | ... AG27: =IF(Hypothèses!$C$53=Paramètres!$C$33,MAX(0,AF25)*Paramètres!$C$10*Hypothèses!$C$36,0) -> 0
B28: Flux net en poche (après crédit et impôt) | C28: =SUMPRODUCT((D$6:AG$6<=Hypothèses!$C$44)*(D28:AG28)) -> -82887.274 | D28: =D9-D10-D17-D26+D27 -> -8553.9783 | E28: =E9-E10-E17-E26+E27 -> -8496.5911 | F28: =F9-F10-F17-F26+F27 -> -8438.63 | G28: =G9-G10-G17-G26+G27 -> -8380.0893 | H28: =H9-H10-H17-H26+H27 -> -8320.9632 | I28: =I9-I10-I17-I26+I27 -> -8261.2459 | J28: =J9-J10-J17-J26+J27 -> -8200.9314 | K28: =K9-K10-K17-K26+K27 -> -8140.0137 | ... AG28: =AG9-AG10-AG17-AG26+AG27 -> 7658.3441
B30: LOCATION NUE, RÉEL FONCIER
B31: Résultat foncier du bien (travaux déduits l'année 1) | C31: =SUMPRODUCT((D$6:AG$6<=Hypothèses!$C$44)*(D31:AG31)) -> 41654.299 | D31: =D9-D10-(D14+D16)-IF(D$6=1,Hypothèses!$C$10,0) -> -1973.0881 | E31: =E9-E10-(E14+E16)-IF(E$6=1,Hypothèses!$C$10,0) -> 3366.0761 | F31: =F9-F10-(F14+F16)-IF(F$6=1,Hypothèses!$C$10,0) -> 3714.107 | G31: =G9-G10-(G14+G16)-IF(G$6=1,Hypothèses!$C$10,0) -> 4071.2738 | H31: =H9-H10-(H14+H16)-IF(H$6=1,Hypothèses!$C$10,0) -> 4437.8546 | I31: =I9-I10-(I14+I16)-IF(I$6=1,Hypothèses!$C$10,0) -> 4814.1361 | J31: =J9-J10-(J14+J16)-IF(J$6=1,Hypothèses!$C$10,0) -> 5200.4144 | K31: =K9-K10-(K14+K16)-IF(K$6=1,Hypothèses!$C$10,0) -> 5596.9952 | ... AG31: =AG9-AG10-(AG14+AG16)-IF(AG$6=1,Hypothèses!$C$10,0) -> 13478.489
B32: Déficit issu des intérêts (jamais sur le revenu global) | C32: =SUMPRODUCT((D$6:AG$6<=Hypothèses!$C$44)*(D32:AG32)) -> 0 | D32: =MAX(0,(D14+D16)-D9) -> 0 | E32: =MAX(0,(E14+E16)-E9) -> 0 | F32: =MAX(0,(F14+F16)-F9) -> 0 | G32: =MAX(0,(G14+G16)-G9) -> 0 | H32: =MAX(0,(H14+H16)-H9) -> 0 | I32: =MAX(0,(I14+I16)-I9) -> 0 | J32: =MAX(0,(J14+J16)-J9) -> 0 | K32: =MAX(0,(K14+K16)-K9) -> 0 | ... AG32: =MAX(0,(AG14+AG16)-AG9) -> 0
B33: Déficit issu des autres charges | C33: =SUMPRODUCT((D$6:AG$6<=Hypothèses!$C$44)*(D33:AG33)) -> 1973.0881 | D33: =MAX(0,-D31-D32) -> 1973.0881 | E33: =MAX(0,-E31-E32) -> 0 | F33: =MAX(0,-F31-F32) -> 0 | G33: =MAX(0,-G31-G32) -> 0 | H33: =MAX(0,-H31-H32) -> 0 | I33: =MAX(0,-I31-I32) -> 0 | J33: =MAX(0,-J31-J32) -> 0 | K33: =MAX(0,-K31-K32) -> 0 | ... AG33: =MAX(0,-AG31-AG32) -> 0
B34: Déficit intérêts après les autres revenus fonciers | C34: =SUMPRODUCT((D$6:AG$6<=Hypothèses!$C$44)*(D34:AG34)) -> 0 | D34: =MAX(0,D32-Hypothèses!$C$37) -> 0 | E34: =MAX(0,E32-Hypothèses!$C$37) -> 0 | F34: =MAX(0,F32-Hypothèses!$C$37) -> 0 | G34: =MAX(0,G32-Hypothèses!$C$37) -> 0 | H34: =MAX(0,H32-Hypothèses!$C$37) -> 0 | I34: =MAX(0,I32-Hypothèses!$C$37) -> 0 | J34: =MAX(0,J32-Hypothèses!$C$37) -> 0 | K34: =MAX(0,K32-Hypothèses!$C$37) -> 0 | ... AG34: =MAX(0,AG32-Hypothèses!$C$37) -> 0
B35: Déficit autres charges après les autres revenus fonciers | C35: =SUMPRODUCT((D$6:AG$6<=Hypothèses!$C$44)*(D35:AG35)) -> 1973.0881 | D35: =MAX(0,D33-MAX(0,Hypothèses!$C$37-D32)) -> 1973.0881 | E35: =MAX(0,E33-MAX(0,Hypothèses!$C$37-E32)) -> 0 | F35: =MAX(0,F33-MAX(0,Hypothèses!$C$37-F32)) -> 0 | G35: =MAX(0,G33-MAX(0,Hypothèses!$C$37-G32)) -> 0 | H35: =MAX(0,H33-MAX(0,Hypothèses!$C$37-H32)) -> 0 | I35: =MAX(0,I33-MAX(0,Hypothèses!$C$37-I32)) -> 0 | J35: =MAX(0,J33-MAX(0,Hypothèses!$C$37-J32)) -> 0 | K35: =MAX(0,K33-MAX(0,Hypothèses!$C$37-K32)) -> 0 | ... AG35: =MAX(0,AG33-MAX(0,Hypothèses!$C$37-AG32)) -> 0
B36: Déficit imputé sur le revenu global (plafonné) | C36: =SUMPRODUCT((D$6:AG$6<=Hypothèses!$C$44)*(D36:AG36)) -> 1973.0881 | D36: =MIN(D35,IF(Hypothèses!$C$52=Paramètres!$C$33,Paramètres!$C$14,Paramètres!$C$13)) -> 1973.0881 | E36: =MIN(E35,IF(Hypothèses!$C$52=Paramètres!$C$33,Paramètres!$C$14,Paramètres!$C$13)) -> 0 | F36: =MIN(F35,IF(Hypothèses!$C$52=Paramètres!$C$33,Paramètres!$C$14,Paramètres!$C$13)) -> 0 | G36: =MIN(G35,IF(Hypothèses!$C$52=Paramètres!$C$33,Paramètres!$C$14,Paramètres!$C$13)) -> 0 | H36: =MIN(H35,IF(Hypothèses!$C$52=Paramètres!$C$33,Paramètres!$C$14,Paramètres!$C$13)) -> 0 | I36: =MIN(I35,IF(Hypothèses!$C$52=Paramètres!$C$33,Paramètres!$C$14,Paramètres!$C$13)) -> 0 | J36: =MIN(J35,IF(Hypothèses!$C$52=Paramètres!$C$33,Paramètres!$C$14,Paramètres!$C$13)) -> 0 | K36: =MIN(K35,IF(Hypothèses!$C$52=Paramètres!$C$33,Paramètres!$C$14,Paramètres!$C$13)) -> 0 | ... AG36: =MIN(AG35,IF(Hypothèses!$C$52=Paramètres!$C$33,Paramètres!$C$14,Paramètres!$C$13)) -> 0
B37: Revenu foncier net positif du foyer | C37: =SUMPRODUCT((D$6:AG$6<=Hypothèses!$C$44)*(D37:AG37)) -> 43627.387 | D37: =MAX(0,Hypothèses!$C$37+D31) -> 0 | E37: =MAX(0,Hypothèses!$C$37+E31) -> 3366.0761 | F37: =MAX(0,Hypothèses!$C$37+F31) -> 3714.107 | G37: =MAX(0,Hypothèses!$C$37+G31) -> 4071.2738 | H37: =MAX(0,Hypothèses!$C$37+H31) -> 4437.8546 | I37: =MAX(0,Hypothèses!$C$37+I31) -> 4814.1361 | J37: =MAX(0,Hypothèses!$C$37+J31) -> 5200.4144 | K37: =MAX(0,Hypothèses!$C$37+K31) -> 5596.9952 | ... AG37: =MAX(0,Hypothèses!$C$37+AG31) -> 13478.489
B38: Déficits reportables en début d'année | D38: =0 -> 0 | E38: =D40 -> 0 | F38: =E40 -> 0 | G38: =F40 -> 0 | H38: =G40 -> 0 | I38: =H40 -> 0 | J38: =I40 -> 0 | K38: =J40 -> 0 | L38: =K40 -> 0 | ... AG38: =AF40 -> 0
B39: Report imputé sur les revenus fonciers | C39: =SUMPRODUCT((D$6:AG$6<=Hypothèses!$C$44)*(D39:AG39)) -> 0 | D39: =MIN(D38,D37) -> 0 | E39: =MIN(E38,E37) -> 0 | F39: =MIN(F38,F37) -> 0 | G39: =MIN(G38,G37) -> 0 | H39: =MIN(H38,H37) -> 0 | I39: =MIN(I38,I37) -> 0 | J39: =MIN(J38,J37) -> 0 | K39: =MIN(K38,K37) -> 0 | ... AG39: =MIN(AG38,AG37) -> 0
B40: Déficits reportables en fin d'année (10 ans) | C40: =INDEX(D40:AG40,Hypothèses!$C$44) -> 0 | D40: =D38-D39+D34+D35-D36 -> 0 | E40: =E38-E39+E34+E35-E36 -> 0 | F40: =F38-F39+F34+F35-F36 -> 0 | G40: =G38-G39+G34+G35-G36 -> 0 | H40: =H38-H39+H34+H35-H36 -> 0 | I40: =I38-I39+I34+I35-I36 -> 0 | J40: =J38-J39+J34+J35-J36 -> 0 | K40: =K38-K39+K34+K35-K36 -> 0 | ... AG40: =AG38-AG39+AG34+AG35-AG36 -> 0
B41: Base imposable attribuable au bien | C41: =SUMPRODUCT((D$6:AG$6<=Hypothèses!$C$44)*(D41:AG41)) -> 43627.387 | D41: =D37-D39-Hypothèses!$C$37 -> 0 | E41: =E37-E39-Hypothèses!$C$37 -> 3366.0761 | F41: =F37-F39-Hypothèses!$C$37 -> 3714.107 | G41: =G37-G39-Hypothèses!$C$37 -> 4071.2738 | H41: =H37-H39-Hypothèses!$C$37 -> 4437.8546 | I41: =I37-I39-Hypothèses!$C$37 -> 4814.1361 | J41: =J37-J39-Hypothèses!$C$37 -> 5200.4144 | K41: =K37-K39-Hypothèses!$C$37 -> 5596.9952 | ... AG41: =AG37-AG39-Hypothèses!$C$37 -> 13478.489
