Workbook

Sheet Mode d'emploi
B1: CorpusImmo · corpus.immo · Estimer, comparer, décider. Sur les ventes réelles.
B2: Mode d'emploi
B3: À quoi sert ce classeur, dans quel ordre le remplir, et comment lire ce qu'il répond.
B6: À QUOI SERT CE CLASSEUR
B7: Vous voulez savoir combien une banque acceptera de vous prêter, quelle mensualité votre foyer peut porter, et donc jusqu'à quel prix vous pouvez acheter, frais compris. Ce classeur applique les deux règles d'un analyste crédit en 2026 : le taux d'effort de 35 % assurance comprise, fixé par le HCSF (Haut Conseil de stabilité financière, norme 2026), et le reste à vivre minimal du foyer, puis remonte du prêt au prix en déduisant les frais de notaire, de garantie et de dossier.
B8: Le second onglet dresse le bilan patrimonial du foyer, ce que la banque regarde après les revenus : ce qu'il possède, ce qu'il doit, ce qu'il peut mobiliser comme apport, et ce que deviendra son patrimoine le jour de l'achat.
B9: Deux onglets de saisie pour le dossier, remplis de haut en bas : les cellules bleues se remplissent, tout le reste se calcule. Un troisième onglet, Paramètres, ne se touche qu'à la mise à jour des barèmes.
B10: Vous êtes | C10: Ce que le classeur vous donne
B11: Acquéreur, primo-accédant | C11: La mensualité tenable, le prix maximal à donner à l'agent immobilier, et le saut de charge par rapport à votre loyer.
B12: Investisseur locatif | C12: La capacité en tenant compte du loyer attendu du bien financé (pondéré) et du loyer que vous continuez à payer.
B13: Courtier, banquier | C13: Les deux ratios (taux d'effort HCSF strict et taux de charges tout compris), le reste à vivre après mensualité, les contrôles apport, durée et endettement.
B14: Conseiller en gestion de patrimoine | C14: Le patrimoine net, l'endettement immobilier (LTV, « loan to value » : encours de crédit rapporté à la valeur des biens), la dette rapportée aux revenus, l'épargne résiduelle après apport et le pro forma après l'opération.
B15: Agent immobilier | C15: Un prix maximal argumenté, frais de notaire 2026 compris (ancien ou neuf, droit départemental majoré ou non).
B17: LE PRINCIPE, EN UNE LIGNE
B18: Revenus retenus × 35 % (HCSF 2026) − charges = mensualité, bornée par le reste à vivre ; mensualité → capital ; capital + apport − frais = prix maximal
B20: LES ONGLETS, DANS L'ORDRE OÙ ON LES REMPLIT
B21: Onglet | C21: Ce que vous y faites | D21: Ce que vous y lisez
B22: Mode d'emploi | C22: Rien à saisir. Vous lisez ce guide. | D22: La marche à suivre et l'exemple guidé.
B23: Capacité d'emprunt | C23: Quatre blocs de saisie : revenus, charges, foyer, projet. | D23: Ce que la banque retient, la mensualité tenable, le capital, le prix maximal, six contrôles OK / À CORRIGER (C35 taux vraisemblable, C50 endettement, C58 durée, C60 taux d'usure, C67 apport, C70 saisies).
B24: Bilan patrimonial | C24: Trois blocs de saisie : immobilier, liquidités et placements, dettes. | D24: Le patrimoine net, la lecture bancaire, l'apport couvert ou non, le pro forma après l'achat.
B25: Paramètres | C25: Rien, sauf à la mise à jour des barèmes (HCSF, droits de mutation, émoluments), des repères de marché (pondérations, reste à vivre, garantie, dossier) et des bornes de saisie. | D25: Chaque valeur avec sa source datée et sa fréquence de mise à jour.
B26: Méthode | C26: Rien à saisir. | D26: Les conventions de calcul, ce que le modèle ne fait pas, les sources.
B28: LE CODE COULEUR, ET COMMENT DÉVERROUILLER UNE CELLULE
B29: Cellule | C29: Ce que c'est | D29: Ce que vous faites
B30: Fond bleu clair | C30: Saisie utilisateur | D30: Vous la remplissez. Jamais de formule dedans.
B31: Fond blanc | C31: Calcul | D31: Vous la lisez. Elle est verrouillée.
B32: Fond presque blanc, texte en gras | C32: Résultat de bloc, chiffre clé | D32: Vous la lisez. C'est un chiffre à retenir. Le gras est le repère, pas la couleur.
B33: Bandeau bleu nuit | C33: Titre de section | D33: Repère de navigation.
B34: Texte gris, à droite | C34: Commentaire d'aide, ordre de grandeur | D34: Une phrase par ligne pour savoir quoi saisir. Dans les onglets, les chiffres cités y sont lus dans Paramètres et se mettent à jour seuls ; ceux de ce guide sont écrits en dur (millésime 2026).
B35: Vert OK / rouge À CORRIGER | C35: Contrôle de cohérence | D35: Rouge : lisez le commentaire de la ligne, corrigez la saisie ou présentez le dossier comme dérogatoire.
B36: Les onglets sont protégés sans mot de passe pour éviter d'écraser une formule par erreur. Pour modifier une cellule blanche : onglet Révision, puis « Ôter la protection de la feuille ». Aucun mot de passe n'est demandé.
B38: LA MARCHE À SUIVRE, ÉTAPE PAR ÉTAPE
B39: Étape | C39: Où (onglet et plage) | D39: Ce que vous faites | E39: Pourquoi
B40: 0. L'exemple livré | C40: Toutes les cellules bleues des onglets Capacité d'emprunt et Bilan patrimonial | D40: Le classeur est livré rempli d'un exemple (section « Exemple guidé »). Gardez-le pour vous repérer, ou remplacez chaque cellule bleue par votre valeur. Mettez 0 dans celles qui ne vous concernent pas, ne laissez jamais une cellule bleue vide et gardez un choix dans chaque liste : le contrôle C70 passe au rouge sinon. Vérifiez surtout les saisies secondaires qui n'ont pas de raison d'être chez vous : loyers encaissés (C10), crédits en cours (C15, C16), loyer payé (C18), loyer du bien financé (C27), les trois choix Oui / Non (C32 à C34), et dans le Bilan patrimonial le bien locatif (C8), son encours (C24), le restant dû du crédit auto (C25) et les quatre postes d'épargne (C13 à C16). | E40: Une saisie résiduelle de l'exemple est l'erreur la plus probable d'un premier usage : les 700 € de loyers ou les 450 € de crédit de l'exemple 2026, s'ils ne sont pas les vôtres, déplacent le prix maximal de plusieurs dizaines de milliers d'euros.
B41: 1. Les revenus | C41: Capacité d'emprunt!C7:C11 | D41: Salaires nets avant impôt, primes lissées, loyers bruts actuels, autres revenus pérennes. | E41: La banque pondère les loyers et parfois les primes : saisissez les montants bruts, le classeur pondère avec Paramètres.
B42: 2. Les charges | C42: Capacité d'emprunt!C15:C18 | D42: Mensualités des crédits qui continueront, pension versée, loyer payé aujourd'hui. | E42: Le loyer actuel disparaît pour une résidence principale et reste pour un investissement : le classeur tranche selon l'objet.
B43: 3. Le foyer | C43: Capacité d'emprunt!C22:C23 | D43: Nombre d'adultes et d'enfants à charge. | E43: Le reste à vivre minimal en dépend : c'est la règle qui refuse un dossier à 33 % avec quatre enfants.
B44: 4. Le projet | C44: Capacité d'emprunt!C26:C34 | D44: Objet (résidence principale ou investissement), loyer attendu du bien financé, apport, taux (tapez 3,3 pour 3,30 %), durée, assurance (taux global du foyer : avec deux emprunteurs couverts à 100 % chacun, additionnez les deux taux), neuf ou en VEFA (vente en l'état futur d'achèvement) ou ancien, différé, droit départemental majoré. Vérifiez que C58 (durée) et C67 (apport) affichent OK. | E44: Ces neuf cellules pilotent le capital et les frais. Le droit majoré (LF 2025, en vigueur jusqu'au 31/03/2028) ne s'applique ni dans les départements restés à 4,50 % (liste à jour sur taximmo.fr ou sur le site des notaires de France, source citée en Paramètres!D13), ni aux primo-accédants pour leur résidence principale.
B45: 5. La lecture | C45: Capacité d'emprunt!C38:C70 | D45: Rien à saisir. Vérifiez que les six contrôles affichent OK : C35 (taux vraisemblable), C50 (endettement dans la norme), C58 (durée), C60 (taux et assurance sous le taux d'usure, ligne C59), C67 (apport), C70 (saisies complètes). Puis lisez la mensualité tenable (C45), le capital (C53) et le prix maximal (C63). | E45: Un contrôle rouge signale une saisie manquante, hors bornes ou un dossier hors norme : le classeur préfère un rouge à un chiffre faux.
B46: 6. Le bilan | C46: Bilan patrimonial!C7:C9, Bilan patrimonial!C13:C18, Bilan patrimonial!C23:C28 | D46: Valeurs de marché des biens, épargne poste par poste avant l'achat (l'apport prévu en fait encore partie : s'il est sur le compte courant, il compte dans C13), capital restant dû de chaque crédit (lu sur le tableau d'amortissement). Vérifiez que Bilan patrimonial!C45 (saisies complètes) puis Bilan patrimonial!C44 (apport couvert par les liquidités) affichent OK. | E46: Le Bilan décrit la situation avant l'achat : le pro forma retire lui-même l'apport. Le même foyer que dans Capacité d'emprunt : le bien loué qui produit les loyers doit figurer ici avec son encours. Si Bilan patrimonial!C44 est rouge, l'épargne saisie ne contient pas l'apport, ou l'apport vient d'ailleurs (donation, PER).
...

Sheet Capacité d'emprunt
B1: CorpusImmo · corpus.immo · Estimer, comparer, décider. Sur les ventes réelles.
B2: Capacité d'emprunt
B3: Jusqu'où la banque peut vous suivre, et ce qu'il vous reste pour vivre.
B5: Cellules bleues : à remplir. Cellules blanches : calculées automatiquement.
B6: REVENUS MENSUELS NETS DU FOYER
B7: Salaire net emprunteur 1 | C7: 2600 | D7: Net avant impôt, hors primes exceptionnelles : la ligne « net à payer avant impôt sur le revenu » de la fiche de paie.
B8: Salaire net emprunteur 2 | C8: 1900 | D8: 0 s'il n'y a qu'un emprunteur. Indépendant : moyenne des derniers bilans.
B9: Primes et variables (moyenne mensuelle) | C9: 200 | D9: ="Moyenne pluriannuelle si elles sont récurrentes. Retenues à "&TEXT(ROUND(Paramètres!$C$29*100,0),"0")&" %"&" (Paramètres, pondération des primes)." -> Moyenne pluriannuelle si elles sont récurrentes. Retenues à 100 % (Paramètres, pondération des primes).
B10: Revenus locatifs actuels (loyers bruts) | C10: 700 | D10: ="Loyers hors charges encaissés aujourd'hui. Retenus à "&TEXT(ROUND(Paramètres!$C$28*100,0),"0")&" %"&" plus bas (Paramètres) : ne les pondérez pas vous-même." -> Loyers hors charges encaissés aujourd'hui. Retenus à 70 % plus bas (Paramètres) : ne les pondérez pas vous-même.
B11: Autres revenus pérennes | C11: 0 | D11: Pensions reçues, rentes, allocations pérennes. Pas les aides temporaires.
B12: Total des revenus du foyer | C12: =SUM($C$7:$C$11) -> 5400 | D12: Ce que le foyer encaisse réellement chaque mois, avant pondération.
B14: CHARGES MENSUELLES ACTUELLES
B15: Crédits immobiliers en cours (mensualités) | C15: 450 | D15: Assurance comprise, pour les prêts qui continueront après l'opération. Exemple : le prêt du bien loué.
B16: Crédit auto, consommation, LOA (mensualités) | C16: 280 | D16: Toutes les mensualités de crédits non immobiliers en cours.
B17: Pension alimentaire versée | C17: 0 | D17: Pension versée. Une pension reçue se saisit dans les autres revenus.
B18: Loyer actuel payé par le foyer | C18: 850 | D18: Loyer payé aujourd'hui. Il disparaît pour une résidence principale, il reste une charge pour un investissement locatif (choix dans Le projet).
B19: Charges de crédits en cours | C19: =SUM($C$15:$C$16) -> 730 | D19: Les seules charges comptées dans le taux d'effort HCSF strict.
B21: LE FOYER
B22: Nombre d'adultes | C22: 2 | D22: Emprunteurs et adultes à charge. Au moins 1.
B23: Nombre d'enfants à charge | C23: 1 | D23: Enfants à charge, garde alternée comprise.
B25: LE PROJET
B26: Objet du financement | C26: Résidence principale | D26: Choisir dans la liste. Résidence principale : le loyer actuel disparaît. Investissement locatif : il reste, et le loyer du bien financé est retenu (pondéré).
B27: Loyer mensuel attendu du bien financé | C27: 0 | D27: ="Hors charges. Retenu à "&TEXT(ROUND(Paramètres!$C$28*100,0),"0")&" %"&" seulement si l'objet est un investissement locatif, ignoré sinon. 0 pour une résidence principale." -> Hors charges. Retenu à 70 % seulement si l'objet est un investissement locatif, ignoré sinon. 0 pour une résidence principale.
B28: Apport personnel | C28: 30000 | D28: Épargne apportée. Doit au moins couvrir les frais de notaire, de garantie et de dossier (contrôle plus bas).
B29: Taux du prêt (hors assurance) | C29: 0.033 | D29: ="Taux nominal annuel. Tapez 3,3 pour 3,30 %. Repère de Paramètres (Observatoire Crédit Logement, vérifié le "&TEXT(DAY(Paramètres!$C$55),"00")&"/"&TEXT(MONTH(Paramètres!$C$55),"00")&"/"&YEAR(Paramètres!$C$55)&") : "&TEXT(INT(ROUND(Paramètres!$C$35*100,2)),"0")&","&TEXT((ROUND(Paramètres!$C$35*100,2)-INT(ROUND(Paramètres!$C$35*100,2)))*100,"00")&" %"&" sur 25 ans." -> Taux nominal annuel. Tapez 3,3 pour 3,30 %. Repère de Paramètres (Observatoire Crédit Logement, vérifié le 05/09/2026) : 3,35 % sur 25 ans.
B30: Durée envisagée | C30: 25 | D30: ="Années entières. "&TEXT(Paramètres!$C$9,"0")&" ans au plus (HCSF), "&TEXT(Paramètres!$C$10,"0")&" avec différé (ligne « Différé »). Au-delà : dossier dérogatoire, contrôle rouge." -> Années entières. 25 ans au plus (HCSF), 27 avec différé (ligne « Différé »). Au-delà : dossier dérogatoire, contrôle rouge.
B31: Taux d'assurance emprunteur (sur capital initial) | C31: 0.003 | D31: ="Taux global du foyer : avec deux emprunteurs couverts à 100 % chacun, additionnez les deux taux. Repères de Paramètres (vérifiés le "&TEXT(DAY(Paramètres!$C$55),"00")&"/"&TEXT(MONTH(Paramètres!$C$55),"00")&"/"&YEAR(Paramètres!$C$55)&") : "&TEXT(INT(ROUND(Paramètres!$C$36*100,2)),"0")&","&TEXT((ROUND(Paramètres!$C$36*100,2)-INT(ROUND(Paramètres!$C$36*100,2)))*100,"00")&" %"&" en contrat groupe, "&TEXT(INT(ROUND(Paramètres!$C$37*100,2)),"0")&","&TEXT((ROUND(Paramètres!$C$37*100,2)-INT(ROUND(Paramètres!$C$37*100,2)))*100,"00")&" %"&" en délégation, par tête." -> Taux global du foyer : avec deux emprunteurs couverts à 100 % chacun, additionnez les deux taux. Repères de Paramètres (vérifiés le 05/09/2026) : 0,36 % en contrat groupe, 0,17 % en délégation, par tête.
B32: Bien neuf ou en VEFA ? | C32: Non | D32: ="Oui : taxe de publicité foncière réduite ("&TEXT(INT(ROUND(Paramètres!$C$15*100,3)),"0")&","&TEXT((ROUND(Paramètres!$C$15*100,3)-INT(ROUND(Paramètres!$C$15*100,3)))*1000,"000")&" %"&") à la place des droits de mutation." -> Oui : taxe de publicité foncière réduite (0,715 %) à la place des droits de mutation.
B33: Différé d'amortissement justifié (VEFA, construction, gros travaux) ? | C33: Non | D33: ="Oui si VEFA, construction, ou travaux d'au moins "&TEXT(ROUND(Paramètres!$C$11*100,0),"0")&" %"&" du coût total : durée HCSF portée à "&TEXT(Paramètres!$C$10,"0")&" ans (différé de 2 ans au plus)." -> Oui si VEFA, construction, ou travaux d'au moins 10 % du coût total : durée HCSF portée à 27 ans (différé de 2 ans au plus).
B34: Droit départemental majoré à 5 % applicable ? | C34: Non | D34: ="Oui dans la grande majorité des départements depuis le 01/04/2025 ("&TEXT(INT(ROUND(Paramètres!$C$13*100,2)),"0")&","&TEXT((ROUND(Paramètres!$C$13*100,2)-INT(ROUND(Paramètres!$C$13*100,2)))*100,"00")&" %"&" de droits). Non si le département est resté au taux de base ("&TEXT(INT(ROUND(Paramètres!$C$14*100,2)),"0")&","&TEXT((ROUND(Paramètres!$C$14*100,2)-INT(ROUND(Paramètres!$C$14*100,2)))*100,"00")&" %"&"), ou pour un primo-accédant achetant sa résidence principale." -> Oui dans la grande majorité des départements depuis le 01/04/2025 (6,32 % de droits). Non si le département est resté au taux de base (5,81 %), ou pour un primo-accédant achetant sa résidence principale.
B35: Taux vraisemblable | C35: =IF(AND(ISNUMBER(Paramètres!$C$48),OR(NOT(ISNUMBER($C$29)),$C$29<=0,$C$29>=Paramètres!$C$48),OR(NOT(ISNUMBER($C$31)),$C$31<=0,$C$31>=Paramètres!$C$48)),"OK","À CORRIGER") -> OK | D35: ="À CORRIGER si le taux du prêt ou le taux d'assurance est strictement positif et inférieur au plancher de plausibilité de Paramètres ("&TEXT(INT(ROUND(Paramètres!$C$48*100,2)),"0")&","&TEXT((ROUND(Paramètres!$C$48*100,2)-INT(ROUND(Paramètres!$C$48*100,2)))*100,"00")&" %"&") : vous avez sans doute tapé 0,033 au lieu de 3,3. Un prêt à taux zéro se saisit 0 exactement." -> À CORRIGER si le taux du prêt ou le taux d'assurance est strictement positif et inférieur au plancher de plausibilité de Paramètres (0,10 %) : vous avez sans doute tapé 0,033 au lieu de 3,3. Un prêt à taux zéro se saisit 0 exactement.
B37: CE QUE LA BANQUE RETIENT
B38: Loyers retenus (pondérés) | C38: =(N($C$10)+IF($C$26=Paramètres!$C$53,N($C$27),0))*Paramètres!$C$28 -> 490 | D38: Loyers actuels, plus loyer du bien financé pour un investissement locatif, multipliés par la pondération de Paramètres.
B39: Revenus retenus par la banque | C39: =SUM($C$7,$C$8,$C$11)+N($C$9)*Paramètres!$C$29+$C$38 -> 5190 | D39: Salaires, primes pondérées, autres revenus et loyers pondérés : le dénominateur de tous les ratios.
B40: Loyer actuel conservé après l'opération | C40: =IF($C$26=Paramètres!$C$52,0,N($C$18)) -> 0 | D40: Le loyer actuel s'il continue (investissement locatif), 0 pour une résidence principale.
B41: Charges retenues | C41: =$C$19+N($C$17)+$C$40 -> 730 | D41: Crédits en cours, pension versée et loyer conservé. Option prudente : tout compte.
B42: Mensualité maximale au taux d'effort | C42: =$C$39*Paramètres!$C$8-$C$41 -> 1086.5 | D42: ="Revenus retenus × taux d'effort HCSF ("&TEXT(ROUND(Paramètres!$C$8*100,0),"0")&" %"&"), moins les charges retenues. Assurance comprise." -> Revenus retenus × taux d'effort HCSF (35 %), moins les charges retenues. Assurance comprise.
B43: Reste à vivre minimal attendu | C43: =N($C$22)*Paramètres!$C$30+N($C$23)*Paramètres!$C$31 -> 1900 | D43: Adultes et enfants multipliés par les minimums de Paramètres. Repère bancaire, pas une règle légale.
B44: Mensualité maximale au reste à vivre | C44: =$C$39-$C$41-$C$43 -> 2560 | D44: Revenus retenus, moins charges retenues, moins reste à vivre minimal.
B45: Mensualité réellement tenable, assurance comprise | C45: =MAX(0,MIN($C$42,$C$44)) -> 1086.5 | D45: La plus contraignante des deux règles. Le chiffre à présenter à la banque.
...

Sheet Bilan patrimonial
B1: CorpusImmo · corpus.immo · Estimer, comparer, décider. Sur les ventes réelles.
B2: Bilan patrimonial
B3: Ce que la banque regarde après les revenus : ce que vous possédez déjà, et ce qu'il en restera après l'achat.
B5: Cellules bleues : à remplir. Cellules blanches : calculées automatiquement.
B6: ACTIF IMMOBILIER (VALEUR DE MARCHÉ)
B7: Résidence principale | C7: 0 | D7: Valeur de revente réaliste aujourd'hui (pas le prix payé). 0 si vous êtes locataire.
B8: Biens locatifs | C8: 140000 | D8: Valeur de marché des biens loués. Leurs loyers sont saisis dans Capacité d'emprunt.
B9: Autres biens immobiliers | C9: 0 | D9: Résidence secondaire, terrain, parking, nue-propriété (à sa valeur décotée).
B10: Total immobilier | C10: =SUM($C$7:$C$9) -> 140000 | D10: Valeur brute du patrimoine immobilier.
B12: LIQUIDITÉS ET PLACEMENTS
B13: Comptes courants et livrets | C13: 18000 | D13: Disponibles immédiatement : comptes, Livret A, LDDS, LEP, CEL, PEL.
B14: Assurance-vie | C14: 25000 | D14: Valeur de rachat. Mobilisable sous quelques semaines, avec la fiscalité du rachat.
B15: PEA et comptes-titres | C15: 12000 | D15: Valeur liquidative. Un retrait sur un PEA de moins de cinq ans entraîne sa clôture.
B16: Épargne retraite (PER, PERCO) | C16: 8000 | D16: Bloquée jusqu'à la retraite, sauf déblocage pour l'achat de la résidence principale (PER individuel) : non comptée dans les liquidités mobilisables.
B17: Parts de sociétés et SCPI | C17: 0 | D17: Valeur de retrait ou de marché. Peu liquide : non comptée dans les liquidités mobilisables.
B18: Autres actifs (véhicules, œuvres, métaux) | C18: 0 | D18: À la valeur de revente. Non comptés dans les liquidités mobilisables.
B19: Total liquidités et placements | C19: =SUM($C$13:$C$18) -> 63000 | D19: Actif financier brut.
B20: Liquidités mobilisables pour l'apport | C20: =SUM($C$13:$C$15) -> 55000 | D20: Comptes et livrets, assurance-vie, PEA et comptes-titres. Ce que la banque accepte comme apport disponible.
B22: PASSIF (CAPITAL RESTANT DÛ)
B23: Capital restant dû, résidence principale | C23: 0 | D23: Lire le dernier tableau d'amortissement, pas la mensualité.
B24: Capital restant dû, biens locatifs | C24: 60000 | D24: Encours des prêts des biens loués. Leur mensualité est dans Capacité d'emprunt (crédits immobiliers en cours).
B25: Crédit auto ou consommation (restant dû) | C25: 6500 | D25: Capital restant dû, pas la mensualité.
B26: Découverts et crédits renouvelables | C26: 0 | D26: Encours utilisé à ce jour.
B27: Impôts et charges à régler | C27: 0 | D27: Impôt sur le revenu restant dû, taxe foncière à venir, charges de copropriété impayées.
B28: Autres dettes | C28: 0 | D28: Prêt familial, soulte, dette professionnelle personnelle.
B29: Encours immobilier | C29: =SUM($C$23:$C$24) -> 60000 | D29: Capital restant dû sur l'ensemble des biens immobiliers.
B30: Total passif | C30: =SUM($C$23:$C$28) -> 66500 | D30: Tout ce qui est dû aujourd'hui.
B32: LECTURE BANCAIRE, AVANT L'OPÉRATION
B33: Total actif | C33: =$C$10+$C$19 -> 203000 | D33: Immobilier plus liquidités et placements.
B34: Patrimoine net | C34: =$C$33-$C$30 -> 136500 | D34: Ce qui reste si tout est vendu et toutes les dettes soldées. Ce qui amortit un accident de parcours aux yeux de la banque.
B35: Patrimoine immobilier net | C35: =$C$10-$C$29 -> 80000 | D35: Valeur des biens moins leur encours de crédit.
B36: Endettement immobilier (encours / valeur, LTV) | C36: =IF($C$10>0,$C$29/$C$10,"") -> 0.42857143 | D36: Plus il est proche de 100 %, moins l'immobilier existant offre de marge de sûreté à la banque.
B37: Ratio dettes / actif brut | C37: =IF($C$33>0,$C$30/$C$33,"") -> 0.32758621 | D37: Un ratio de stock (dettes totales rapportées à l'actif total), à ne pas confondre avec le taux d'effort, qui est un ratio de flux.
B38: Dette totale / revenus annuels retenus | C38: =IF('Capacité d''emprunt'!$C$39>0,$C$30/('Capacité d''emprunt'!$C$39*12),"") -> 1.0677585 | D38: En années de revenus retenus (Capacité d'emprunt). Plus il est élevé, plus la stabilité des revenus compte.
B40: APPORT ET ÉPARGNE DE PRÉCAUTION
B41: Apport prévu (lu dans Capacité d'emprunt) | C41: =N('Capacité d''emprunt'!$C$28) -> 30000 | D41: Repris de l'onglet Capacité d'emprunt.
B42: Épargne résiduelle après apport | C42: =$C$20-$C$41 -> 25000 | D42: Liquidités mobilisables moins apport : l'épargne de précaution que la banque veut voir subsister.
B43: Épargne résiduelle en mois de mensualité future | C43: =IF('Capacité d''emprunt'!$C$45>0,$C$42/'Capacité d''emprunt'!$C$45,"") -> 23.009664 | D43: Épargne résiduelle divisée par la mensualité tenable. Vide si aucune mensualité n'est possible.
B44: Apport couvert par les liquidités | C44: =IF($C$41<=$C$20,"OK","À CORRIGER") -> OK | D44: À CORRIGER sil'apport prévu dépasse les liquidités mobilisables : il faudra un rachat, un déblocage de PER ou une donation.
B45: Saisies du bilan complètes et positives | C45: =IF(AND(COUNT($C$7:$C$9)=3,COUNT($C$13:$C$18)=6,COUNT($C$23:$C$28)=6,MIN($C$7:$C$9)>=0,MIN($C$13:$C$18)>=0,MIN($C$23:$C$28)>=0),"OK","À CORRIGER") -> OK | D45: À CORRIGER : unecellule bleue de cet onglet est vide, n'est pas un nombre ou est négative.
...

Sheet Paramètres
B1: CorpusImmo · corpus.immo · Estimer, comparer, décider. Sur les ventes réelles.
B2: Paramètres
B3: Les règles de la banque et les barèmes 2026, en clair. Toutes les formules du classeur pointent ici.
B5: Cellules bleues : à remplir. Cellules blanches : calculées automatiquement.
B6: BARÈMES RÉGLEMENTAIRES, MILLÉSIME 2026
B7: Paramètre | C7: Valeur | D7: Source (organisme, texte, date) | E7: Mise à jour | F7: Commentaire
B8: Taux d'effort maximal HCSF (assurance comprise) | C8: 0.35 | D8: ="HCSF, décision D-HCSF-2021-7 du 29/09/2021, confirmée par la décision D-HCSF-2023-2 du 29/06/2023. economie.gouv.fr/hcsf, vérifié le "&TEXT(DAY(Paramètres!$C$55),"00")&"/"&TEXT(MONTH(Paramètres!$C$55),"00")&"/"&YEAR(Paramètres!$C$55)&"." -> HCSF, décision D-HCSF-2021-7 du 29/09/2021, confirmée par la décision D-HCSF-2023-2 du 29/06/2023. economie.gouv.fr/hcsf, vérifié le 05/09/2026. | E8: À chaque décision HCSF (réunion trimestrielle) | F8: Charges d'emprunt assurance comprise rapportées aux revenus nets avant impôt. Norme contraignante depuis le 01/01/2022, avec une marge de flexibilité (ligne plus bas).
B9: Durée maximale HCSF, cas général | C9: 25 | D9: ="HCSF, décision D-HCSF-2021-7 du 29/09/2021. Vérifié le "&TEXT(DAY(Paramètres!$C$55),"00")&"/"&TEXT(MONTH(Paramètres!$C$55),"00")&"/"&YEAR(Paramètres!$C$55)&"." -> HCSF, décision D-HCSF-2021-7 du 29/09/2021. Vérifié le 05/09/2026. | E9: À chaque décision HCSF | F9: Maturité maximale du crédit.
B10: Durée maximale HCSF avec différé (VEFA, construction, travaux) | C10: 27 | D10: ="HCSF, décisions du 29/09/2021 (différé de 2 ans au plus) et du 29/06/2023 (seuil de travaux abaissé de 25 % à 10 % du coût total). Vérifié le "&TEXT(DAY(Paramètres!$C$55),"00")&"/"&TEXT(MONTH(Paramètres!$C$55),"00")&"/"&YEAR(Paramètres!$C$55)&"." -> HCSF, décisions du 29/09/2021 (différé de 2 ans au plus) et du 29/06/2023 (seuil de travaux abaissé de 25 % à 10 % du coût total). Vérifié le 05/09/2026. | E10: À chaque décision HCSF | F10: Durée générale plus 2 ans de différé d'amortissement au plus, quand le bien n'est pas livré ou que les travaux atteignent le seuil de la ligne suivante.
B11: Seuil de travaux ouvrant le différé (part du coût total) | C11: 0.1 | D11: ="HCSF, décision D-HCSF-2023-2 du 29/06/2023 (auparavant 25 %). Vérifié le "&TEXT(DAY(Paramètres!$C$55),"00")&"/"&TEXT(MONTH(Paramètres!$C$55),"00")&"/"&YEAR(Paramètres!$C$55)&"." -> HCSF, décision D-HCSF-2023-2 du 29/06/2023 (auparavant 25 %). Vérifié le 05/09/2026. | E11: À chaque décision HCSF | F11: Information : sert à répondre à la question « Différé » de l'onglet Capacité d'emprunt, pas aux formules.
B12: Marge de flexibilité HCSF (part de la production trimestrielle) | C12: 0.2 | D12: ="HCSF, décision D-HCSF-2023-2 du 29/06/2023 : 20 % de la production, dont au moins 70 % pour la résidence principale et au moins 30 % pour les primo-accédants. Utilisée à 17,5 % au 1er trimestre 2026 (Meilleurtaux, 11/06/2026). Vérifié le "&TEXT(DAY(Paramètres!$C$55),"00")&"/"&TEXT(MONTH(Paramètres!$C$55),"00")&"/"&YEAR(Paramètres!$C$55)&"." -> HCSF, décision D-HCSF-2023-2 du 29/06/2023 : 20 % de la production, dont au moins 70 % pour la résidence principale et au moins 30 % pour les primo-accédants. Utilisée à 17,5 % au 1er trimestre 2026 (Meilleurtaux, 11/06/2026). Vérifié le 05/09/2026. | E12: À chaque décision HCSF | F12: Information : non utilisée par les formules. Un dossier au-delà du taux d'effort ou de la durée ne passe que dans cette marge, à la main de chaque banque.
B13: Droits de mutation, ancien, droit départemental majoré à 5 % | C13: 0.0632 | D13: ="LF 2025 (loi n° 2025-127 du 14/02/2025) art. 116 : droit départemental porté de 4,50 % à 5 % (CGI art. 1594 D) du 01/04/2025 au 31/03/2028 ; taxe communale 1,20 % (art. 1584) ; frais d'assiette 2,37 % du droit départemental (art. 1647 V). taximmo.fr,"&" vérifié le "&TEXT(DAY(Paramètres!$C$55),"00")&"/"&TEXT(MONTH(Paramètres!$C$55),"00")&"/"&YEAR(Paramètres!$C$55)&"." -> LF 2025 (loi n° 2025-127 du 14/02/2025) art. 116 : droit départemental porté de 4,50 % à 5 % (CGI art. 1594 D) du 01/04/2025 au 31/03/2028 ; taxe communale 1,20 % (art. 1584) ; frais d'assiette 2,37 % du droit départemental (art. 1647 V). taximmo.fr, vérifié le 05/09/2026. | E13: À chaque loi de finances ; échéance 31/03/2028 | F13: 5 % × 1,0237 + 1,20 % = 6,32 %. Appliqué par la grande majorité des départements ; le classeur demande si le droit majoré s'applique.
B14: Droits de mutation, ancien, droit départemental à 4,50 % | C14: 0.0581 | D14: ="CGI art. 1594 D (4,50 %), 1584 (1,20 %), 1647 V (2,37 %). Maintenu dans les départements qui n'ont pas voté la hausse et pour les primo-accédants achetant leur résidence principale (LF 2025 art. 116, II). taximmo.fr, vérifié le "&TEXT(DAY(Paramètres!$C$55),"00")&"/"&TEXT(MONTH(Paramètres!$C$55),"00")&"/"&YEAR(Paramètres!$C$55)&"." -> CGI art. 1594 D (4,50 %), 1584 (1,20 %), 1647 V (2,37 %). Maintenu dans les départements qui n'ont pas voté la hausse et pour les primo-accédants achetant leur résidence principale (LF 2025 art. 116, II). taximmo.fr, vérifié le 05/09/2026. | E14: À chaque loi de finances | F14: 4,50 % × 1,0237 + 1,20 % = 5,81 %.
B15: Taxe de publicité foncière, neuf ou VEFA | C15: 0.00715 | D15: ="CGI art. 1594 F quinquies A (taux réduit 0,70 %) et 1647 V (frais d'assiette 2,14 %). Vérifié le "&TEXT(DAY(Paramètres!$C$55),"00")&"/"&TEXT(MONTH(Paramètres!$C$55),"00")&"/"&YEAR(Paramètres!$C$55)&"." -> CGI art. 1594 F quinquies A (taux réduit 0,70 %) et 1647 V (frais d'assiette 2,14 %). Vérifié le 05/09/2026. | E15: À chaque loi de finances | F15: 0,70 % × 1,0214 = 0,715 %. Remplace les droits de mutation pour un logement neuf ou vendu en l'état futur d'achèvement.
B16: Contribution de sécurité immobilière | C16: 0.001 | D16: ="CGI art. 879 : 0,10 % du prix, ancien comme neuf. Vérifié le "&TEXT(DAY(Paramètres!$C$55),"00")&"/"&TEXT(MONTH(Paramètres!$C$55),"00")&"/"&YEAR(Paramètres!$C$55)&"." -> CGI art. 879 : 0,10 % du prix, ancien comme neuf. Vérifié le 05/09/2026. | E16: À chaque loi de finances | F16: Ex-salaire du conservateur des hypothèques.
B17: Émoluments du notaire, taux marginal au-delà de 60 000 € (HT) | C17: 0.00799 | D17: ="Code de commerce art. A444-91, arrêté du 25/02/2026 (en vigueur du 01/03/2026 au 29/02/2028) : 3,870 % jusqu'à 6 500 €, 1,596 % de 6 500 à 17 000 €, 1,064 % de 17 000 à 60 000 €, 0,799 % au-delà. pretto.fr, vérifié le "&TEXT(DAY(Paramètres!$C$55),"00")&"/"&TEXT(MONTH(Paramètres!$C$55),"00")&"/"&YEAR(Paramètres!$C$55)&"." -> Code de commerce art. A444-91, arrêté du 25/02/2026 (en vigueur du 01/03/2026 au 29/02/2028) : 3,870 % jusqu'à 6 500 €, 1,596 % de 6 500 à 17 000 €, 1,064 % de 17 000 à 60 000 €, 0,799 % au-delà. pretto.fr, vérifié le 05/09/2026. | E17: À chaque arrêté tarifaire (tous les deux ans) | F17: Le classeur applique la forme linéaire du barème au-delà de 60 000 € : taux marginal × prix + part fixe (ligne suivante). En dessous de 60 000 €, il surestime légèrement les émoluments (prudent).
B18: Émoluments du notaire, part fixe des tranches inférieures (HT) | C18: 397.25 | D18: Calcul depuis le barème A444-91 : 6 500 × (3,870 − 0,799) % + 10 500 × (1,596 − 0,799) % + 43 000 × (1,064 − 0,799) % = 397,25 €. | E18: À chaque arrêté tarifaire | F18: Ce que les trois premières tranches ajoutent par rapport au taux marginal appliqué dès le premier euro.
B19: TVA sur les émoluments | C19: 0.2 | D19: ="CGI art. 278 : taux normal 20 %. Vérifié le "&TEXT(DAY(Paramètres!$C$55),"00")&"/"&TEXT(MONTH(Paramètres!$C$55),"00")&"/"&YEAR(Paramètres!$C$55)&"." -> CGI art. 278 : taux normal 20 %. Vérifié le 05/09/2026. | E19: À chaque loi de finances | F19: Les émoluments sont exprimés HT dans le barème ; l'acquéreur les paie TTC.
B20: Taux d'usure, prêts à taux fixe de moins de 10 ans | C20: 0.0407 | D20: ="Banque de France, taux d'usure applicables au 3e trimestre 2026, avis publié le 29/06/2026 et applicable depuis le 01/07/2026. banque-france.fr, rubrique Taux d'usure. Vérifié le "&TEXT(DAY(Paramètres!$C$55),"00")&"/"&TEXT(MONTH(Paramètres!$C$55),"00")&"/"&YEAR(Paramètres!$C$55)&"." -> Banque de France, taux d'usure applicables au 3e trimestre 2026, avis publié le 29/06/2026 et applicable depuis le 01/07/2026. banque-france.fr, rubrique Taux d'usure. Vérifié le 05/09/2026. | E20: Trimestrielle (1er janvier, avril, juillet, octobre) | F20: Plafond légal du TAEG. Une offre au-dessus est illégale.
B21: Taux d'usure, prêts à taux fixe de 10 ans à moins de 20 ans | C21: 0.0457 | D21: ="Banque de France, taux d'usure applicables au 3e trimestre 2026, avis publié le 29/06/2026 et applicable depuis le 01/07/2026. banque-france.fr, rubrique Taux d'usure. Vérifié le "&TEXT(DAY(Paramètres!$C$55),"00")&"/"&TEXT(MONTH(Paramètres!$C$55),"00")&"/"&YEAR(Paramètres!$C$55)&"." -> Banque de France, taux d'usure applicables au 3e trimestre 2026, avis publié le 29/06/2026 et applicable depuis le 01/07/2026. banque-france.fr, rubrique Taux d'usure. Vérifié le 05/09/2026. | E21: Trimestrielle
B22: Taux d'usure, prêts à taux fixe de 20 ans et plus | C22: 0.0529 | D22: ="Banque de France, taux d'usure applicables au 3e trimestre 2026, avis publié le 29/06/2026 et applicable depuis le 01/07/2026. banque-france.fr, rubrique Taux d'usure. Vérifié le "&TEXT(DAY(Paramètres!$C$55),"00")&"/"&TEXT(MONTH(Paramètres!$C$55),"00")&"/"&YEAR(Paramètres!$C$55)&"." -> Banque de France, taux d'usure applicables au 3e trimestre 2026, avis publié le 29/06/2026 et applicable depuis le 01/07/2026. banque-france.fr, rubrique Taux d'usure. Vérifié le 05/09/2026. | E22: Trimestrielle | F22: Tranche de la plupart des prêts immobiliers (20 et 25 ans).
B23: Seuil de durée entre les deux premières tranches d'usure | C23: 10 | D23: ="Banque de France, taux d'usure applicables au 3e trimestre 2026, avis publié le 29/06/2026 et applicable depuis le 01/07/2026. banque-france.fr, rubrique Taux d'usure. Vérifié le "&TEXT(DAY(Paramètres!$C$55),"00")&"/"&TEXT(MONTH(Paramètres!$C$55),"00")&"/"&YEAR(Paramètres!$C$55)&"." -> Banque de France, taux d'usure applicables au 3e trimestre 2026, avis publié le 29/06/2026 et applicable depuis le 01/07/2026. banque-france.fr, rubrique Taux d'usure. Vérifié le 05/09/2026. | E23: Stable | F23: Le classeur choisit la tranche d'usure selon la durée du prêt. Le tableau d'amortissement porte le même seuil en mois (120).
B24: Seuil de durée entre les deux dernières tranches d'usure | C24: 20 | D24: ="Banque de France, taux d'usure applicables au 3e trimestre 2026, avis publié le 29/06/2026 et applicable depuis le 01/07/2026. banque-france.fr, rubrique Taux d'usure. Vérifié le "&TEXT(DAY(Paramètres!$C$55),"00")&"/"&TEXT(MONTH(Paramètres!$C$55),"00")&"/"&YEAR(Paramètres!$C$55)&"." -> Banque de France, taux d'usure applicables au 3e trimestre 2026, avis publié le 29/06/2026 et applicable depuis le 01/07/2026. banque-france.fr, rubrique Taux d'usure. Vérifié le 05/09/2026. | E24: Stable | F24: Même seuil que le tableau d'amortissement, exprimé en années (240 mois).
B26: REPÈRES DE MARCHÉ (POINTS DE DÉPART, À AJUSTER SELON LA BANQUE)
B27: Paramètre | C27: Valeur | D27: Source (organisme, texte, date) | E27: Mise à jour | F27: Commentaire
B28: Pondération des revenus locatifs | C28: 0.7 | D28: ="Usage bancaire : 70 % chez la plupart des banques, 80 à 90 % chez quelques-unes sur dossiers de qualité. empruntis.com, quelcredit.com, vérifié le "&TEXT(DAY(Paramètres!$C$55),"00")&"/"&TEXT(MONTH(Paramètres!$C$55),"00")&"/"&YEAR(Paramètres!$C$55)&"." -> Usage bancaire : 70 % chez la plupart des banques, 80 à 90 % chez quelques-unes sur dossiers de qualité. empruntis.com, quelcredit.com, vérifié le 05/09/2026. | E28: Annuelle, selon la banque visée | F28: Couvre la vacance, les impayés et les charges du bailleur. S'applique aux loyers actuels et au loyer du bien financé.
B29: Pondération des primes et variables | C29: 1 | D29: ="Usage bancaire : 100 % si récurrentes sur 2 à 3 ans, 75 % dans certains établissements. prettymo.fr, vérifié le "&TEXT(DAY(Paramètres!$C$55),"00")&"/"&TEXT(MONTH(Paramètres!$C$55),"00")&"/"&YEAR(Paramètres!$C$55)&"." -> Usage bancaire : 100 % si récurrentes sur 2 à 3 ans, 75 % dans certains établissements. prettymo.fr, vérifié le 05/09/2026. | E29: Annuelle, selon la banque visée | F29: Paramètre optionnel. Laissez 100 % si les primes sont déjà lissées sur 3 ans.
B30: Reste à vivre minimal par adulte | C30: 800 | D30: ="Usage bancaire : 700 à 1 000 € par adulte, davantage en Île-de-France ; aucun minimum légal. reassurez-moi.fr (2026), selectra.info, vérifié le "&TEXT(DAY(Paramètres!$C$55),"00")&"/"&TEXT(MONTH(Paramètres!$C$55),"00")&"/"&YEAR(Paramètres!$C$55)&"." -> Usage bancaire : 700 à 1 000 € par adulte, davantage en Île-de-France ; aucun minimum légal. reassurez-moi.fr (2026), selectra.info, vérifié le 05/09/2026. | E30: Annuelle, selon la banque visée | F30: Ordre de grandeur ; varie fortement selon la banque et la zone.
B31: Reste à vivre minimal par enfant à charge | C31: 300 | D31: ="Usage bancaire : 300 à 500 € par enfant. Mêmes sources, vérifié le "&TEXT(DAY(Paramètres!$C$55),"00")&"/"&TEXT(MONTH(Paramètres!$C$55),"00")&"/"&YEAR(Paramètres!$C$55)&"." -> Usage bancaire : 300 à 500 € par enfant. Mêmes sources, vérifié le 05/09/2026. | E31: Annuelle, selon la banque visée | F31: Par enfant à charge.
B32: Débours et frais de formalités du notaire (forfait) | C32: 1000 | D32: ="frais-de-notaire.fr (CSI et débours 1 100 € pour 300 000 €, dont CSI 300 €) et pretto.fr (environ 0,4 % du prix) : 800 à 1 200 € pour un logement. Vérifié le "&TEXT(DAY(Paramètres!$C$55),"00")&"/"&TEXT(MONTH(Paramètres!$C$55),"00")&"/"&YEAR(Paramètres!$C$55)&"." -> frais-de-notaire.fr (CSI et débours 1 100 € pour 300 000 €, dont CSI 300 €) et pretto.fr (environ 0,4 % du prix) : 800 à 1 200 € pour un logement. Vérifié le 05/09/2026. | E32: Annuelle | F32: Documents d'urbanisme, état hypothécaire, cadastre, géomètre : des frais réels, peu liés au prix.
B33: Frais de garantie du prêt (en % du capital emprunté) | C33: 0.012 | D33: ="Convention prudente du classeur : Crédit Logement ne publie pas son barème et les relevés de place vont de 0,85 % + 200 € (optimhome.com, 2026) à 1,5 à 1,75 % du capital (perlib.fr, 2026). Vérifié le "&TEXT(DAY(Paramètres!$C$55),"00")&"/"&TEXT(MONTH(Paramètres!$C$55),"00")&"/"&YEAR(Paramètres!$C$55)&"." -> Convention prudente du classeur : Crédit Logement ne publie pas son barème et les relevés de place vont de 0,85 % + 200 € (optimhome.com, 2026) à 1,5 à 1,75 % du capital (perlib.fr, 2026). Vérifié le 05/09/2026. | E33: Annuelle, sur le simulateur creditlogement.fr | F33: Aucune source primaire ne tranche : le classeur retient la borne haute des relevés, parce que sous-estimer un coût avancé par l'emprunteur flatte le plan de financement. Caution : 65 à 70 % restitués en fin de prêt. Hypothèque ou PPD : 1,5 à 2 %, non restituables. À avancer dans tous les cas.
B34: Frais de dossier de la banque (forfait) | C34: 2000 | D34: ="Meilleurtaux, relevé de 119 banques au 01/03/2026 : moyenne 1 899,68 € pour 200 000 €, 92 établissements entre 0,50 % et 1,40 % du capital, de 0 € à 2 500 € selon les banques. Vérifié le "&TEXT(DAY(Paramètres!$C$55),"00")&"/"&TEXT(MONTH(Paramètres!$C$55),"00")&"/"&YEAR(Paramètres!$C$55)&"." -> Meilleurtaux, relevé de 119 banques au 01/03/2026 : moyenne 1 899,68 € pour 200 000 €, 92 établissements entre 0,50 % et 1,40 % du capital, de 0 € à 2 500 € selon les banques. Vérifié le 05/09/2026. | E34: Annuelle | F34: Négociables. 0 € dans quelques banques en ligne, 2 500 € au plafond le plus élevé du relevé. Valeur prudente, arrondie au-dessus de la moyenne du relevé.
B35: Taux moyen constaté sur 25 ans (repère pour la saisie du taux) | C35: 0.0335 | D35: ="Observatoire Crédit Logement / CSA, analyse du marché du mois d'août 2026 (publiée en septembre 2026) : 3,35 % sur 25 ans, 3,14 % sur 15 ans, en hausse de 15 centièmes de point depuis décembre 2025. lobservatoire.creditlogement.fr. Vérifié le "&TEXT(DAY(Paramètres!$C$55),"00")&"/"&TEXT(MONTH(Paramètres!$C$55),"00")&"/"&YEAR(Paramètres!$C$55)&"." -> Observatoire Crédit Logement / CSA, analyse du marché du mois d'août 2026 (publiée en septembre 2026) : 3,35 % sur 25 ans, 3,14 % sur 15 ans, en hausse de 15 centièmes de point depuis décembre 2025. lobservatoire.creditlogement.fr. Vérifié le 05/09/2026. | E35: Mensuelle | F35: Information : non utilisée par les formules. Le taux du dossier se saisit dans l'onglet Capacité d'emprunt.
B36: Taux d'assurance emprunteur, contrat groupe (repère) | C36: 0.0036 | D36: ="Baromètres 2026 (pretclair.fr, covelia.fr) : environ 0,36 % du capital initial, 35 ans non fumeur. Vérifié le "&TEXT(DAY(Paramètres!$C$55),"00")&"/"&TEXT(MONTH(Paramètres!$C$55),"00")&"/"&YEAR(Paramètres!$C$55)&"." -> Baromètres 2026 (pretclair.fr, covelia.fr) : environ 0,36 % du capital initial, 35 ans non fumeur. Vérifié le 05/09/2026. | E36: Annuelle | F36: Information : repère pour la saisie du taux d'assurance. Davantage après 45 ans ou avec surprime.
B37: Taux d'assurance emprunteur, délégation (repère) | C37: 0.0017 | D37: ="Baromètres 2026 (pretclair.fr, covelia.fr) : environ 0,17 % du capital initial, 35 ans non fumeur. Vérifié le "&TEXT(DAY(Paramètres!$C$55),"00")&"/"&TEXT(MONTH(Paramètres!$C$55),"00")&"/"&YEAR(Paramètres!$C$55)&"." -> Baromètres 2026 (pretclair.fr, covelia.fr) : environ 0,17 % du capital initial, 35 ans non fumeur. Vérifié le 05/09/2026. | E37: Annuelle | F37: Information : repère pour la saisie du taux d'assurance.
B38: Frais de notaire usuels dans l'ancien (ordre de grandeur) | C38: 0.08 | D38: ="frais-de-notaire.fr, achat ancien 2026 : 7,8 % pour 300 000 €, de 7 à 8,5 % selon le prix. Vérifié le "&TEXT(DAY(Paramètres!$C$55),"00")&"/"&TEXT(MONTH(Paramètres!$C$55),"00")&"/"&YEAR(Paramètres!$C$55)&"." -> frais-de-notaire.fr, achat ancien 2026 : 7,8 % pour 300 000 €, de 7 à 8,5 % selon le prix. Vérifié le 05/09/2026. | E38: Annuelle | F38: Information : repère pour lire la ligne « Frais de notaire rapportés au prix ». Le classeur calcule les frais réels.
B39: Frais de notaire usuels dans le neuf (ordre de grandeur) | C39: 0.025 | D39: ="meilleurescpi.com, frais de notaire 2026 : 2 à 3 % dans le neuf. Vérifié le "&TEXT(DAY(Paramètres!$C$55),"00")&"/"&TEXT(MONTH(Paramètres!$C$55),"00")&"/"&YEAR(Paramètres!$C$55)&"." -> meilleurescpi.com, frais de notaire 2026 : 2 à 3 % dans le neuf. Vérifié le 05/09/2026. | E39: Annuelle | F39: Information : repère pour lire la ligne « Frais de notaire rapportés au prix ».
B41: BORNES DE SAISIE (VALIDATIONS ET CONTRÔLE GLOBAL)
B42: Paramètre | C42: Valeur | D42: Source (organisme, texte, date) | E42: Mise à jour | F42: Commentaire
B43: Borne de saisie : taux du prêt maximal | C43: 0.2 | D43: Borne de vraisemblance du classeur, sans valeur réglementaire. | E43: Jamais | F43: Une saisie au-delà est refusée et le contrôle global passe au rouge.
...

Sheet Méthode
B1: CorpusImmo · corpus.immo · Estimer, comparer, décider. Sur les ventes réelles.
B2: Méthode et limites
B3: Comment la banque raisonne, où le modèle s'arrête, et sur quelles sources reposent ses chiffres.
B5: CONVENTIONS RETENUES, ET CE QU'ELLES COÛTENT
B6: Revenus retenus | C6: Salaires nets, primes récurrentes lissées, et loyers PONDÉRÉS. La pondération (70 % par défaut, repère 2026) couvre la vacance, les impayés et les charges du bailleur. Compter les loyers à 100 % au lieu de 70 % majore la part locative des revenus de 43 % ; l'effet sur la capacité dépend du poids des loyers (sur l'exemple 2026 : +210 € de revenus retenus, soit +4 % de capacité). Les primes et variables sont pondérées à part (100 % par défaut, repère 2026). Pour un investissement locatif, le loyer attendu du bien financé est ajouté aux loyers, avec la même pondération : c'est la méthode classique des banques ; la méthode différentielle (loyers nets de charges compensés avec la mensualité) n'est pas modélisée.
B7: Mensualité maximale | C7: Revenus retenus × taux d'effort − charges existantes. Le taux d'effort de 35 % (HCSF, norme 2026) s'entend assurance emprunteur comprise, ce que beaucoup de simulateurs oublient. Les charges retenues comprennent les crédits en cours, la pension versée et, pour un investissement locatif, le loyer actuel qui continue : option prudente, certaines banques renvoient loyer et pension au seul reste à vivre.
B8: Reste à vivre | C8: Deuxième filtre, indépendant du premier. Le modèle retient la plus contraignante des deux règles, parce que c'est ce que fait un analyste crédit. Le reste à vivre affiché est calculé après la mensualité retenue (et non après la mensualité théorique) : il ne peut donc pas passer sous le minimum tant qu'une mensualité est possible. Il est calculé sur les revenus retenus (loyers pondérés) et avant impôt sur le revenu : convention prudente ; une banque qui raisonne après impôt trouvera un reste à vivre plus faible, une banque qui compte les loyers à 100 % un reste à vivre plus élevé.
B9: Deux taux d'endettement | C9: Le taux d'effort HCSF strict rapporte les seules charges d'emprunt (crédits en cours plus la mensualité, assurance comprise) aux revenus retenus : c'est le ratio que la banque déclare au régulateur. Le taux de charges tout compris ajoute la pension versée et le loyer conservé : c'est celui que le modèle plafonne à 35 %. Les deux sont affichés parce qu'un courtier présente les deux.
B10: Capital empruntable | C10: Valeur actuelle (PV) de la mensualité sur la durée, corrigée de l'assurance. L'assurance étant assise sur le capital initial, elle mord sur la mensualité disponible : la corriger après coup surestime le capital d'environ 5 % à 0,30 % d'assurance sur 25 ans (exemple 2026), moins sur une durée courte. Taux mensuel proportionnel (taux annuel divisé par 12), annuité constante. L'assurance est calculée sur le capital initial avec un taux global pour tous les emprunteurs : deux emprunteurs assurés chacun à 100 % doublent ce taux.
B11: Frais de notaire 2026 | C11: Barèmes 2026, tous en Paramètres. Ancien : droits de mutation à 6,32 % du prix (droit départemental porté à 5 % du 1er avril 2025 au 31 mars 2028 dans la grande majorité des départements) ou 5,81 % (départements restés à 4,50 %, et primo-accédants achetant leur résidence principale, exonérés de la hausse), plus contribution de sécurité immobilière 0,10 %, émoluments du notaire TTC selon le barème par tranches (linéarisé au-delà de 60 000 €) et débours forfaitaires. Neuf ou VEFA : taxe de publicité foncière 0,715 % à la place des droits de mutation, le reste inchangé. Hors honoraires d'agence et hors mobilier, qui échappent aux droits.
B12: Prix d'achat maximal | C12: Budget total (capital plus apport), moins les frais de garantie (en % du capital), les frais de dossier et la part fixe des frais de notaire, divisé par (1 + part proportionnelle des frais de notaire). On raisonne à l'envers du budget, car les frais se calculent sur le prix, pas sur le budget. Le contrôle « Apport couvre les frais » signale un dossier où le prêt financerait des frais, ce que les banques refusent en pratique.
B13: Durée | C13: 25 ans au plus (HCSF, norme 2026) ; 27 ans quand un différé d'amortissement de 2 ans au plus est justifié par une VEFA, une construction ou des travaux représentant au moins 10 % du coût total (décision HCSF du 29 juin 2023, seuil auparavant fixé à 25 %). Le classeur accepte une durée jusqu'à la borne de Paramètres (30 ans) mais l'affiche en rouge au-delà du maximum applicable.
B14: Dérogations HCSF | C14: Les banques peuvent déroger au taux d'effort et à la durée pour 20 % de leur production trimestrielle (HCSF, norme 2026), dont au moins 70 % pour l'achat d'une résidence principale et au moins 30 % pour les primo-accédants ; cette marge était utilisée à 17,5 % au premier trimestre 2026. Le classeur signale les dossiers hors norme (contrôles rouges) sans les interdire : leur acceptation relève de chaque banque.
B15: Bilan patrimonial | C15: Le patrimoine net est ce qui reste si tout était vendu et toutes les dettes soldées. Une banque le regarde pour deux raisons : il mesure votre capacité à encaisser un coup dur, et il révèle une éventuelle capacité d'apport complémentaire. Un patrimoine net solide compense parfois un taux d'endettement à la limite. Les liquidités mobilisables retiennent les comptes, livrets, assurance-vie, PEA et comptes-titres, et excluent l'épargne retraite (bloquée, sauf déblocage pour la résidence principale), les parts de sociétés et les autres actifs. Le pro forma se place au jour de la signature, au prix maximal : le patrimoine net baisse exactement des frais de l'opération ; l'endettement immobilier (LTV) et le ratio dettes sur actif sont recalculés avec le nouveau prêt.
B16: Taux d'usure | C16: Le taux d'usure plafonne le TAEG, pas le taux nominal, et la Banque de France le publie par tranche de durée (moins de 10 ans, 10 à moins de 20 ans, 20 ans et plus) le dernier jour ouvré de chaque trimestre. Ce classeur ne calcule pas de TAEG : il compare le taux du prêt augmenté du taux d'assurance au plafond de la tranche. Cette somme est inférieure au TAEG, qui intègre en plus les frais de dossier et de garantie : le contrôle est donc conservateur dans un seul sens. Rouge veut dire que l'offre est certainement illégale ; vert veut dire qu'il reste de la marge, à condition que les frais tiennent dedans. Le TAEG lui-même se calcule dans la matrice Tableau d'amortissement et comparateur de prêts, qui porte les mêmes trois tranches et le même seuil de durée.
B17: Taux et dates | C17: Tous les taux sont des fractions affichées en pourcentage : tapez 3,3 dans une cellule de taux, elle affiche 3,30 % et contient 0,033. Aucune formule ne divise par 100. Les durées sont en années entières.
B19: CE QUE CE MODÈLE NE FAIT PAS
B20: • Il ne remplace pas l'accord d'une banque : chaque établissement a sa grille et ses dérogations.
B21: • Il ne tient pas compte de la stabilité professionnelle, qui pèse autant que le taux d'effort.
B22: • Il ne modélise pas le prêt à taux zéro, ni les prêts employeur ou aidés, ni un prêt relais (dont les intérêts sont exclus du taux d'effort par la décision HCSF du 4 décembre 2023).
B23: • Il ne calcule pas le TAEG, le seul taux que le taux d'usure plafonne légalement. Le contrôle d'usure de cet onglet compare le taux du prêt augmenté de l'assurance, qui reste en dessous du TAEG puisqu'il ignore les frais : il détecte une offre certainement illégale, il ne certifie pas une offre conforme. Le TAEG se calcule dans la matrice Tableau d'amortissement et comparateur de prêts.
B24: • Il ne calcule pas les frais de notaire au barème exact en dessous de 60 000 € (il les surestime légèrement), ni les honoraires d'agence, ni la part de mobilier hors droits.
B25: • Il ne modélise pas la méthode différentielle des banques pour l'investissement locatif, ni la fiscalité des loyers (voir la matrice Calculateur de rentabilité locative).
B26: • Il ne fait pas de sensibilité durée × taux sur le capital empruntable (voir la matrice Tableau d'amortissement et comparateur de prêts).
B27: • Il ne remplace ni un courtier, ni un conseil en gestion de patrimoine.
B29: SOURCES
B30: Taux d'effort maximal HCSF (assurance comprise) | C30: ="HCSF, décision D-HCSF-2021-7 du 29/09/2021, confirmée par la décision D-HCSF-2023-2 du 29/06/2023. economie.gouv.fr/hcsf, vérifié le "&TEXT(DAY(Paramètres!$C$55),"00")&"/"&TEXT(MONTH(Paramètres!$C$55),"00")&"/"&YEAR(Paramètres!$C$55)&"." -> HCSF, décision D-HCSF-2021-7 du 29/09/2021, confirmée par la décision D-HCSF-2023-2 du 29/06/2023. economie.gouv.fr/hcsf, vérifié le 05/09/2026.
B31: Durée maximale HCSF, cas général | C31: ="HCSF, décision D-HCSF-2021-7 du 29/09/2021. Vérifié le "&TEXT(DAY(Paramètres!$C$55),"00")&"/"&TEXT(MONTH(Paramètres!$C$55),"00")&"/"&YEAR(Paramètres!$C$55)&"." -> HCSF, décision D-HCSF-2021-7 du 29/09/2021. Vérifié le 05/09/2026.
B32: Durée maximale HCSF avec différé (VEFA, construction, travaux) | C32: ="HCSF, décisions du 29/09/2021 (différé de 2 ans au plus) et du 29/06/2023 (seuil de travaux abaissé de 25 % à 10 % du coût total). Vérifié le "&TEXT(DAY(Paramètres!$C$55),"00")&"/"&TEXT(MONTH(Paramètres!$C$55),"00")&"/"&YEAR(Paramètres!$C$55)&"." -> HCSF, décisions du 29/09/2021 (différé de 2 ans au plus) et du 29/06/2023 (seuil de travaux abaissé de 25 % à 10 % du coût total). Vérifié le 05/09/2026.
B33: Seuil de travaux ouvrant le différé (part du coût total) | C33: ="HCSF, décision D-HCSF-2023-2 du 29/06/2023 (auparavant 25 %). Vérifié le "&TEXT(DAY(Paramètres!$C$55),"00")&"/"&TEXT(MONTH(Paramètres!$C$55),"00")&"/"&YEAR(Paramètres!$C$55)&"." -> HCSF, décision D-HCSF-2023-2 du 29/06/2023 (auparavant 25 %). Vérifié le 05/09/2026.
B34: Marge de flexibilité HCSF (part de la production trimestrielle) | C34: ="HCSF, décision D-HCSF-2023-2 du 29/06/2023 : 20 % de la production, dont au moins 70 % pour la résidence principale et au moins 30 % pour les primo-accédants. Utilisée à 17,5 % au 1er trimestre 2026 (Meilleurtaux, 11/06/2026). Vérifié le "&TEXT(DAY(Paramètres!$C$55),"00")&"/"&TEXT(MONTH(Paramètres!$C$55),"00")&"/"&YEAR(Paramètres!$C$55)&"." -> HCSF, décision D-HCSF-2023-2 du 29/06/2023 : 20 % de la production, dont au moins 70 % pour la résidence principale et au moins 30 % pour les primo-accédants. Utilisée à 17,5 % au 1er trimestre 2026 (Meilleurtaux, 11/06/2026). Vérifié le 05/09/2026.
B35: Droits de mutation, ancien, droit départemental majoré à 5 % | C35: ="LF 2025 (loi n° 2025-127 du 14/02/2025) art. 116 : droit départemental porté de 4,50 % à 5 % (CGI art. 1594 D) du 01/04/2025 au 31/03/2028 ; taxe communale 1,20 % (art. 1584) ; frais d'assiette 2,37 % du droit départemental (art. 1647 V). taximmo.fr,"&" vérifié le "&TEXT(DAY(Paramètres!$C$55),"00")&"/"&TEXT(MONTH(Paramètres!$C$55),"00")&"/"&YEAR(Paramètres!$C$55)&"." -> LF 2025 (loi n° 2025-127 du 14/02/2025) art. 116 : droit départemental porté de 4,50 % à 5 % (CGI art. 1594 D) du 01/04/2025 au 31/03/2028 ; taxe communale 1,20 % (art. 1584) ; frais d'assiette 2,37 % du droit départemental (art. 1647 V). taximmo.fr, vérifié le 05/09/2026.
B36: Droits de mutation, ancien, droit départemental à 4,50 % | C36: ="CGI art. 1594 D (4,50 %), 1584 (1,20 %), 1647 V (2,37 %). Maintenu dans les départements qui n'ont pas voté la hausse et pour les primo-accédants achetant leur résidence principale (LF 2025 art. 116, II). taximmo.fr, vérifié le "&TEXT(DAY(Paramètres!$C$55),"00")&"/"&TEXT(MONTH(Paramètres!$C$55),"00")&"/"&YEAR(Paramètres!$C$55)&"." -> CGI art. 1594 D (4,50 %), 1584 (1,20 %), 1647 V (2,37 %). Maintenu dans les départements qui n'ont pas voté la hausse et pour les primo-accédants achetant leur résidence principale (LF 2025 art. 116, II). taximmo.fr, vérifié le 05/09/2026.
B37: Taxe de publicité foncière, neuf ou VEFA | C37: ="CGI art. 1594 F quinquies A (taux réduit 0,70 %) et 1647 V (frais d'assiette 2,14 %). Vérifié le "&TEXT(DAY(Paramètres!$C$55),"00")&"/"&TEXT(MONTH(Paramètres!$C$55),"00")&"/"&YEAR(Paramètres!$C$55)&"." -> CGI art. 1594 F quinquies A (taux réduit 0,70 %) et 1647 V (frais d'assiette 2,14 %). Vérifié le 05/09/2026.
B38: Contribution de sécurité immobilière | C38: ="CGI art. 879 : 0,10 % du prix, ancien comme neuf. Vérifié le "&TEXT(DAY(Paramètres!$C$55),"00")&"/"&TEXT(MONTH(Paramètres!$C$55),"00")&"/"&YEAR(Paramètres!$C$55)&"." -> CGI art. 879 : 0,10 % du prix, ancien comme neuf. Vérifié le 05/09/2026.
B39: Émoluments du notaire, taux marginal au-delà de 60 000 € (HT) | C39: ="Code de commerce art. A444-91, arrêté du 25/02/2026 (en vigueur du 01/03/2026 au 29/02/2028) : 3,870 % jusqu'à 6 500 €, 1,596 % de 6 500 à 17 000 €, 1,064 % de 17 000 à 60 000 €, 0,799 % au-delà. pretto.fr, vérifié le "&TEXT(DAY(Paramètres!$C$55),"00")&"/"&TEXT(MONTH(Paramètres!$C$55),"00")&"/"&YEAR(Paramètres!$C$55)&"." -> Code de commerce art. A444-91, arrêté du 25/02/2026 (en vigueur du 01/03/2026 au 29/02/2028) : 3,870 % jusqu'à 6 500 €, 1,596 % de 6 500 à 17 000 €, 1,064 % de 17 000 à 60 000 €, 0,799 % au-delà. pretto.fr, vérifié le 05/09/2026.
B40: Émoluments du notaire, part fixe des tranches inférieures (HT) | C40: Calcul depuis le barème A444-91 : 6 500 × (3,870 − 0,799) % + 10 500 × (1,596 − 0,799) % + 43 000 × (1,064 − 0,799) % = 397,25 €.
B41: TVA sur les émoluments | C41: ="CGI art. 278 : taux normal 20 %. Vérifié le "&TEXT(DAY(Paramètres!$C$55),"00")&"/"&TEXT(MONTH(Paramètres!$C$55),"00")&"/"&YEAR(Paramètres!$C$55)&"." -> CGI art. 278 : taux normal 20 %. Vérifié le 05/09/2026.
B42: Taux d'usure, prêts à taux fixe de moins de 10 ans | C42: ="Banque de France, taux d'usure applicables au 3e trimestre 2026, avis publié le 29/06/2026 et applicable depuis le 01/07/2026. banque-france.fr, rubrique Taux d'usure. Vérifié le "&TEXT(DAY(Paramètres!$C$55),"00")&"/"&TEXT(MONTH(Paramètres!$C$55),"00")&"/"&YEAR(Paramètres!$C$55)&"." -> Banque de France, taux d'usure applicables au 3e trimestre 2026, avis publié le 29/06/2026 et applicable depuis le 01/07/2026. banque-france.fr, rubrique Taux d'usure. Vérifié le 05/09/2026.
B43: Taux d'usure, prêts à taux fixe de 10 ans à moins de 20 ans | C43: ="Banque de France, taux d'usure applicables au 3e trimestre 2026, avis publié le 29/06/2026 et applicable depuis le 01/07/2026. banque-france.fr, rubrique Taux d'usure. Vérifié le "&TEXT(DAY(Paramètres!$C$55),"00")&"/"&TEXT(MONTH(Paramètres!$C$55),"00")&"/"&YEAR(Paramètres!$C$55)&"." -> Banque de France, taux d'usure applicables au 3e trimestre 2026, avis publié le 29/06/2026 et applicable depuis le 01/07/2026. banque-france.fr, rubrique Taux d'usure. Vérifié le 05/09/2026.
...
