Workbook

Sheet Mode d'emploi
B1: CorpusImmo · corpus.immo · Estimer, comparer, décider. Sur les ventes réelles.
B2: Mode d'emploi
B3: À quoi sert ce classeur, dans quel ordre le remplir, et comment lire ce qu'il répond.
B6: À QUOI SERT CE CLASSEUR
B7: Vous avez un immeuble et ses baux. Ce classeur répond à trois questions : combien il rapporte aujourd'hui, combien de temps ce revenu est sécurisé, et quand il se remet en jeu.
B8: Un rent roll, c'est l'état locatif d'un immeuble : une ligne par lot, avec son locataire, sa surface, son loyer et ses dates. À partir de là, le classeur calcule le WAULT et le WALB, les deux durées résiduelles que publient les foncières, le taux d'occupation physique et le taux d'occupation financier, la réversion, et l'échéancier des sorties année par année.
B9: Un seul onglet à remplir : Rent roll. Vous saisissez les cellules bleues, tout le reste se calcule. La Synthèse et l'Échéancier ne se saisissent pas, ils se lisent.
B10: Vous êtes | C10: Ce que le classeur vous donne
B11: Analyste investissement, acquéreur | C11: Le WALB (Synthèse!C39), la réversion, en euros (Synthèse!C30) et en part du loyer en place (Synthèse!C31), et l'année de pointe de l'échéancier : de quoi savoir si vous achetez un revenu ou un risque de relocation.
B12: Asset manager | C12: Les lots à traiter en priorité : ceux dont la sortie est proche (colonne Q du rent roll) et ceux dont le loyer est au-dessus du marché (colonne L).
B13: Property manager, gestionnaire | C13: Un état locatif tenu, avec un contrôle par ligne qui refuse une saisie incomplète au lieu de la compter à zéro (Rent roll!V11:V50).
B14: Broker, conseil en investissement | C14: Les chiffres du teaser : le loyer facial en place (Synthèse!C24), le taux d'occupation financier, le WAULT et le WALB au loyer facial, l'échéancier. Ceux que l'acquéreur vérifiera. Gardez le loyer économique (Synthèse!C25) pour la discussion de prix : c'est sur lui que se calcule un rendement.
B15: Banquier | C15: Le loyer sécurisé au-delà de la durée du prêt : l'échéancier (Échéancier!B10:I28) dit combien de loyer se remet en jeu chaque année, et sa dernière ligne recoupe le total avec le rent roll.
B16: Expert, évaluateur | C16: Le loyer facial et le loyer économique côte à côte (Synthèse!C24 et Synthèse!C25), et l'écart au marché lot par lot.
B18: LE PRINCIPE, EN UNE LIGNE
B19: Le loyer de chaque bail, pondéré par le temps qui reste avant que le locataire puisse partir, divisé par le loyer total : c'est le WALB, la durée pendant laquelle le revenu est sécurisé. Le reste du classeur dit ce que vaut ce revenu aujourd'hui, ce qu'il vaudrait au marché, et quand il se remet en jeu
B21: LES ONGLETS, DANS L'ORDRE OÙ ON LES REMPLIT
B22: Onglet | C22: Ce que vous y faites | D22: Ce que vous y lisez
B23: Mode d'emploi | C23: Rien à saisir. Vous lisez ce guide. | D23: La marche à suivre et l'exemple guidé.
B24: Rent roll | C24: Vous saisissez la date d'analyse en Rent roll!C7, puis un lot par ligne : nature, locataire, statut, surface, loyer, valeur locative, dates, périodicité de sortie, franchise. | D24: Par ligne : le loyer annuel, la valeur locative annuelle, la réversion, la prochaine sortie calculée, le loyer économique, les deux durées résiduelles, un contrôle et son motif.
B25: Synthèse | C25: Rien à saisir. | D25: Cinq blocs : les contrôles, les surfaces et l'occupation, les loyers et la réversion, les durées résiduelles, la concentration.
B26: Échéancier | C26: Rien à saisir. | D26: Le loyer qui se remet en jeu par année, au terme et à la sortie, avec les baux échus, l'au-delà de l'horizon, le total et son recoupement.
B27: Paramètres | C27: Rien, sauf à la mise à jour des indices et des seuils. | D27: Chaque valeur avec sa source datée et sa fréquence de mise à jour.
B28: Méthode | C28: Rien à saisir. | D28: Les conventions de calcul, ce que le modèle ne fait pas, les sources.
B30: LE CODE COULEUR, ET COMMENT DÉVERROUILLER UNE CELLULE
B31: Cellule | C31: Ce que c'est | D31: Ce que vous faites
B32: Fond bleu ciel, texte bleu nuit | C32: Saisie utilisateur | D32: Vous la remplissez ou l'effacez (touche Suppr), même feuille protégée. Jamais de formule dedans.
B33: Fond blanc | C33: Calcul | D33: Vous la lisez. Elle est verrouillée.
B34: Fond presque blanc, texte bleu nuit en gras | C34: Résultat de bloc, chiffre clé | D34: Vous la lisez. C'est un chiffre à retenir.
B35: Bandeau bleu nuit | C35: Titre de section, en-tête de tableau | D35: Repère de navigation.
B36: Texte gris | C36: Commentaire d'aide, ordre de grandeur | D36: Une phrase par ligne pour savoir quoi saisir.
B37: Vert OK, rouge À CORRIGER | C37: Contrôle de cohérence | D37: Rouge : lisez la colonne W de la ligne concernée, ou la Synthèse, qui nomme la première ligne en cause.
B38: Les onglets sont protégés sans mot de passe pour éviter d'écraser une formule par erreur. Les cellules bleues restent modifiables et effaçables sans rien déverrouiller. N'ôtez la protection que pour toucher une cellule blanche, par l'onglet Révision, « Ôter la protection de la feuille ». Aucun mot de passe n'est demandé.
B40: LA MARCHE À SUIVRE, ÉTAPE PAR ÉTAPE
B41: Étape | C41: Où (onglet et plage) | D41: Ce que vous faites | E41: Pourquoi
B42: 0. L'exemple livré | C42: Rent roll!B11:G50, Rent roll!I11:I50, Rent roll!M11:P50, Rent roll!R11:R50, Rent roll!C7 | D42: Le classeur est livré rempli d'un exemple : un immeuble de 1 755 m² avec sept lots. Gardez-le pour vous repérer, ou effacez les sept lignes de l'exemple avant de saisir votre immeuble. Les colonnes bleues d'une ligne ne sont pas contiguës : sélectionnez Rent roll!B11:G17, Rent roll!I11:I17, Rent roll!M11:P17 et Rent roll!R11:R17, en maintenant la touche Ctrl pour ajouter chaque bloc à la sélection, puis appuyez sur Suppr. Les colonnes H, J, K, L et Q sont des formules verrouillées : si vous les incluez dans la sélection, Excel refuse l'effacement entier et affiche un message de protection. Elles se videront d'elles-mêmes. Videz toujours une ligne de bail en entier : une ligne à demi effacée reste comptée comme renseignée, passe au rouge et bloque le contrôle d'ensemble. La grille accepte 40 baux, lignes 11 à 50 : pour ajouter un lot, servez-vous de la première ligne bleue libre, elles sont déjà prêtes et il n'y a aucune ligne à insérer. Vérifiez surtout les saisies facultatives, qui n'ont pas de raison d'être dans votre cas : la périodicité de sortie (Rent roll!O11:O50, à ne remplir que pour un bail ayant renoncé à ses triennales), la sortie forcée (Rent roll!P11:P50) et la franchise (Rent roll!R11:R50). Pendant que vous effacez, les contrôles passent au rouge et les totaux tombent : c'est normal, tout revient dès que la saisie est complète. | E42: Une saisie résiduelle de l'exemple est l'erreur la plus probable d'un premier usage, et les deux colonnes facultatives ne se trahissent pas de la même façon. Une périodicité de six ans héritée allonge le WALB et gonfle le loyer économique, parce que la franchise s'étale alors sur 72 mois au lieu de 36. Une franchise héritée, elle, ne touche pas au WALB, qui ne dépend que des dates : elle rabote le loyer économique. Trois mois hérités sur un lot à 119 700 € lui retirent 9 975 € par an. Dans les deux cas, aucun contrôle ne s'allume.
B43: 1. La date d'analyse | C43: Rent roll!C7 | D43: Tapez la date à laquelle vous photographiez l'immeuble, en vraie date au format jj/mm/aaaa. Le plus souvent la date d'un arrêté comptable, d'une offre ou d'un rapport d'expertise. | E43: Toutes les durées résiduelles, la prochaine sortie de chaque bail et la première année de l'échéancier en dépendent. C'est la seule cellule qui commande tout le classeur.
B44: 2. Les lots et les locataires | C44: Rent roll!B11:E50 | D44: Une ligne par lot : un libellé (obligatoire, il nomme la ligne dans les contrôles), la nature dans la liste, le nom du locataire, et le statut Loué ou Vacant. Laissez le locataire vide sur un lot vacant. | E44: Le statut remplace le test « la colonne locataire est-elle vide ». Écrire « Vacant » dans la colonne du locataire ne suffit pas : c'est le statut qui décide. Avec le statut Vacant, la ligne passe au rouge ; avec le statut Loué et un loyer saisi, le lot est compté comme loué et rien ne le signale.
B45: 3. Surfaces, loyers et valeur locative | C45: Rent roll!F11:G50 et Rent roll!I11:I50 | D45: La surface locative, le loyer facial hors taxes hors charges au mètre carré et par an, et la valeur locative de marché au mètre carré. Cette colonne s'intitule VLM sur la feuille, pour valeur locative de marché. Renseignez-la sur tous les lots, vacants compris. | E45: Le loyer annuel (Rent roll!H11:H50) et la valeur locative annuelle (Rent roll!J11:J50) se calculent seuls. Sans valeur locative sur tous les lots, le contrôle Synthèse!C10 passe au rouge, et le taux d'occupation financier comme la réversion restent vides : sur un lot vacant, une valeur locative manquante minorerait la vacance, donc flatterait l'immeuble ; sur un lot loué, elle vaudrait zéro et retournerait la réversion. Tant que ce contrôle est rouge, ne lisez ni l'un ni l'autre, et cherchez la ligne que nomme Synthèse!C9.
B46: 4. Les dates du bail | C46: Rent roll!M11:P50 | D46: La prise d'effet et l'échéance, en vraies dates. Laissez la périodicité de sortie vide dans le cas général : le classeur applique la périodicité légale de Paramètres!C8. Mettez 6 ou 9 pour un bail de bureaux, un bail long, un local monovalent ou de stockage ayant renoncé à ses premières triennales. Ne remplissez la sortie forcée que si vous connaissez déjà la date de sortie, par exemple parce qu'un congé a été reçu. | E46: La prochaine sortie (Rent roll!Q11:Q50) est alors calculée, pas devinée : c'est la première fin de période strictement postérieure à la date d'analyse, plafonnée à l'échéance. C'est le cœur du WALB, et la première cause d'erreur dans un rent roll tenu à la main.
...

Sheet Rent roll
B1: CorpusImmo · corpus.immo · Estimer, comparer, décider. Sur les ventes réelles.
B2: Rent roll
B3: L'état locatif lot par lot : loyer facial et loyer économique, valeur locative de marché, prochaine faculté de sortie et durées résiduelles.
B5: Cellules bleues : à remplir. Cellules blanches : calculées automatiquement. | E5: Une ligne par lot. La grille accepte 40 baux, lignes 11 à 50 : ajoutez vos lots à la suite, dans les lignes bleues déjà prêtes, sans jamais insérer de ligne. Aucune cellule n'est fusionnée. Le filtre automatique est posé sur la ligne d'en-tête et la protection l'autorise : filtrez sans rien déverrouiller. Pour trier, ôtez d'abord la protection par l'onglet Révision, puis triez la plage entière, colonnes calculées comprises, et remettez la protection.
B7: Date d'analyse | C7: 46203 | E7: Toutes les durées résiduelles et l'échéancier partent de cette date. Une vraie date, au format jj/mm/aaaa.
B8: État locatif exploitable | C8: =IF(Synthèse!$C$7="OK","OK","À CORRIGER") -> OK | E8: Rouge : la date d'analyse manque, aucun bail n'est retenu, une ligne est à corriger ou à compléter, ou un paramètre est vide. Le motif est dans la colonne W, y compris sur une ligne verte à laquelle il ne manque que sa valeur locative ; la Synthèse les compte et nomme la première.
B10: Lot | C10: Nature | D10: Locataire | E10: Statut | F10: Surface | G10: Loyer facial €/m²/an HT HC | H10: Loyer facial annuel HT HC | I10: VLM €/m²/an | J10: VLM annuelle | K10: Réversion | L10: Réversion % | M10: Prise d'effet | N10: Échéance | O10: Périodicité de sortie (ans) | P10: Sortie forcée (facultatif) | Q10: Prochaine sortie retenue | R10: Franchise (mois) | S10: Loyer économique annuel | T10: Durée au terme | U10: Durée à la sortie | V10: Contrôle | W10: Motif | X10: Loyer du locataire (tous ses lots)
B11: R+1 Plateau A | C11: Bureaux | D11: Locataire Alpha | E11: Loué | F11: 420 | G11: 285 | H11: =IF(AND(ISNUMBER(F11),ISNUMBER(G11)),F11*G11,0) -> 119700 | I11: 300 | J11: =IF(AND(ISNUMBER(F11),ISNUMBER(I11)),F11*I11,0) -> 126000 | K11: =IF(OR(H11<=0,J11<=0),"",J11-H11) -> 6300 | L11: =IF(OR(H11<=0,J11<=0),"",J11/H11-1) -> 0.052631579 | M11: 45108 | N11: 48395 | Q11: =IF(OR(NOT(ISNUMBER($C$7)),NOT(ISNUMBER(M11)),NOT(ISNUMBER(N11))),"",IF(ISNUMBER(P11),P11,IF((IF(OR(O11="",NOT(ISNUMBER(O11))),Paramètres!$C$8,O11))<=0,"",MIN(EDATE(M11,(12*(IF(OR(O11="",NOT(ISNUMBER(O11))),Paramètres!$C$8,O11)))*MAX(1,INT(((YEAR($C$7+1)-YEAR(M11))*12+MONTH($C$7+1)-MONTH(M11)-(DAY($C$7+1)<DAY(M11)))/(12*(IF(OR(O11="",NOT(ISNUMBER(O11))),Paramètres!$C$8,O11))))+1))-1,N11)))) -> 47299 | R11: 3 | S11: =IF(H11=0,0,IF(OR(R11="",R11=0),H11,IF(OR(NOT(ISNUMBER(R11)),(IF(OR(NOT(ISNUMBER(M11)),NOT(ISNUMBER(N11)),N11<=M11),0,MIN(12*(IF(OR(O11="",NOT(ISNUMBER(O11))),Paramètres!$C$8,O11)),(YEAR(N11)-YEAR(M11))*12+MONTH(N11)-MONTH(M11)+1)))<=0),0,MAX(0,H11*(1-R11/(IF(OR(NOT(ISNUMBER(M11)),NOT(ISNUMBER(N11)),N11<=M11),0,MIN(12*(IF(OR(O11="",NOT(ISNUMBER(O11))),Paramètres!$C$8,O11)),(YEAR(N11)-YEAR(M11))*12+MONTH(N11)-MONTH(M11)+1)))))))) -> 109725 | T11: =IF(AND(ISNUMBER(N11),ISNUMBER($C$7)),MAX(0,(N11-$C$7)/365.25),0) -> 6.0013689 | U11: =IF(AND(ISNUMBER(Q11),ISNUMBER($C$7)),MAX(0,(Q11-$C$7)/365.25),0) -> 3.0006845 | V11: =IF(COUNTA(B11,C11,D11,E11,F11,G11,I11,M11,N11,O11,P11,R11)>0,IF(AND(COUNT(Paramètres!$C$8:$C$12)=5,COUNT(Paramètres!$C$16:$C$25)=10,ISNUMBER($C$7),B11<>"",NOT(ISNA(MATCH(C11,Paramètres!$B$29:$B$34,0))),NOT(ISNA(MATCH(E11,Paramètres!$D$29:$D$30,0))),ISNUMBER(F11),F11>0,F11<=Paramètres!$C$22,OR(I11="",AND(ISNUMBER(I11),I11>=0,I11<=Paramètres!$C$21)),IF(E11=Paramètres!$D$29,AND(D11<>"",ISNUMBER(G11),G11>0,G11<=Paramètres!$C$21,ISNUMBER(M11),ISNUMBER(N11),N11>M11,(N(N11)-N(M11))/365.25<=Paramètres!$C$23,OR(O11="",AND(ISNUMBER(O11),O11>=1,O11<=Paramètres!$C$23,O11=INT(N(O11)))),OR(P11="",AND(ISNUMBER(P11),P11>$C$7,P11<=N11)),OR(R11="",AND(ISNUMBER(R11),R11>=0,R11<=Paramètres!$C$24,R11<=(IF(OR(NOT(ISNUMBER(M11)),NOT(ISNUMBER(N11)),N11<=M11),0,MIN(12*(IF(OR(O11="",NOT(ISNUMBER(O11))),Paramètres!$C$8,O11)),(YEAR(N11)-YEAR(M11))*12+MONTH(N11)-MONTH(M11)+1)))))),AND(D11="",OR(G11="",G11=0)))),"OK","À CORRIGER"),"") -> OK | W11: =IF(NOT(COUNTA(B11,C11,D11,E11,F11,G11,I11,M11,N11,O11,P11,R11)>0),"",IF(OR(COUNT(Paramètres!$C$8:$C$12)<>5,COUNT(Paramètres!$C$16:$C$25)<>10),"Un paramètre de l'onglet Paramètres est vide.",IF(NOT(ISNUMBER($C$7)),"Date d'analyse manquante.",IF(B11="","Libellé du lot manquant.",IF(ISNA(MATCH(C11,Paramètres!$B$29:$B$34,0)),"Nature hors liste.",IF(ISNA(MATCH(E11,Paramètres!$D$29:$D$30,0)),"Statut hors liste.",IF(NOT(AND(ISNUMBER(F11),F11>0)),"Surface manquante ou nulle.",IF(F11>Paramètres!$C$22,"Surface au-delà du garde-fou de saisie.",IF(AND(I11<>"",NOT(AND(ISNUMBER(I11),I11>=0,I11<=Paramètres!$C$21))),"Valeur locative de marché hors bornes.",IF(AND(E11=Paramètres!$D$29,D11=""),"Lot déclaré loué sans locataire.",IF(AND(E11=Paramètres!$D$29,NOT(AND(ISNUMBER(G11),G11>0))),"Loyer facial manquant ou nul.",IF(AND(E11=Paramètres!$D$29,G11>Paramètres!$C$21),"Loyer facial au-delà du garde-fou de saisie.",IF(AND(E11=Paramètres!$D$29,NOT(ISNUMBER(M11))),"Date de prise d'effet manquante.",IF(AND(E11=Paramètres!$D$29,NOT(ISNUMBER(N11))),"Date d'échéance manquante.",IF(AND(E11=Paramètres!$D$29,N11<=M11),"Échéance antérieure ou égale à la prise d'effet.",IF(AND(E11=Paramètres!$D$29,(N(N11)-N(M11))/365.25>Paramètres!$C$23),"Durée du bail au-delà du garde-fou de saisie.",IF(AND(E11=Paramètres!$D$29,O11<>"",NOT(AND(ISNUMBER(O11),O11>=1,O11<=Paramètres!$C$23,O11=INT(N(O11))))),"Périodicité de sortie hors bornes.",IF(AND(E11=Paramètres!$D$29,P11<>"",NOT(AND(ISNUMBER(P11),P11>$C$7,P11<=N11))),"Sortie forcée hors de l'intervalle admis.",IF(AND(E11=Paramètres!$D$29,R11<>"",NOT(AND(ISNUMBER(R11),R11>=0,R11<=Paramètres!$C$24,R11<=(IF(OR(NOT(ISNUMBER(M11)),NOT(ISNUMBER(N11)),N11<=M11),0,MIN(12*(IF(OR(O11="",NOT(ISNUMBER(O11))),Paramètres!$C$8,O11)),(YEAR(N11)-YEAR(M11))*12+MONTH(N11)-MONTH(M11)+1)))))),"Franchise hors bornes ou plus longue que la période ferme.",IF(AND(E11=Paramètres!$D$30,D11<>""),"Lot vacant avec un locataire renseigné.",IF(AND(E11=Paramètres!$D$30,G11<>"",G11<>0),"Lot vacant avec un loyer renseigné.",IF(AND(E11=Paramètres!$D$29,ISNUMBER(N11),ISNUMBER($C$7),N11<$C$7),"Bail échu, en tacite prolongation.",IF(I11="","Valeur locative de marché non renseignée.",""))))))))))))))))))))))) | X11: =IF(AND(V11="OK",E11=Paramètres!$D$29),SUMIFS($H$11:$H$50,$D$11:$D$50,D11,$E$11:$E$50,Paramètres!$D$29,$V$11:$V$50,"OK"),0) -> 178080
B12: R+1 Plateau B | C12: Bureaux | D12: Locataire Bêta | E12: Loué | F12: 310 | G12: 275 | H12: =IF(AND(ISNUMBER(F12),ISNUMBER(G12)),F12*G12,0) -> 85250 | I12: 300 | J12: =IF(AND(ISNUMBER(F12),ISNUMBER(I12)),F12*I12,0) -> 93000 | K12: =IF(OR(H12<=0,J12<=0),"",J12-H12) -> 7750 | L12: =IF(OR(H12<=0,J12<=0),"",J12/H12-1) -> 0.090909091 | M12: 44197 | N12: 47483 | Q12: =IF(OR(NOT(ISNUMBER($C$7)),NOT(ISNUMBER(M12)),NOT(ISNUMBER(N12))),"",IF(ISNUMBER(P12),P12,IF((IF(OR(O12="",NOT(ISNUMBER(O12))),Paramètres!$C$8,O12))<=0,"",MIN(EDATE(M12,(12*(IF(OR(O12="",NOT(ISNUMBER(O12))),Paramètres!$C$8,O12)))*MAX(1,INT(((YEAR($C$7+1)-YEAR(M12))*12+MONTH($C$7+1)-MONTH(M12)-(DAY($C$7+1)<DAY(M12)))/(12*(IF(OR(O12="",NOT(ISNUMBER(O12))),Paramètres!$C$8,O12))))+1))-1,N12)))) -> 46387 | S12: =IF(H12=0,0,IF(OR(R12="",R12=0),H12,IF(OR(NOT(ISNUMBER(R12)),(IF(OR(NOT(ISNUMBER(M12)),NOT(ISNUMBER(N12)),N12<=M12),0,MIN(12*(IF(OR(O12="",NOT(ISNUMBER(O12))),Paramètres!$C$8,O12)),(YEAR(N12)-YEAR(M12))*12+MONTH(N12)-MONTH(M12)+1)))<=0),0,MAX(0,H12*(1-R12/(IF(OR(NOT(ISNUMBER(M12)),NOT(ISNUMBER(N12)),N12<=M12),0,MIN(12*(IF(OR(O12="",NOT(ISNUMBER(O12))),Paramètres!$C$8,O12)),(YEAR(N12)-YEAR(M12))*12+MONTH(N12)-MONTH(M12)+1)))))))) -> 85250 | T12: =IF(AND(ISNUMBER(N12),ISNUMBER($C$7)),MAX(0,(N12-$C$7)/365.25),0) -> 3.504449 | U12: =IF(AND(ISNUMBER(Q12),ISNUMBER($C$7)),MAX(0,(Q12-$C$7)/365.25),0) -> 0.50376454 | V12: =IF(COUNTA(B12,C12,D12,E12,F12,G12,I12,M12,N12,O12,P12,R12)>0,IF(AND(COUNT(Paramètres!$C$8:$C$12)=5,COUNT(Paramètres!$C$16:$C$25)=10,ISNUMBER($C$7),B12<>"",NOT(ISNA(MATCH(C12,Paramètres!$B$29:$B$34,0))),NOT(ISNA(MATCH(E12,Paramètres!$D$29:$D$30,0))),ISNUMBER(F12),F12>0,F12<=Paramètres!$C$22,OR(I12="",AND(ISNUMBER(I12),I12>=0,I12<=Paramètres!$C$21)),IF(E12=Paramètres!$D$29,AND(D12<>"",ISNUMBER(G12),G12>0,G12<=Paramètres!$C$21,ISNUMBER(M12),ISNUMBER(N12),N12>M12,(N(N12)-N(M12))/365.25<=Paramètres!$C$23,OR(O12="",AND(ISNUMBER(O12),O12>=1,O12<=Paramètres!$C$23,O12=INT(N(O12)))),OR(P12="",AND(ISNUMBER(P12),P12>$C$7,P12<=N12)),OR(R12="",AND(ISNUMBER(R12),R12>=0,R12<=Paramètres!$C$24,R12<=(IF(OR(NOT(ISNUMBER(M12)),NOT(ISNUMBER(N12)),N12<=M12),0,MIN(12*(IF(OR(O12="",NOT(ISNUMBER(O12))),Paramètres!$C$8,O12)),(YEAR(N12)-YEAR(M12))*12+MONTH(N12)-MONTH(M12)+1)))))),AND(D12="",OR(G12="",G12=0)))),"OK","À CORRIGER"),"") -> OK | W12: =IF(NOT(COUNTA(B12,C12,D12,E12,F12,G12,I12,M12,N12,O12,P12,R12)>0),"",IF(OR(COUNT(Paramètres!$C$8:$C$12)<>5,COUNT(Paramètres!$C$16:$C$25)<>10),"Un paramètre de l'onglet Paramètres est vide.",IF(NOT(ISNUMBER($C$7)),"Date d'analyse manquante.",IF(B12="","Libellé du lot manquant.",IF(ISNA(MATCH(C12,Paramètres!$B$29:$B$34,0)),"Nature hors liste.",IF(ISNA(MATCH(E12,Paramètres!$D$29:$D$30,0)),"Statut hors liste.",IF(NOT(AND(ISNUMBER(F12),F12>0)),"Surface manquante ou nulle.",IF(F12>Paramètres!$C$22,"Surface au-delà du garde-fou de saisie.",IF(AND(I12<>"",NOT(AND(ISNUMBER(I12),I12>=0,I12<=Paramètres!$C$21))),"Valeur locative de marché hors bornes.",IF(AND(E12=Paramètres!$D$29,D12=""),"Lot déclaré loué sans locataire.",IF(AND(E12=Paramètres!$D$29,NOT(AND(ISNUMBER(G12),G12>0))),"Loyer facial manquant ou nul.",IF(AND(E12=Paramètres!$D$29,G12>Paramètres!$C$21),"Loyer facial au-delà du garde-fou de saisie.",IF(AND(E12=Paramètres!$D$29,NOT(ISNUMBER(M12))),"Date de prise d'effet manquante.",IF(AND(E12=Paramètres!$D$29,NOT(ISNUMBER(N12))),"Date d'échéance manquante.",IF(AND(E12=Paramètres!$D$29,N12<=M12),"Échéance antérieure ou égale à la prise d'effet.",IF(AND(E12=Paramètres!$D$29,(N(N12)-N(M12))/365.25>Paramètres!$C$23),"Durée du bail au-delà du garde-fou de saisie.",IF(AND(E12=Paramètres!$D$29,O12<>"",NOT(AND(ISNUMBER(O12),O12>=1,O12<=Paramètres!$C$23,O12=INT(N(O12))))),"Périodicité de sortie hors bornes.",IF(AND(E12=Paramètres!$D$29,P12<>"",NOT(AND(ISNUMBER(P12),P12>$C$7,P12<=N12))),"Sortie forcée hors de l'intervalle admis.",IF(AND(E12=Paramètres!$D$29,R12<>"",NOT(AND(ISNUMBER(R12),R12>=0,R12<=Paramètres!$C$24,R12<=(IF(OR(NOT(ISNUMBER(M12)),NOT(ISNUMBER(N12)),N12<=M12),0,MIN(12*(IF(OR(O12="",NOT(ISNUMBER(O12))),Paramètres!$C$8,O12)),(YEAR(N12)-YEAR(M12))*12+MONTH(N12)-MONTH(M12)+1)))))),"Franchise hors bornes ou plus longue que la période ferme.",IF(AND(E12=Paramètres!$D$30,D12<>""),"Lot vacant avec un locataire renseigné.",IF(AND(E12=Paramètres!$D$30,G12<>"",G12<>0),"Lot vacant avec un loyer renseigné.",IF(AND(E12=Paramètres!$D$29,ISNUMBER(N12),ISNUMBER($C$7),N12<$C$7),"Bail échu, en tacite prolongation.",IF(I12="","Valeur locative de marché non renseignée.",""))))))))))))))))))))))) | X12: =IF(AND(V12="OK",E12=Paramètres!$D$29),SUMIFS($H$11:$H$50,$D$11:$D$50,D12,$E$11:$E$50,Paramètres!$D$29,$V$11:$V$50,"OK"),0) -> 85250
B13: RDC Local 1 | C13: Commerce | D13: Locataire Gamma | E13: Loué | F13: 180 | G13: 420 | H13: =IF(AND(ISNUMBER(F13),ISNUMBER(G13)),F13*G13,0) -> 75600 | I13: 400 | J13: =IF(AND(ISNUMBER(F13),ISNUMBER(I13)),F13*I13,0) -> 72000 | K13: =IF(OR(H13<=0,J13<=0),"",J13-H13) -> -3600 | L13: =IF(OR(H13<=0,J13<=0),"",J13/H13-1) -> -0.047619048 | M13: 44440 | N13: 47726 | Q13: =IF(OR(NOT(ISNUMBER($C$7)),NOT(ISNUMBER(M13)),NOT(ISNUMBER(N13))),"",IF(ISNUMBER(P13),P13,IF((IF(OR(O13="",NOT(ISNUMBER(O13))),Paramètres!$C$8,O13))<=0,"",MIN(EDATE(M13,(12*(IF(OR(O13="",NOT(ISNUMBER(O13))),Paramètres!$C$8,O13)))*MAX(1,INT(((YEAR($C$7+1)-YEAR(M13))*12+MONTH($C$7+1)-MONTH(M13)-(DAY($C$7+1)<DAY(M13)))/(12*(IF(OR(O13="",NOT(ISNUMBER(O13))),Paramètres!$C$8,O13))))+1))-1,N13)))) -> 46630 | S13: =IF(H13=0,0,IF(OR(R13="",R13=0),H13,IF(OR(NOT(ISNUMBER(R13)),(IF(OR(NOT(ISNUMBER(M13)),NOT(ISNUMBER(N13)),N13<=M13),0,MIN(12*(IF(OR(O13="",NOT(ISNUMBER(O13))),Paramètres!$C$8,O13)),(YEAR(N13)-YEAR(M13))*12+MONTH(N13)-MONTH(M13)+1)))<=0),0,MAX(0,H13*(1-R13/(IF(OR(NOT(ISNUMBER(M13)),NOT(ISNUMBER(N13)),N13<=M13),0,MIN(12*(IF(OR(O13="",NOT(ISNUMBER(O13))),Paramètres!$C$8,O13)),(YEAR(N13)-YEAR(M13))*12+MONTH(N13)-MONTH(M13)+1)))))))) -> 75600 | T13: =IF(AND(ISNUMBER(N13),ISNUMBER($C$7)),MAX(0,(N13-$C$7)/365.25),0) -> 4.1697467 | U13: =IF(AND(ISNUMBER(Q13),ISNUMBER($C$7)),MAX(0,(Q13-$C$7)/365.25),0) -> 1.1690623 | V13: =IF(COUNTA(B13,C13,D13,E13,F13,G13,I13,M13,N13,O13,P13,R13)>0,IF(AND(COUNT(Paramètres!$C$8:$C$12)=5,COUNT(Paramètres!$C$16:$C$25)=10,ISNUMBER($C$7),B13<>"",NOT(ISNA(MATCH(C13,Paramètres!$B$29:$B$34,0))),NOT(ISNA(MATCH(E13,Paramètres!$D$29:$D$30,0))),ISNUMBER(F13),F13>0,F13<=Paramètres!$C$22,OR(I13="",AND(ISNUMBER(I13),I13>=0,I13<=Paramètres!$C$21)),IF(E13=Paramètres!$D$29,AND(D13<>"",ISNUMBER(G13),G13>0,G13<=Paramètres!$C$21,ISNUMBER(M13),ISNUMBER(N13),N13>M13,(N(N13)-N(M13))/365.25<=Paramètres!$C$23,OR(O13="",AND(ISNUMBER(O13),O13>=1,O13<=Paramètres!$C$23,O13=INT(N(O13)))),OR(P13="",AND(ISNUMBER(P13),P13>$C$7,P13<=N13)),OR(R13="",AND(ISNUMBER(R13),R13>=0,R13<=Paramètres!$C$24,R13<=(IF(OR(NOT(ISNUMBER(M13)),NOT(ISNUMBER(N13)),N13<=M13),0,MIN(12*(IF(OR(O13="",NOT(ISNUMBER(O13))),Paramètres!$C$8,O13)),(YEAR(N13)-YEAR(M13))*12+MONTH(N13)-MONTH(M13)+1)))))),AND(D13="",OR(G13="",G13=0)))),"OK","À CORRIGER"),"") -> OK | W13: =IF(NOT(COUNTA(B13,C13,D13,E13,F13,G13,I13,M13,N13,O13,P13,R13)>0),"",IF(OR(COUNT(Paramètres!$C$8:$C$12)<>5,COUNT(Paramètres!$C$16:$C$25)<>10),"Un paramètre de l'onglet Paramètres est vide.",IF(NOT(ISNUMBER($C$7)),"Date d'analyse manquante.",IF(B13="","Libellé du lot manquant.",IF(ISNA(MATCH(C13,Paramètres!$B$29:$B$34,0)),"Nature hors liste.",IF(ISNA(MATCH(E13,Paramètres!$D$29:$D$30,0)),"Statut hors liste.",IF(NOT(AND(ISNUMBER(F13),F13>0)),"Surface manquante ou nulle.",IF(F13>Paramètres!$C$22,"Surface au-delà du garde-fou de saisie.",IF(AND(I13<>"",NOT(AND(ISNUMBER(I13),I13>=0,I13<=Paramètres!$C$21))),"Valeur locative de marché hors bornes.",IF(AND(E13=Paramètres!$D$29,D13=""),"Lot déclaré loué sans locataire.",IF(AND(E13=Paramètres!$D$29,NOT(AND(ISNUMBER(G13),G13>0))),"Loyer facial manquant ou nul.",IF(AND(E13=Paramètres!$D$29,G13>Paramètres!$C$21),"Loyer facial au-delà du garde-fou de saisie.",IF(AND(E13=Paramètres!$D$29,NOT(ISNUMBER(M13))),"Date de prise d'effet manquante.",IF(AND(E13=Paramètres!$D$29,NOT(ISNUMBER(N13))),"Date d'échéance manquante.",IF(AND(E13=Paramètres!$D$29,N13<=M13),"Échéance antérieure ou égale à la prise d'effet.",IF(AND(E13=Paramètres!$D$29,(N(N13)-N(M13))/365.25>Paramètres!$C$23),"Durée du bail au-delà du garde-fou de saisie.",IF(AND(E13=Paramètres!$D$29,O13<>"",NOT(AND(ISNUMBER(O13),O13>=1,O13<=Paramètres!$C$23,O13=INT(N(O13))))),"Périodicité de sortie hors bornes.",IF(AND(E13=Paramètres!$D$29,P13<>"",NOT(AND(ISNUMBER(P13),P13>$C$7,P13<=N13))),"Sortie forcée hors de l'intervalle admis.",IF(AND(E13=Paramètres!$D$29,R13<>"",NOT(AND(ISNUMBER(R13),R13>=0,R13<=Paramètres!$C$24,R13<=(IF(OR(NOT(ISNUMBER(M13)),NOT(ISNUMBER(N13)),N13<=M13),0,MIN(12*(IF(OR(O13="",NOT(ISNUMBER(O13))),Paramètres!$C$8,O13)),(YEAR(N13)-YEAR(M13))*12+MONTH(N13)-MONTH(M13)+1)))))),"Franchise hors bornes ou plus longue que la période ferme.",IF(AND(E13=Paramètres!$D$30,D13<>""),"Lot vacant avec un locataire renseigné.",IF(AND(E13=Paramètres!$D$30,G13<>"",G13<>0),"Lot vacant avec un loyer renseigné.",IF(AND(E13=Paramètres!$D$29,ISNUMBER(N13),ISNUMBER($C$7),N13<$C$7),"Bail échu, en tacite prolongation.",IF(I13="","Valeur locative de marché non renseignée.",""))))))))))))))))))))))) | X13: =IF(AND(V13="OK",E13=Paramètres!$D$29),SUMIFS($H$11:$H$50,$D$11:$D$50,D13,$E$11:$E$50,Paramètres!$D$29,$V$11:$V$50,"OK"),0) -> 75600
B14: RDC Local 2 | C14: Commerce | E14: Vacant | F14: 95 | H14: =IF(AND(ISNUMBER(F14),ISNUMBER(G14)),F14*G14,0) -> 0 | I14: 380 | J14: =IF(AND(ISNUMBER(F14),ISNUMBER(I14)),F14*I14,0) -> 36100 | K14: =IF(OR(H14<=0,J14<=0),"",J14-H14) | L14: =IF(OR(H14<=0,J14<=0),"",J14/H14-1) | Q14: =IF(OR(NOT(ISNUMBER($C$7)),NOT(ISNUMBER(M14)),NOT(ISNUMBER(N14))),"",IF(ISNUMBER(P14),P14,IF((IF(OR(O14="",NOT(ISNUMBER(O14))),Paramètres!$C$8,O14))<=0,"",MIN(EDATE(M14,(12*(IF(OR(O14="",NOT(ISNUMBER(O14))),Paramètres!$C$8,O14)))*MAX(1,INT(((YEAR($C$7+1)-YEAR(M14))*12+MONTH($C$7+1)-MONTH(M14)-(DAY($C$7+1)<DAY(M14)))/(12*(IF(OR(O14="",NOT(ISNUMBER(O14))),Paramètres!$C$8,O14))))+1))-1,N14)))) | S14: =IF(H14=0,0,IF(OR(R14="",R14=0),H14,IF(OR(NOT(ISNUMBER(R14)),(IF(OR(NOT(ISNUMBER(M14)),NOT(ISNUMBER(N14)),N14<=M14),0,MIN(12*(IF(OR(O14="",NOT(ISNUMBER(O14))),Paramètres!$C$8,O14)),(YEAR(N14)-YEAR(M14))*12+MONTH(N14)-MONTH(M14)+1)))<=0),0,MAX(0,H14*(1-R14/(IF(OR(NOT(ISNUMBER(M14)),NOT(ISNUMBER(N14)),N14<=M14),0,MIN(12*(IF(OR(O14="",NOT(ISNUMBER(O14))),Paramètres!$C$8,O14)),(YEAR(N14)-YEAR(M14))*12+MONTH(N14)-MONTH(M14)+1)))))))) -> 0 | T14: =IF(AND(ISNUMBER(N14),ISNUMBER($C$7)),MAX(0,(N14-$C$7)/365.25),0) -> 0 | U14: =IF(AND(ISNUMBER(Q14),ISNUMBER($C$7)),MAX(0,(Q14-$C$7)/365.25),0) -> 0 | V14: =IF(COUNTA(B14,C14,D14,E14,F14,G14,I14,M14,N14,O14,P14,R14)>0,IF(AND(COUNT(Paramètres!$C$8:$C$12)=5,COUNT(Paramètres!$C$16:$C$25)=10,ISNUMBER($C$7),B14<>"",NOT(ISNA(MATCH(C14,Paramètres!$B$29:$B$34,0))),NOT(ISNA(MATCH(E14,Paramètres!$D$29:$D$30,0))),ISNUMBER(F14),F14>0,F14<=Paramètres!$C$22,OR(I14="",AND(ISNUMBER(I14),I14>=0,I14<=Paramètres!$C$21)),IF(E14=Paramètres!$D$29,AND(D14<>"",ISNUMBER(G14),G14>0,G14<=Paramètres!$C$21,ISNUMBER(M14),ISNUMBER(N14),N14>M14,(N(N14)-N(M14))/365.25<=Paramètres!$C$23,OR(O14="",AND(ISNUMBER(O14),O14>=1,O14<=Paramètres!$C$23,O14=INT(N(O14)))),OR(P14="",AND(ISNUMBER(P14),P14>$C$7,P14<=N14)),OR(R14="",AND(ISNUMBER(R14),R14>=0,R14<=Paramètres!$C$24,R14<=(IF(OR(NOT(ISNUMBER(M14)),NOT(ISNUMBER(N14)),N14<=M14),0,MIN(12*(IF(OR(O14="",NOT(ISNUMBER(O14))),Paramètres!$C$8,O14)),(YEAR(N14)-YEAR(M14))*12+MONTH(N14)-MONTH(M14)+1)))))),AND(D14="",OR(G14="",G14=0)))),"OK","À CORRIGER"),"") -> OK | W14: =IF(NOT(COUNTA(B14,C14,D14,E14,F14,G14,I14,M14,N14,O14,P14,R14)>0),"",IF(OR(COUNT(Paramètres!$C$8:$C$12)<>5,COUNT(Paramètres!$C$16:$C$25)<>10),"Un paramètre de l'onglet Paramètres est vide.",IF(NOT(ISNUMBER($C$7)),"Date d'analyse manquante.",IF(B14="","Libellé du lot manquant.",IF(ISNA(MATCH(C14,Paramètres!$B$29:$B$34,0)),"Nature hors liste.",IF(ISNA(MATCH(E14,Paramètres!$D$29:$D$30,0)),"Statut hors liste.",IF(NOT(AND(ISNUMBER(F14),F14>0)),"Surface manquante ou nulle.",IF(F14>Paramètres!$C$22,"Surface au-delà du garde-fou de saisie.",IF(AND(I14<>"",NOT(AND(ISNUMBER(I14),I14>=0,I14<=Paramètres!$C$21))),"Valeur locative de marché hors bornes.",IF(AND(E14=Paramètres!$D$29,D14=""),"Lot déclaré loué sans locataire.",IF(AND(E14=Paramètres!$D$29,NOT(AND(ISNUMBER(G14),G14>0))),"Loyer facial manquant ou nul.",IF(AND(E14=Paramètres!$D$29,G14>Paramètres!$C$21),"Loyer facial au-delà du garde-fou de saisie.",IF(AND(E14=Paramètres!$D$29,NOT(ISNUMBER(M14))),"Date de prise d'effet manquante.",IF(AND(E14=Paramètres!$D$29,NOT(ISNUMBER(N14))),"Date d'échéance manquante.",IF(AND(E14=Paramètres!$D$29,N14<=M14),"Échéance antérieure ou égale à la prise d'effet.",IF(AND(E14=Paramètres!$D$29,(N(N14)-N(M14))/365.25>Paramètres!$C$23),"Durée du bail au-delà du garde-fou de saisie.",IF(AND(E14=Paramètres!$D$29,O14<>"",NOT(AND(ISNUMBER(O14),O14>=1,O14<=Paramètres!$C$23,O14=INT(N(O14))))),"Périodicité de sortie hors bornes.",IF(AND(E14=Paramètres!$D$29,P14<>"",NOT(AND(ISNUMBER(P14),P14>$C$7,P14<=N14))),"Sortie forcée hors de l'intervalle admis.",IF(AND(E14=Paramètres!$D$29,R14<>"",NOT(AND(ISNUMBER(R14),R14>=0,R14<=Paramètres!$C$24,R14<=(IF(OR(NOT(ISNUMBER(M14)),NOT(ISNUMBER(N14)),N14<=M14),0,MIN(12*(IF(OR(O14="",NOT(ISNUMBER(O14))),Paramètres!$C$8,O14)),(YEAR(N14)-YEAR(M14))*12+MONTH(N14)-MONTH(M14)+1)))))),"Franchise hors bornes ou plus longue que la période ferme.",IF(AND(E14=Paramètres!$D$30,D14<>""),"Lot vacant avec un locataire renseigné.",IF(AND(E14=Paramètres!$D$30,G14<>"",G14<>0),"Lot vacant avec un loyer renseigné.",IF(AND(E14=Paramètres!$D$29,ISNUMBER(N14),ISNUMBER($C$7),N14<$C$7),"Bail échu, en tacite prolongation.",IF(I14="","Valeur locative de marché non renseignée.",""))))))))))))))))))))))) | X14: =IF(AND(V14="OK",E14=Paramètres!$D$29),SUMIFS($H$11:$H$50,$D$11:$D$50,D14,$E$11:$E$50,Paramètres!$D$29,$V$11:$V$50,"OK"),0) -> 0
B15: R+2 Plateau C | C15: Bureaux | D15: Locataire Delta | E15: Loué | F15: 400 | G15: 268 | H15: =IF(AND(ISNUMBER(F15),ISNUMBER(G15)),F15*G15,0) -> 107200 | I15: 300 | J15: =IF(AND(ISNUMBER(F15),ISNUMBER(I15)),F15*I15,0) -> 120000 | K15: =IF(OR(H15<=0,J15<=0),"",J15-H15) -> 12800 | L15: =IF(OR(H15<=0,J15<=0),"",J15/H15-1) -> 0.11940299 | M15: 45383 | N15: 48669 | O15: 6 | Q15: =IF(OR(NOT(ISNUMBER($C$7)),NOT(ISNUMBER(M15)),NOT(ISNUMBER(N15))),"",IF(ISNUMBER(P15),P15,IF((IF(OR(O15="",NOT(ISNUMBER(O15))),Paramètres!$C$8,O15))<=0,"",MIN(EDATE(M15,(12*(IF(OR(O15="",NOT(ISNUMBER(O15))),Paramètres!$C$8,O15)))*MAX(1,INT(((YEAR($C$7+1)-YEAR(M15))*12+MONTH($C$7+1)-MONTH(M15)-(DAY($C$7+1)<DAY(M15)))/(12*(IF(OR(O15="",NOT(ISNUMBER(O15))),Paramètres!$C$8,O15))))+1))-1,N15)))) -> 47573 | R15: 6 | S15: =IF(H15=0,0,IF(OR(R15="",R15=0),H15,IF(OR(NOT(ISNUMBER(R15)),(IF(OR(NOT(ISNUMBER(M15)),NOT(ISNUMBER(N15)),N15<=M15),0,MIN(12*(IF(OR(O15="",NOT(ISNUMBER(O15))),Paramètres!$C$8,O15)),(YEAR(N15)-YEAR(M15))*12+MONTH(N15)-MONTH(M15)+1)))<=0),0,MAX(0,H15*(1-R15/(IF(OR(NOT(ISNUMBER(M15)),NOT(ISNUMBER(N15)),N15<=M15),0,MIN(12*(IF(OR(O15="",NOT(ISNUMBER(O15))),Paramètres!$C$8,O15)),(YEAR(N15)-YEAR(M15))*12+MONTH(N15)-MONTH(M15)+1)))))))) -> 98266.667 | T15: =IF(AND(ISNUMBER(N15),ISNUMBER($C$7)),MAX(0,(N15-$C$7)/365.25),0) -> 6.75154 | U15: =IF(AND(ISNUMBER(Q15),ISNUMBER($C$7)),MAX(0,(Q15-$C$7)/365.25),0) -> 3.7508556 | V15: =IF(COUNTA(B15,C15,D15,E15,F15,G15,I15,M15,N15,O15,P15,R15)>0,IF(AND(COUNT(Paramètres!$C$8:$C$12)=5,COUNT(Paramètres!$C$16:$C$25)=10,ISNUMBER($C$7),B15<>"",NOT(ISNA(MATCH(C15,Paramètres!$B$29:$B$34,0))),NOT(ISNA(MATCH(E15,Paramètres!$D$29:$D$30,0))),ISNUMBER(F15),F15>0,F15<=Paramètres!$C$22,OR(I15="",AND(ISNUMBER(I15),I15>=0,I15<=Paramètres!$C$21)),IF(E15=Paramètres!$D$29,AND(D15<>"",ISNUMBER(G15),G15>0,G15<=Paramètres!$C$21,ISNUMBER(M15),ISNUMBER(N15),N15>M15,(N(N15)-N(M15))/365.25<=Paramètres!$C$23,OR(O15="",AND(ISNUMBER(O15),O15>=1,O15<=Paramètres!$C$23,O15=INT(N(O15)))),OR(P15="",AND(ISNUMBER(P15),P15>$C$7,P15<=N15)),OR(R15="",AND(ISNUMBER(R15),R15>=0,R15<=Paramètres!$C$24,R15<=(IF(OR(NOT(ISNUMBER(M15)),NOT(ISNUMBER(N15)),N15<=M15),0,MIN(12*(IF(OR(O15="",NOT(ISNUMBER(O15))),Paramètres!$C$8,O15)),(YEAR(N15)-YEAR(M15))*12+MONTH(N15)-MONTH(M15)+1)))))),AND(D15="",OR(G15="",G15=0)))),"OK","À CORRIGER"),"") -> OK | W15: =IF(NOT(COUNTA(B15,C15,D15,E15,F15,G15,I15,M15,N15,O15,P15,R15)>0),"",IF(OR(COUNT(Paramètres!$C$8:$C$12)<>5,COUNT(Paramètres!$C$16:$C$25)<>10),"Un paramètre de l'onglet Paramètres est vide.",IF(NOT(ISNUMBER($C$7)),"Date d'analyse manquante.",IF(B15="","Libellé du lot manquant.",IF(ISNA(MATCH(C15,Paramètres!$B$29:$B$34,0)),"Nature hors liste.",IF(ISNA(MATCH(E15,Paramètres!$D$29:$D$30,0)),"Statut hors liste.",IF(NOT(AND(ISNUMBER(F15),F15>0)),"Surface manquante ou nulle.",IF(F15>Paramètres!$C$22,"Surface au-delà du garde-fou de saisie.",IF(AND(I15<>"",NOT(AND(ISNUMBER(I15),I15>=0,I15<=Paramètres!$C$21))),"Valeur locative de marché hors bornes.",IF(AND(E15=Paramètres!$D$29,D15=""),"Lot déclaré loué sans locataire.",IF(AND(E15=Paramètres!$D$29,NOT(AND(ISNUMBER(G15),G15>0))),"Loyer facial manquant ou nul.",IF(AND(E15=Paramètres!$D$29,G15>Paramètres!$C$21),"Loyer facial au-delà du garde-fou de saisie.",IF(AND(E15=Paramètres!$D$29,NOT(ISNUMBER(M15))),"Date de prise d'effet manquante.",IF(AND(E15=Paramètres!$D$29,NOT(ISNUMBER(N15))),"Date d'échéance manquante.",IF(AND(E15=Paramètres!$D$29,N15<=M15),"Échéance antérieure ou égale à la prise d'effet.",IF(AND(E15=Paramètres!$D$29,(N(N15)-N(M15))/365.25>Paramètres!$C$23),"Durée du bail au-delà du garde-fou de saisie.",IF(AND(E15=Paramètres!$D$29,O15<>"",NOT(AND(ISNUMBER(O15),O15>=1,O15<=Paramètres!$C$23,O15=INT(N(O15))))),"Périodicité de sortie hors bornes.",IF(AND(E15=Paramètres!$D$29,P15<>"",NOT(AND(ISNUMBER(P15),P15>$C$7,P15<=N15))),"Sortie forcée hors de l'intervalle admis.",IF(AND(E15=Paramètres!$D$29,R15<>"",NOT(AND(ISNUMBER(R15),R15>=0,R15<=Paramètres!$C$24,R15<=(IF(OR(NOT(ISNUMBER(M15)),NOT(ISNUMBER(N15)),N15<=M15),0,MIN(12*(IF(OR(O15="",NOT(ISNUMBER(O15))),Paramètres!$C$8,O15)),(YEAR(N15)-YEAR(M15))*12+MONTH(N15)-MONTH(M15)+1)))))),"Franchise hors bornes ou plus longue que la période ferme.",IF(AND(E15=Paramètres!$D$30,D15<>""),"Lot vacant avec un locataire renseigné.",IF(AND(E15=Paramètres!$D$30,G15<>"",G15<>0),"Lot vacant avec un loyer renseigné.",IF(AND(E15=Paramètres!$D$29,ISNUMBER(N15),ISNUMBER($C$7),N15<$C$7),"Bail échu, en tacite prolongation.",IF(I15="","Valeur locative de marché non renseignée.",""))))))))))))))))))))))) | X15: =IF(AND(V15="OK",E15=Paramètres!$D$29),SUMIFS($H$11:$H$50,$D$11:$D$50,D15,$E$11:$E$50,Paramètres!$D$29,$V$11:$V$50,"OK"),0) -> 107200
B16: R+2 Plateau D | C16: Bureaux | D16: Locataire Alpha | E16: Loué | F16: 210 | G16: 278 | H16: =IF(AND(ISNUMBER(F16),ISNUMBER(G16)),F16*G16,0) -> 58380 | I16: 300 | J16: =IF(AND(ISNUMBER(F16),ISNUMBER(I16)),F16*I16,0) -> 63000 | K16: =IF(OR(H16<=0,J16<=0),"",J16-H16) -> 4620 | L16: =IF(OR(H16<=0,J16<=0),"",J16/H16-1) -> 0.079136691 | M16: 45108 | N16: 48395 | Q16: =IF(OR(NOT(ISNUMBER($C$7)),NOT(ISNUMBER(M16)),NOT(ISNUMBER(N16))),"",IF(ISNUMBER(P16),P16,IF((IF(OR(O16="",NOT(ISNUMBER(O16))),Paramètres!$C$8,O16))<=0,"",MIN(EDATE(M16,(12*(IF(OR(O16="",NOT(ISNUMBER(O16))),Paramètres!$C$8,O16)))*MAX(1,INT(((YEAR($C$7+1)-YEAR(M16))*12+MONTH($C$7+1)-MONTH(M16)-(DAY($C$7+1)<DAY(M16)))/(12*(IF(OR(O16="",NOT(ISNUMBER(O16))),Paramètres!$C$8,O16))))+1))-1,N16)))) -> 47299 | R16: 3 | S16: =IF(H16=0,0,IF(OR(R16="",R16=0),H16,IF(OR(NOT(ISNUMBER(R16)),(IF(OR(NOT(ISNUMBER(M16)),NOT(ISNUMBER(N16)),N16<=M16),0,MIN(12*(IF(OR(O16="",NOT(ISNUMBER(O16))),Paramètres!$C$8,O16)),(YEAR(N16)-YEAR(M16))*12+MONTH(N16)-MONTH(M16)+1)))<=0),0,MAX(0,H16*(1-R16/(IF(OR(NOT(ISNUMBER(M16)),NOT(ISNUMBER(N16)),N16<=M16),0,MIN(12*(IF(OR(O16="",NOT(ISNUMBER(O16))),Paramètres!$C$8,O16)),(YEAR(N16)-YEAR(M16))*12+MONTH(N16)-MONTH(M16)+1)))))))) -> 53515 | T16: =IF(AND(ISNUMBER(N16),ISNUMBER($C$7)),MAX(0,(N16-$C$7)/365.25),0) -> 6.0013689 | U16: =IF(AND(ISNUMBER(Q16),ISNUMBER($C$7)),MAX(0,(Q16-$C$7)/365.25),0) -> 3.0006845 | V16: =IF(COUNTA(B16,C16,D16,E16,F16,G16,I16,M16,N16,O16,P16,R16)>0,IF(AND(COUNT(Paramètres!$C$8:$C$12)=5,COUNT(Paramètres!$C$16:$C$25)=10,ISNUMBER($C$7),B16<>"",NOT(ISNA(MATCH(C16,Paramètres!$B$29:$B$34,0))),NOT(ISNA(MATCH(E16,Paramètres!$D$29:$D$30,0))),ISNUMBER(F16),F16>0,F16<=Paramètres!$C$22,OR(I16="",AND(ISNUMBER(I16),I16>=0,I16<=Paramètres!$C$21)),IF(E16=Paramètres!$D$29,AND(D16<>"",ISNUMBER(G16),G16>0,G16<=Paramètres!$C$21,ISNUMBER(M16),ISNUMBER(N16),N16>M16,(N(N16)-N(M16))/365.25<=Paramètres!$C$23,OR(O16="",AND(ISNUMBER(O16),O16>=1,O16<=Paramètres!$C$23,O16=INT(N(O16)))),OR(P16="",AND(ISNUMBER(P16),P16>$C$7,P16<=N16)),OR(R16="",AND(ISNUMBER(R16),R16>=0,R16<=Paramètres!$C$24,R16<=(IF(OR(NOT(ISNUMBER(M16)),NOT(ISNUMBER(N16)),N16<=M16),0,MIN(12*(IF(OR(O16="",NOT(ISNUMBER(O16))),Paramètres!$C$8,O16)),(YEAR(N16)-YEAR(M16))*12+MONTH(N16)-MONTH(M16)+1)))))),AND(D16="",OR(G16="",G16=0)))),"OK","À CORRIGER"),"") -> OK | W16: =IF(NOT(COUNTA(B16,C16,D16,E16,F16,G16,I16,M16,N16,O16,P16,R16)>0),"",IF(OR(COUNT(Paramètres!$C$8:$C$12)<>5,COUNT(Paramètres!$C$16:$C$25)<>10),"Un paramètre de l'onglet Paramètres est vide.",IF(NOT(ISNUMBER($C$7)),"Date d'analyse manquante.",IF(B16="","Libellé du lot manquant.",IF(ISNA(MATCH(C16,Paramètres!$B$29:$B$34,0)),"Nature hors liste.",IF(ISNA(MATCH(E16,Paramètres!$D$29:$D$30,0)),"Statut hors liste.",IF(NOT(AND(ISNUMBER(F16),F16>0)),"Surface manquante ou nulle.",IF(F16>Paramètres!$C$22,"Surface au-delà du garde-fou de saisie.",IF(AND(I16<>"",NOT(AND(ISNUMBER(I16),I16>=0,I16<=Paramètres!$C$21))),"Valeur locative de marché hors bornes.",IF(AND(E16=Paramètres!$D$29,D16=""),"Lot déclaré loué sans locataire.",IF(AND(E16=Paramètres!$D$29,NOT(AND(ISNUMBER(G16),G16>0))),"Loyer facial manquant ou nul.",IF(AND(E16=Paramètres!$D$29,G16>Paramètres!$C$21),"Loyer facial au-delà du garde-fou de saisie.",IF(AND(E16=Paramètres!$D$29,NOT(ISNUMBER(M16))),"Date de prise d'effet manquante.",IF(AND(E16=Paramètres!$D$29,NOT(ISNUMBER(N16))),"Date d'échéance manquante.",IF(AND(E16=Paramètres!$D$29,N16<=M16),"Échéance antérieure ou égale à la prise d'effet.",IF(AND(E16=Paramètres!$D$29,(N(N16)-N(M16))/365.25>Paramètres!$C$23),"Durée du bail au-delà du garde-fou de saisie.",IF(AND(E16=Paramètres!$D$29,O16<>"",NOT(AND(ISNUMBER(O16),O16>=1,O16<=Paramètres!$C$23,O16=INT(N(O16))))),"Périodicité de sortie hors bornes.",IF(AND(E16=Paramètres!$D$29,P16<>"",NOT(AND(ISNUMBER(P16),P16>$C$7,P16<=N16))),"Sortie forcée hors de l'intervalle admis.",IF(AND(E16=Paramètres!$D$29,R16<>"",NOT(AND(ISNUMBER(R16),R16>=0,R16<=Paramètres!$C$24,R16<=(IF(OR(NOT(ISNUMBER(M16)),NOT(ISNUMBER(N16)),N16<=M16),0,MIN(12*(IF(OR(O16="",NOT(ISNUMBER(O16))),Paramètres!$C$8,O16)),(YEAR(N16)-YEAR(M16))*12+MONTH(N16)-MONTH(M16)+1)))))),"Franchise hors bornes ou plus longue que la période ferme.",IF(AND(E16=Paramètres!$D$30,D16<>""),"Lot vacant avec un locataire renseigné.",IF(AND(E16=Paramètres!$D$30,G16<>"",G16<>0),"Lot vacant avec un loyer renseigné.",IF(AND(E16=Paramètres!$D$29,ISNUMBER(N16),ISNUMBER($C$7),N16<$C$7),"Bail échu, en tacite prolongation.",IF(I16="","Valeur locative de marché non renseignée.",""))))))))))))))))))))))) | X16: =IF(AND(V16="OK",E16=Paramètres!$D$29),SUMIFS($H$11:$H$50,$D$11:$D$50,D16,$E$11:$E$50,Paramètres!$D$29,$V$11:$V$50,"OK"),0) -> 178080
B17: RDC Local 3 | C17: Commerce | D17: Locataire Epsilon | E17: Loué | F17: 140 | G17: 390 | H17: =IF(AND(ISNUMBER(F17),ISNUMBER(G17)),F17*G17,0) -> 54600 | I17: 400 | J17: =IF(AND(ISNUMBER(F17),ISNUMBER(I17)),F17*I17,0) -> 56000 | K17: =IF(OR(H17<=0,J17<=0),"",J17-H17) -> 1400 | L17: =IF(OR(H17<=0,J17<=0),"",J17/H17-1) -> 0.025641026 | M17: 43009 | N17: 46295 | Q17: =IF(OR(NOT(ISNUMBER($C$7)),NOT(ISNUMBER(M17)),NOT(ISNUMBER(N17))),"",IF(ISNUMBER(P17),P17,IF((IF(OR(O17="",NOT(ISNUMBER(O17))),Paramètres!$C$8,O17))<=0,"",MIN(EDATE(M17,(12*(IF(OR(O17="",NOT(ISNUMBER(O17))),Paramètres!$C$8,O17)))*MAX(1,INT(((YEAR($C$7+1)-YEAR(M17))*12+MONTH($C$7+1)-MONTH(M17)-(DAY($C$7+1)<DAY(M17)))/(12*(IF(OR(O17="",NOT(ISNUMBER(O17))),Paramètres!$C$8,O17))))+1))-1,N17)))) -> 46295 | S17: =IF(H17=0,0,IF(OR(R17="",R17=0),H17,IF(OR(NOT(ISNUMBER(R17)),(IF(OR(NOT(ISNUMBER(M17)),NOT(ISNUMBER(N17)),N17<=M17),0,MIN(12*(IF(OR(O17="",NOT(ISNUMBER(O17))),Paramètres!$C$8,O17)),(YEAR(N17)-YEAR(M17))*12+MONTH(N17)-MONTH(M17)+1)))<=0),0,MAX(0,H17*(1-R17/(IF(OR(NOT(ISNUMBER(M17)),NOT(ISNUMBER(N17)),N17<=M17),0,MIN(12*(IF(OR(O17="",NOT(ISNUMBER(O17))),Paramètres!$C$8,O17)),(YEAR(N17)-YEAR(M17))*12+MONTH(N17)-MONTH(M17)+1)))))))) -> 54600 | T17: =IF(AND(ISNUMBER(N17),ISNUMBER($C$7)),MAX(0,(N17-$C$7)/365.25),0) -> 0.25188227 | U17: =IF(AND(ISNUMBER(Q17),ISNUMBER($C$7)),MAX(0,(Q17-$C$7)/365.25),0) -> 0.25188227 | V17: =IF(COUNTA(B17,C17,D17,E17,F17,G17,I17,M17,N17,O17,P17,R17)>0,IF(AND(COUNT(Paramètres!$C$8:$C$12)=5,COUNT(Paramètres!$C$16:$C$25)=10,ISNUMBER($C$7),B17<>"",NOT(ISNA(MATCH(C17,Paramètres!$B$29:$B$34,0))),NOT(ISNA(MATCH(E17,Paramètres!$D$29:$D$30,0))),ISNUMBER(F17),F17>0,F17<=Paramètres!$C$22,OR(I17="",AND(ISNUMBER(I17),I17>=0,I17<=Paramètres!$C$21)),IF(E17=Paramètres!$D$29,AND(D17<>"",ISNUMBER(G17),G17>0,G17<=Paramètres!$C$21,ISNUMBER(M17),ISNUMBER(N17),N17>M17,(N(N17)-N(M17))/365.25<=Paramètres!$C$23,OR(O17="",AND(ISNUMBER(O17),O17>=1,O17<=Paramètres!$C$23,O17=INT(N(O17)))),OR(P17="",AND(ISNUMBER(P17),P17>$C$7,P17<=N17)),OR(R17="",AND(ISNUMBER(R17),R17>=0,R17<=Paramètres!$C$24,R17<=(IF(OR(NOT(ISNUMBER(M17)),NOT(ISNUMBER(N17)),N17<=M17),0,MIN(12*(IF(OR(O17="",NOT(ISNUMBER(O17))),Paramètres!$C$8,O17)),(YEAR(N17)-YEAR(M17))*12+MONTH(N17)-MONTH(M17)+1)))))),AND(D17="",OR(G17="",G17=0)))),"OK","À CORRIGER"),"") -> OK | W17: =IF(NOT(COUNTA(B17,C17,D17,E17,F17,G17,I17,M17,N17,O17,P17,R17)>0),"",IF(OR(COUNT(Paramètres!$C$8:$C$12)<>5,COUNT(Paramètres!$C$16:$C$25)<>10),"Un paramètre de l'onglet Paramètres est vide.",IF(NOT(ISNUMBER($C$7)),"Date d'analyse manquante.",IF(B17="","Libellé du lot manquant.",IF(ISNA(MATCH(C17,Paramètres!$B$29:$B$34,0)),"Nature hors liste.",IF(ISNA(MATCH(E17,Paramètres!$D$29:$D$30,0)),"Statut hors liste.",IF(NOT(AND(ISNUMBER(F17),F17>0)),"Surface manquante ou nulle.",IF(F17>Paramètres!$C$22,"Surface au-delà du garde-fou de saisie.",IF(AND(I17<>"",NOT(AND(ISNUMBER(I17),I17>=0,I17<=Paramètres!$C$21))),"Valeur locative de marché hors bornes.",IF(AND(E17=Paramètres!$D$29,D17=""),"Lot déclaré loué sans locataire.",IF(AND(E17=Paramètres!$D$29,NOT(AND(ISNUMBER(G17),G17>0))),"Loyer facial manquant ou nul.",IF(AND(E17=Paramètres!$D$29,G17>Paramètres!$C$21),"Loyer facial au-delà du garde-fou de saisie.",IF(AND(E17=Paramètres!$D$29,NOT(ISNUMBER(M17))),"Date de prise d'effet manquante.",IF(AND(E17=Paramètres!$D$29,NOT(ISNUMBER(N17))),"Date d'échéance manquante.",IF(AND(E17=Paramètres!$D$29,N17<=M17),"Échéance antérieure ou égale à la prise d'effet.",IF(AND(E17=Paramètres!$D$29,(N(N17)-N(M17))/365.25>Paramètres!$C$23),"Durée du bail au-delà du garde-fou de saisie.",IF(AND(E17=Paramètres!$D$29,O17<>"",NOT(AND(ISNUMBER(O17),O17>=1,O17<=Paramètres!$C$23,O17=INT(N(O17))))),"Périodicité de sortie hors bornes.",IF(AND(E17=Paramètres!$D$29,P17<>"",NOT(AND(ISNUMBER(P17),P17>$C$7,P17<=N17))),"Sortie forcée hors de l'intervalle admis.",IF(AND(E17=Paramètres!$D$29,R17<>"",NOT(AND(ISNUMBER(R17),R17>=0,R17<=Paramètres!$C$24,R17<=(IF(OR(NOT(ISNUMBER(M17)),NOT(ISNUMBER(N17)),N17<=M17),0,MIN(12*(IF(OR(O17="",NOT(ISNUMBER(O17))),Paramètres!$C$8,O17)),(YEAR(N17)-YEAR(M17))*12+MONTH(N17)-MONTH(M17)+1)))))),"Franchise hors bornes ou plus longue que la période ferme.",IF(AND(E17=Paramètres!$D$30,D17<>""),"Lot vacant avec un locataire renseigné.",IF(AND(E17=Paramètres!$D$30,G17<>"",G17<>0),"Lot vacant avec un loyer renseigné.",IF(AND(E17=Paramètres!$D$29,ISNUMBER(N17),ISNUMBER($C$7),N17<$C$7),"Bail échu, en tacite prolongation.",IF(I17="","Valeur locative de marché non renseignée.",""))))))))))))))))))))))) | X17: =IF(AND(V17="OK",E17=Paramètres!$D$29),SUMIFS($H$11:$H$50,$D$11:$D$50,D17,$E$11:$E$50,Paramètres!$D$29,$V$11:$V$50,"OK"),0) -> 54600
H18: =IF(AND(ISNUMBER(F18),ISNUMBER(G18)),F18*G18,0) -> 0 | J18: =IF(AND(ISNUMBER(F18),ISNUMBER(I18)),F18*I18,0) -> 0 | K18: =IF(OR(H18<=0,J18<=0),"",J18-H18) | L18: =IF(OR(H18<=0,J18<=0),"",J18/H18-1) | Q18: =IF(OR(NOT(ISNUMBER($C$7)),NOT(ISNUMBER(M18)),NOT(ISNUMBER(N18))),"",IF(ISNUMBER(P18),P18,IF((IF(OR(O18="",NOT(ISNUMBER(O18))),Paramètres!$C$8,O18))<=0,"",MIN(EDATE(M18,(12*(IF(OR(O18="",NOT(ISNUMBER(O18))),Paramètres!$C$8,O18)))*MAX(1,INT(((YEAR($C$7+1)-YEAR(M18))*12+MONTH($C$7+1)-MONTH(M18)-(DAY($C$7+1)<DAY(M18)))/(12*(IF(OR(O18="",NOT(ISNUMBER(O18))),Paramètres!$C$8,O18))))+1))-1,N18)))) | S18: =IF(H18=0,0,IF(OR(R18="",R18=0),H18,IF(OR(NOT(ISNUMBER(R18)),(IF(OR(NOT(ISNUMBER(M18)),NOT(ISNUMBER(N18)),N18<=M18),0,MIN(12*(IF(OR(O18="",NOT(ISNUMBER(O18))),Paramètres!$C$8,O18)),(YEAR(N18)-YEAR(M18))*12+MONTH(N18)-MONTH(M18)+1)))<=0),0,MAX(0,H18*(1-R18/(IF(OR(NOT(ISNUMBER(M18)),NOT(ISNUMBER(N18)),N18<=M18),0,MIN(12*(IF(OR(O18="",NOT(ISNUMBER(O18))),Paramètres!$C$8,O18)),(YEAR(N18)-YEAR(M18))*12+MONTH(N18)-MONTH(M18)+1)))))))) -> 0 | T18: =IF(AND(ISNUMBER(N18),ISNUMBER($C$7)),MAX(0,(N18-$C$7)/365.25),0) -> 0 | U18: =IF(AND(ISNUMBER(Q18),ISNUMBER($C$7)),MAX(0,(Q18-$C$7)/365.25),0) -> 0 | V18: =IF(COUNTA(B18,C18,D18,E18,F18,G18,I18,M18,N18,O18,P18,R18)>0,IF(AND(COUNT(Paramètres!$C$8:$C$12)=5,COUNT(Paramètres!$C$16:$C$25)=10,ISNUMBER($C$7),B18<>"",NOT(ISNA(MATCH(C18,Paramètres!$B$29:$B$34,0))),NOT(ISNA(MATCH(E18,Paramètres!$D$29:$D$30,0))),ISNUMBER(F18),F18>0,F18<=Paramètres!$C$22,OR(I18="",AND(ISNUMBER(I18),I18>=0,I18<=Paramètres!$C$21)),IF(E18=Paramètres!$D$29,AND(D18<>"",ISNUMBER(G18),G18>0,G18<=Paramètres!$C$21,ISNUMBER(M18),ISNUMBER(N18),N18>M18,(N(N18)-N(M18))/365.25<=Paramètres!$C$23,OR(O18="",AND(ISNUMBER(O18),O18>=1,O18<=Paramètres!$C$23,O18=INT(N(O18)))),OR(P18="",AND(ISNUMBER(P18),P18>$C$7,P18<=N18)),OR(R18="",AND(ISNUMBER(R18),R18>=0,R18<=Paramètres!$C$24,R18<=(IF(OR(NOT(ISNUMBER(M18)),NOT(ISNUMBER(N18)),N18<=M18),0,MIN(12*(IF(OR(O18="",NOT(ISNUMBER(O18))),Paramètres!$C$8,O18)),(YEAR(N18)-YEAR(M18))*12+MONTH(N18)-MONTH(M18)+1)))))),AND(D18="",OR(G18="",G18=0)))),"OK","À CORRIGER"),"") | W18: =IF(NOT(COUNTA(B18,C18,D18,E18,F18,G18,I18,M18,N18,O18,P18,R18)>0),"",IF(OR(COUNT(Paramètres!$C$8:$C$12)<>5,COUNT(Paramètres!$C$16:$C$25)<>10),"Un paramètre de l'onglet Paramètres est vide.",IF(NOT(ISNUMBER($C$7)),"Date d'analyse manquante.",IF(B18="","Libellé du lot manquant.",IF(ISNA(MATCH(C18,Paramètres!$B$29:$B$34,0)),"Nature hors liste.",IF(ISNA(MATCH(E18,Paramètres!$D$29:$D$30,0)),"Statut hors liste.",IF(NOT(AND(ISNUMBER(F18),F18>0)),"Surface manquante ou nulle.",IF(F18>Paramètres!$C$22,"Surface au-delà du garde-fou de saisie.",IF(AND(I18<>"",NOT(AND(ISNUMBER(I18),I18>=0,I18<=Paramètres!$C$21))),"Valeur locative de marché hors bornes.",IF(AND(E18=Paramètres!$D$29,D18=""),"Lot déclaré loué sans locataire.",IF(AND(E18=Paramètres!$D$29,NOT(AND(ISNUMBER(G18),G18>0))),"Loyer facial manquant ou nul.",IF(AND(E18=Paramètres!$D$29,G18>Paramètres!$C$21),"Loyer facial au-delà du garde-fou de saisie.",IF(AND(E18=Paramètres!$D$29,NOT(ISNUMBER(M18))),"Date de prise d'effet manquante.",IF(AND(E18=Paramètres!$D$29,NOT(ISNUMBER(N18))),"Date d'échéance manquante.",IF(AND(E18=Paramètres!$D$29,N18<=M18),"Échéance antérieure ou égale à la prise d'effet.",IF(AND(E18=Paramètres!$D$29,(N(N18)-N(M18))/365.25>Paramètres!$C$23),"Durée du bail au-delà du garde-fou de saisie.",IF(AND(E18=Paramètres!$D$29,O18<>"",NOT(AND(ISNUMBER(O18),O18>=1,O18<=Paramètres!$C$23,O18=INT(N(O18))))),"Périodicité de sortie hors bornes.",IF(AND(E18=Paramètres!$D$29,P18<>"",NOT(AND(ISNUMBER(P18),P18>$C$7,P18<=N18))),"Sortie forcée hors de l'intervalle admis.",IF(AND(E18=Paramètres!$D$29,R18<>"",NOT(AND(ISNUMBER(R18),R18>=0,R18<=Paramètres!$C$24,R18<=(IF(OR(NOT(ISNUMBER(M18)),NOT(ISNUMBER(N18)),N18<=M18),0,MIN(12*(IF(OR(O18="",NOT(ISNUMBER(O18))),Paramètres!$C$8,O18)),(YEAR(N18)-YEAR(M18))*12+MONTH(N18)-MONTH(M18)+1)))))),"Franchise hors bornes ou plus longue que la période ferme.",IF(AND(E18=Paramètres!$D$30,D18<>""),"Lot vacant avec un locataire renseigné.",IF(AND(E18=Paramètres!$D$30,G18<>"",G18<>0),"Lot vacant avec un loyer renseigné.",IF(AND(E18=Paramètres!$D$29,ISNUMBER(N18),ISNUMBER($C$7),N18<$C$7),"Bail échu, en tacite prolongation.",IF(I18="","Valeur locative de marché non renseignée.",""))))))))))))))))))))))) | X18: =IF(AND(V18="OK",E18=Paramètres!$D$29),SUMIFS($H$11:$H$50,$D$11:$D$50,D18,$E$11:$E$50,Paramètres!$D$29,$V$11:$V$50,"OK"),0) -> 0
H19: =IF(AND(ISNUMBER(F19),ISNUMBER(G19)),F19*G19,0) -> 0 | J19: =IF(AND(ISNUMBER(F19),ISNUMBER(I19)),F19*I19,0) -> 0 | K19: =IF(OR(H19<=0,J19<=0),"",J19-H19) | L19: =IF(OR(H19<=0,J19<=0),"",J19/H19-1) | Q19: =IF(OR(NOT(ISNUMBER($C$7)),NOT(ISNUMBER(M19)),NOT(ISNUMBER(N19))),"",IF(ISNUMBER(P19),P19,IF((IF(OR(O19="",NOT(ISNUMBER(O19))),Paramètres!$C$8,O19))<=0,"",MIN(EDATE(M19,(12*(IF(OR(O19="",NOT(ISNUMBER(O19))),Paramètres!$C$8,O19)))*MAX(1,INT(((YEAR($C$7+1)-YEAR(M19))*12+MONTH($C$7+1)-MONTH(M19)-(DAY($C$7+1)<DAY(M19)))/(12*(IF(OR(O19="",NOT(ISNUMBER(O19))),Paramètres!$C$8,O19))))+1))-1,N19)))) | S19: =IF(H19=0,0,IF(OR(R19="",R19=0),H19,IF(OR(NOT(ISNUMBER(R19)),(IF(OR(NOT(ISNUMBER(M19)),NOT(ISNUMBER(N19)),N19<=M19),0,MIN(12*(IF(OR(O19="",NOT(ISNUMBER(O19))),Paramètres!$C$8,O19)),(YEAR(N19)-YEAR(M19))*12+MONTH(N19)-MONTH(M19)+1)))<=0),0,MAX(0,H19*(1-R19/(IF(OR(NOT(ISNUMBER(M19)),NOT(ISNUMBER(N19)),N19<=M19),0,MIN(12*(IF(OR(O19="",NOT(ISNUMBER(O19))),Paramètres!$C$8,O19)),(YEAR(N19)-YEAR(M19))*12+MONTH(N19)-MONTH(M19)+1)))))))) -> 0 | T19: =IF(AND(ISNUMBER(N19),ISNUMBER($C$7)),MAX(0,(N19-$C$7)/365.25),0) -> 0 | U19: =IF(AND(ISNUMBER(Q19),ISNUMBER($C$7)),MAX(0,(Q19-$C$7)/365.25),0) -> 0 | V19: =IF(COUNTA(B19,C19,D19,E19,F19,G19,I19,M19,N19,O19,P19,R19)>0,IF(AND(COUNT(Paramètres!$C$8:$C$12)=5,COUNT(Paramètres!$C$16:$C$25)=10,ISNUMBER($C$7),B19<>"",NOT(ISNA(MATCH(C19,Paramètres!$B$29:$B$34,0))),NOT(ISNA(MATCH(E19,Paramètres!$D$29:$D$30,0))),ISNUMBER(F19),F19>0,F19<=Paramètres!$C$22,OR(I19="",AND(ISNUMBER(I19),I19>=0,I19<=Paramètres!$C$21)),IF(E19=Paramètres!$D$29,AND(D19<>"",ISNUMBER(G19),G19>0,G19<=Paramètres!$C$21,ISNUMBER(M19),ISNUMBER(N19),N19>M19,(N(N19)-N(M19))/365.25<=Paramètres!$C$23,OR(O19="",AND(ISNUMBER(O19),O19>=1,O19<=Paramètres!$C$23,O19=INT(N(O19)))),OR(P19="",AND(ISNUMBER(P19),P19>$C$7,P19<=N19)),OR(R19="",AND(ISNUMBER(R19),R19>=0,R19<=Paramètres!$C$24,R19<=(IF(OR(NOT(ISNUMBER(M19)),NOT(ISNUMBER(N19)),N19<=M19),0,MIN(12*(IF(OR(O19="",NOT(ISNUMBER(O19))),Paramètres!$C$8,O19)),(YEAR(N19)-YEAR(M19))*12+MONTH(N19)-MONTH(M19)+1)))))),AND(D19="",OR(G19="",G19=0)))),"OK","À CORRIGER"),"") | W19: =IF(NOT(COUNTA(B19,C19,D19,E19,F19,G19,I19,M19,N19,O19,P19,R19)>0),"",IF(OR(COUNT(Paramètres!$C$8:$C$12)<>5,COUNT(Paramètres!$C$16:$C$25)<>10),"Un paramètre de l'onglet Paramètres est vide.",IF(NOT(ISNUMBER($C$7)),"Date d'analyse manquante.",IF(B19="","Libellé du lot manquant.",IF(ISNA(MATCH(C19,Paramètres!$B$29:$B$34,0)),"Nature hors liste.",IF(ISNA(MATCH(E19,Paramètres!$D$29:$D$30,0)),"Statut hors liste.",IF(NOT(AND(ISNUMBER(F19),F19>0)),"Surface manquante ou nulle.",IF(F19>Paramètres!$C$22,"Surface au-delà du garde-fou de saisie.",IF(AND(I19<>"",NOT(AND(ISNUMBER(I19),I19>=0,I19<=Paramètres!$C$21))),"Valeur locative de marché hors bornes.",IF(AND(E19=Paramètres!$D$29,D19=""),"Lot déclaré loué sans locataire.",IF(AND(E19=Paramètres!$D$29,NOT(AND(ISNUMBER(G19),G19>0))),"Loyer facial manquant ou nul.",IF(AND(E19=Paramètres!$D$29,G19>Paramètres!$C$21),"Loyer facial au-delà du garde-fou de saisie.",IF(AND(E19=Paramètres!$D$29,NOT(ISNUMBER(M19))),"Date de prise d'effet manquante.",IF(AND(E19=Paramètres!$D$29,NOT(ISNUMBER(N19))),"Date d'échéance manquante.",IF(AND(E19=Paramètres!$D$29,N19<=M19),"Échéance antérieure ou égale à la prise d'effet.",IF(AND(E19=Paramètres!$D$29,(N(N19)-N(M19))/365.25>Paramètres!$C$23),"Durée du bail au-delà du garde-fou de saisie.",IF(AND(E19=Paramètres!$D$29,O19<>"",NOT(AND(ISNUMBER(O19),O19>=1,O19<=Paramètres!$C$23,O19=INT(N(O19))))),"Périodicité de sortie hors bornes.",IF(AND(E19=Paramètres!$D$29,P19<>"",NOT(AND(ISNUMBER(P19),P19>$C$7,P19<=N19))),"Sortie forcée hors de l'intervalle admis.",IF(AND(E19=Paramètres!$D$29,R19<>"",NOT(AND(ISNUMBER(R19),R19>=0,R19<=Paramètres!$C$24,R19<=(IF(OR(NOT(ISNUMBER(M19)),NOT(ISNUMBER(N19)),N19<=M19),0,MIN(12*(IF(OR(O19="",NOT(ISNUMBER(O19))),Paramètres!$C$8,O19)),(YEAR(N19)-YEAR(M19))*12+MONTH(N19)-MONTH(M19)+1)))))),"Franchise hors bornes ou plus longue que la période ferme.",IF(AND(E19=Paramètres!$D$30,D19<>""),"Lot vacant avec un locataire renseigné.",IF(AND(E19=Paramètres!$D$30,G19<>"",G19<>0),"Lot vacant avec un loyer renseigné.",IF(AND(E19=Paramètres!$D$29,ISNUMBER(N19),ISNUMBER($C$7),N19<$C$7),"Bail échu, en tacite prolongation.",IF(I19="","Valeur locative de marché non renseignée.",""))))))))))))))))))))))) | X19: =IF(AND(V19="OK",E19=Paramètres!$D$29),SUMIFS($H$11:$H$50,$D$11:$D$50,D19,$E$11:$E$50,Paramètres!$D$29,$V$11:$V$50,"OK"),0) -> 0
H20: =IF(AND(ISNUMBER(F20),ISNUMBER(G20)),F20*G20,0) -> 0 | J20: =IF(AND(ISNUMBER(F20),ISNUMBER(I20)),F20*I20,0) -> 0 | K20: =IF(OR(H20<=0,J20<=0),"",J20-H20) | L20: =IF(OR(H20<=0,J20<=0),"",J20/H20-1) | Q20: =IF(OR(NOT(ISNUMBER($C$7)),NOT(ISNUMBER(M20)),NOT(ISNUMBER(N20))),"",IF(ISNUMBER(P20),P20,IF((IF(OR(O20="",NOT(ISNUMBER(O20))),Paramètres!$C$8,O20))<=0,"",MIN(EDATE(M20,(12*(IF(OR(O20="",NOT(ISNUMBER(O20))),Paramètres!$C$8,O20)))*MAX(1,INT(((YEAR($C$7+1)-YEAR(M20))*12+MONTH($C$7+1)-MONTH(M20)-(DAY($C$7+1)<DAY(M20)))/(12*(IF(OR(O20="",NOT(ISNUMBER(O20))),Paramètres!$C$8,O20))))+1))-1,N20)))) | S20: =IF(H20=0,0,IF(OR(R20="",R20=0),H20,IF(OR(NOT(ISNUMBER(R20)),(IF(OR(NOT(ISNUMBER(M20)),NOT(ISNUMBER(N20)),N20<=M20),0,MIN(12*(IF(OR(O20="",NOT(ISNUMBER(O20))),Paramètres!$C$8,O20)),(YEAR(N20)-YEAR(M20))*12+MONTH(N20)-MONTH(M20)+1)))<=0),0,MAX(0,H20*(1-R20/(IF(OR(NOT(ISNUMBER(M20)),NOT(ISNUMBER(N20)),N20<=M20),0,MIN(12*(IF(OR(O20="",NOT(ISNUMBER(O20))),Paramètres!$C$8,O20)),(YEAR(N20)-YEAR(M20))*12+MONTH(N20)-MONTH(M20)+1)))))))) -> 0 | T20: =IF(AND(ISNUMBER(N20),ISNUMBER($C$7)),MAX(0,(N20-$C$7)/365.25),0) -> 0 | U20: =IF(AND(ISNUMBER(Q20),ISNUMBER($C$7)),MAX(0,(Q20-$C$7)/365.25),0) -> 0 | V20: =IF(COUNTA(B20,C20,D20,E20,F20,G20,I20,M20,N20,O20,P20,R20)>0,IF(AND(COUNT(Paramètres!$C$8:$C$12)=5,COUNT(Paramètres!$C$16:$C$25)=10,ISNUMBER($C$7),B20<>"",NOT(ISNA(MATCH(C20,Paramètres!$B$29:$B$34,0))),NOT(ISNA(MATCH(E20,Paramètres!$D$29:$D$30,0))),ISNUMBER(F20),F20>0,F20<=Paramètres!$C$22,OR(I20="",AND(ISNUMBER(I20),I20>=0,I20<=Paramètres!$C$21)),IF(E20=Paramètres!$D$29,AND(D20<>"",ISNUMBER(G20),G20>0,G20<=Paramètres!$C$21,ISNUMBER(M20),ISNUMBER(N20),N20>M20,(N(N20)-N(M20))/365.25<=Paramètres!$C$23,OR(O20="",AND(ISNUMBER(O20),O20>=1,O20<=Paramètres!$C$23,O20=INT(N(O20)))),OR(P20="",AND(ISNUMBER(P20),P20>$C$7,P20<=N20)),OR(R20="",AND(ISNUMBER(R20),R20>=0,R20<=Paramètres!$C$24,R20<=(IF(OR(NOT(ISNUMBER(M20)),NOT(ISNUMBER(N20)),N20<=M20),0,MIN(12*(IF(OR(O20="",NOT(ISNUMBER(O20))),Paramètres!$C$8,O20)),(YEAR(N20)-YEAR(M20))*12+MONTH(N20)-MONTH(M20)+1)))))),AND(D20="",OR(G20="",G20=0)))),"OK","À CORRIGER"),"") | W20: =IF(NOT(COUNTA(B20,C20,D20,E20,F20,G20,I20,M20,N20,O20,P20,R20)>0),"",IF(OR(COUNT(Paramètres!$C$8:$C$12)<>5,COUNT(Paramètres!$C$16:$C$25)<>10),"Un paramètre de l'onglet Paramètres est vide.",IF(NOT(ISNUMBER($C$7)),"Date d'analyse manquante.",IF(B20="","Libellé du lot manquant.",IF(ISNA(MATCH(C20,Paramètres!$B$29:$B$34,0)),"Nature hors liste.",IF(ISNA(MATCH(E20,Paramètres!$D$29:$D$30,0)),"Statut hors liste.",IF(NOT(AND(ISNUMBER(F20),F20>0)),"Surface manquante ou nulle.",IF(F20>Paramètres!$C$22,"Surface au-delà du garde-fou de saisie.",IF(AND(I20<>"",NOT(AND(ISNUMBER(I20),I20>=0,I20<=Paramètres!$C$21))),"Valeur locative de marché hors bornes.",IF(AND(E20=Paramètres!$D$29,D20=""),"Lot déclaré loué sans locataire.",IF(AND(E20=Paramètres!$D$29,NOT(AND(ISNUMBER(G20),G20>0))),"Loyer facial manquant ou nul.",IF(AND(E20=Paramètres!$D$29,G20>Paramètres!$C$21),"Loyer facial au-delà du garde-fou de saisie.",IF(AND(E20=Paramètres!$D$29,NOT(ISNUMBER(M20))),"Date de prise d'effet manquante.",IF(AND(E20=Paramètres!$D$29,NOT(ISNUMBER(N20))),"Date d'échéance manquante.",IF(AND(E20=Paramètres!$D$29,N20<=M20),"Échéance antérieure ou égale à la prise d'effet.",IF(AND(E20=Paramètres!$D$29,(N(N20)-N(M20))/365.25>Paramètres!$C$23),"Durée du bail au-delà du garde-fou de saisie.",IF(AND(E20=Paramètres!$D$29,O20<>"",NOT(AND(ISNUMBER(O20),O20>=1,O20<=Paramètres!$C$23,O20=INT(N(O20))))),"Périodicité de sortie hors bornes.",IF(AND(E20=Paramètres!$D$29,P20<>"",NOT(AND(ISNUMBER(P20),P20>$C$7,P20<=N20))),"Sortie forcée hors de l'intervalle admis.",IF(AND(E20=Paramètres!$D$29,R20<>"",NOT(AND(ISNUMBER(R20),R20>=0,R20<=Paramètres!$C$24,R20<=(IF(OR(NOT(ISNUMBER(M20)),NOT(ISNUMBER(N20)),N20<=M20),0,MIN(12*(IF(OR(O20="",NOT(ISNUMBER(O20))),Paramètres!$C$8,O20)),(YEAR(N20)-YEAR(M20))*12+MONTH(N20)-MONTH(M20)+1)))))),"Franchise hors bornes ou plus longue que la période ferme.",IF(AND(E20=Paramètres!$D$30,D20<>""),"Lot vacant avec un locataire renseigné.",IF(AND(E20=Paramètres!$D$30,G20<>"",G20<>0),"Lot vacant avec un loyer renseigné.",IF(AND(E20=Paramètres!$D$29,ISNUMBER(N20),ISNUMBER($C$7),N20<$C$7),"Bail échu, en tacite prolongation.",IF(I20="","Valeur locative de marché non renseignée.",""))))))))))))))))))))))) | X20: =IF(AND(V20="OK",E20=Paramètres!$D$29),SUMIFS($H$11:$H$50,$D$11:$D$50,D20,$E$11:$E$50,Paramètres!$D$29,$V$11:$V$50,"OK"),0) -> 0
